Workbook

Sheet Data
A1: Sampling Date | H1: *Multiply N2 fluxes by 2 (presented as umoles N in graphs, not N2)
A2: Site
C3: Time | D3: grasses | E3: SAV | F3: hardwoods | G3: typha | I3: umole N numbers
B4: Net O2 | C4: T0 | D4: -301.63537 | E4: -497.3244 | F4: -635.18972 | G4: -884.36632 | I4: =D4*2 -> -603.27075 | J4: =E4*2 -> -994.6488 | K4: =F4*2 -> -1270.3794 | L4: =G4*2 -> -1768.7326
C5: SE | D5: 282.39914 | E5: 20.099396 | F5: 100.80198 | G5: 291.27576 | I5: =D5*2 -> 564.79827 | J5: =E5*2 -> 40.198792 | K5: =F5*2 -> 201.60395 | L5: =G5*2 -> 582.55152
C6: T1 | D6: -753.63861 | E6: -871.92704 | F6: -1266.8516 | G6: -1038.6274 | I6: =D6*2 -> -1507.2772 | J6: =E6*2 -> -1743.8541 | K6: =F6*2 -> -2533.7032 | L6: =G6*2 -> -2077.2548
C7: SE | D7: 319.22332 | E7: 86.522528 | F7: 360.20352 | G7: 187.26804 | I7: =D7*2 -> 638.44664 | J7: =E7*2 -> 173.04506 | K7: =F7*2 -> 720.40704 | L7: =G7*2 -> 374.53608
C8: T2 | D8: -434.81294 | E8: -944.26845 | F8: -1070.3202 | G8: -591.59293 | I8: =D8*2 -> -869.62588 | J8: =E8*2 -> -1888.5369 | K8: =F8*2 -> -2140.6405 | L8: =G8*2 -> -1183.1859
C9: SE | D9: 343.67278 | E9: 278.38256 | F9: 276.40323 | G9: 242.02915 | I9: =D9*2 -> 687.34557 | J9: =E9*2 -> 556.76512 | K9: =F9*2 -> 552.80647 | L9: =G9*2 -> 484.05831
B10: Net 28 | C10: T0 | D10: -0.79437753 | E10: -1.2560363 | F10: 1.0747414 | G10: 25.140175 | I10: =D10*2 -> -1.5887551 | J10: =E10*2 -> -2.5120726 | K10: =F10*2 -> 2.1494828 | L10: =G10*2 -> 50.28035
C11: SE | D11: 3.2892115 | E11: 0.71438381 | F11: 18.522373 | G11: 8.2759199 | I11: =D11*2 -> 6.578423 | J11: =E11*2 -> 1.4287676 | K11: =F11*2 -> 37.044747 | L11: =G11*2 -> 16.55184
C12: T1 | D12: -1.2779629 | E12: 5.0778552 | F12: 1.7685664 | G12: 5.9899444 | I12: =D12*2 -> -2.5559258 | J12: =E12*2 -> 10.15571 | K12: =F12*2 -> 3.5371328 | L12: =G12*2 -> 11.979889
C13: SE | D13: 20.111756 | E13: 12.132033 | F13: 2.9356909 | G13: 6.0668346 | I13: =D13*2 -> 40.223512 | J13: =E13*2 -> 24.264065 | K13: =F13*2 -> 5.8713818 | L13: =G13*2 -> 12.133669
C14: T2 | D14: 17.208455 | E14: 3.9047069 | F14: 26.811999 | G14: 31.459685 | I14: =D14*2 -> 34.416909 | J14: =E14*2 -> 7.8094139 | K14: =F14*2 -> 53.623997 | L14: =G14*2 -> 62.91937
C15: SE | D15: 38.779079 | E15: 9.0527661 | F15: 2.5524424 | G15: 35.390006 | I15: =D15*2 -> 77.558158 | J15: =E15*2 -> 18.105532 | K15: =F15*2 -> 5.1048847 | L15: =G15*2 -> 70.780013
B16: Net 29 | C16: T0 | H16: *All controls, no isotopic amendments - Can only calculate net flux of 28-N2 (N-fix + DNF) and O2 (SOD)
C17: SE
C18: T1
C19: SE
C20: T2
C21: SE | J21: µ
B22: Net 30 | C22: T0
C23: SE
C24: T1
C25: SE
C26: T2
C27: SE
B28: DNF Pot | C28: T0
C29: SE
C30: T1
C31: SE
C32: T2
C33: SE
B34: 15:14 | C34: T0
C35: SE
C36: T1
C37: SE
C38: T2
C39: SE
B40: 29:30 | C40: T0
...

Sheet ANOVA
A3: Site | C3: Time | D3: =Data!D3 -> grasses | E3: =Data!E3 -> SAV | F3: =Data!F3 -> hardwoods | G3: =Data!G3 -> typha
B4: Net O2 | C4: T0 | D4: =Data!D4 -> -301.63537 | E4: =Data!E4 -> -497.3244 | F4: =Data!F4 -> -635.18972 | G4: =Data!G4 -> -884.36632
C5: T1 | D5: =Data!D6 -> -753.63861 | E5: =Data!E6 -> -871.92704 | F5: =Data!F6 -> -1266.8516 | G5: =Data!G6 -> -1038.6274
C6: T2 | D6: =Data!D8 -> -434.81294 | E6: =Data!E8 -> -944.26845 | F6: =Data!F8 -> -1070.3202 | G6: =Data!G8 -> -591.59293
C7: Avg | D7: =AVERAGE(D4:D6) -> -496.69564 | E7: =AVERAGE(E4:E6) -> -771.1733 | F7: =AVERAGE(F4:F6) -> -990.78718 | G7: =AVERAGE(G4:G6) -> -838.19555
C8: SE | D8: =STDEV(D4:D6)/SQRT(3) -> 134.1005 | E8: =STDEV(E4:E6)/SQRT(3) -> 138.5078 | F8: =STDEV(F4:F6)/SQRT(3) -> 186.63092 | G8: =STDEV(G4:G6)/SQRT(3) -> 131.09635
B9: Net 28 | C9: T0 | D9: =Data!D10 -> -0.79437753 | E9: =Data!E10 -> -1.2560363 | F9: =Data!F10 -> 1.0747414 | G9: =Data!G10 -> 25.140175
C10: T1 | D10: =Data!D12 -> -1.2779629 | E10: =Data!E12 -> 5.0778552 | F10: =Data!F12 -> 1.7685664 | G10: =Data!G12 -> 5.9899444
C11: T2 | D11: =Data!D14 -> 17.208455 | E11: =Data!E14 -> 3.9047069 | F11: =Data!F14 -> 26.811999 | G11: =Data!G14 -> 31.459685
C12: Avg | D12: =AVERAGE(D9:D11) -> 5.0453714 | E12: =AVERAGE(E9:E11) -> 2.5755086 | F12: =AVERAGE(F9:F11) -> 9.8851021 | G12: =AVERAGE(G9:G11) -> 20.863268
C13: SE | D13: =STDEV(D9:D11)/SQRT(3) -> 6.0831436 | E13: =STDEV(E9:E11)/SQRT(3) -> 1.9454752 | F13: =STDEV(F9:F11)/SQRT(3) -> 8.4658178 | G13: =STDEV(G9:G11)/SQRT(3) -> 7.6571508
B14: Net 29 | C14: T0 | D14: =Data!D16 -> 0 | E14: =Data!E16 -> 0 | F14: =Data!F16 -> 0 | G14: =Data!G16 -> 0
C15: T1 | D15: =Data!D18 -> 0 | E15: =Data!E18 -> 0 | F15: =Data!F18 -> 0 | G15: =Data!G18 -> 0
C16: T2 | D16: =Data!D20 -> 0 | E16: =Data!E20 -> 0 | F16: =Data!F20 -> 0 | G16: =Data!G20 -> 0
C17: Avg | D17: =AVERAGE(D14:D16) -> 0 | E17: =AVERAGE(E14:E16) -> 0 | F17: =AVERAGE(F14:F16) -> 0 | G17: =AVERAGE(G14:G16) -> 0
C18: SE | D18: =STDEV(D14:D16)/SQRT(3) -> 0 | E18: =STDEV(E14:E16)/SQRT(3) -> 0 | F18: =STDEV(F14:F16)/SQRT(3) -> 0 | G18: =STDEV(G14:G16)/SQRT(3) -> 0
B19: Net 30 | C19: T0 | D19: =Data!D22 -> 0 | E19: =Data!E22 -> 0 | F19: =Data!F22 -> 0 | G19: =Data!G22 -> 0
C20: T1 | D20: =Data!D24 -> 0 | E20: =Data!E24 -> 0 | F20: =Data!F24 -> 0 | G20: =Data!G24 -> 0
C21: T2 | D21: =Data!D26 -> 0 | E21: =Data!E26 -> 0 | F21: =Data!F26 -> 0 | G21: =Data!G26 -> 0
C22: Avg | D22: =AVERAGE(D19:D21) -> 0 | E22: =AVERAGE(E19:E21) -> 0 | F22: =AVERAGE(F19:F21) -> 0 | G22: =AVERAGE(G19:G21) -> 0
C23: SE | D23: =STDEV(D19:D21)/SQRT(3) -> 0 | E23: =STDEV(E19:E21)/SQRT(3) -> 0 | F23: =STDEV(F19:F21)/SQRT(3) -> 0 | G23: =STDEV(G19:G21)/SQRT(3) -> 0
B24: DNF Pot | C24: T0 | E24: =Data!E28 -> 0 | F24: =Data!F28 -> 0
C25: T1 | E25: =Data!E30 -> 0 | F25: =Data!F30 -> 0
C26: T2 | E26: =Data!E32 -> 0 | F26: =Data!F32 -> 0
C27: Avg | E27: =AVERAGE(E24:E26) -> 0 | F27: =AVERAGE(F24:F26) -> 0
C28: SE | E28: =STDEV(E24:E26)/SQRT(3) -> 0 | F28: =STDEV(F24:F26)/SQRT(3) -> 0
B29: 15:14 | C29: T0 | E29: =Data!E34 -> 0 | F29: =Data!F34 -> 0
C30: T1 | E30: =Data!E36 -> 0 | F30: =Data!F36 -> 0
C31: T2 | E31: =Data!E38 -> 0 | F31: =Data!F38 -> 0
C32: Avg | E32: =AVERAGE(E29:E31) -> 0 | F32: =AVERAGE(F29:F31) -> 0
C33: SE | E33: =STDEV(E29:E31)/SQRT(3) -> 0 | F33: =STDEV(F29:F31)/SQRT(3) -> 0
B34: 29:30 | C34: T0 | D34: =Data!D40 -> 0 | E34: =Data!E40 -> 0 | F34: =Data!F40 -> 0 | G34: =Data!G40 -> 0
C35: T1 | D35: =Data!D42 -> 0 | E35: =Data!E42 -> 0 | F35: =Data!F42 -> 0 | G35: =Data!G42 -> 0
C36: T2 | D36: =Data!D44 -> 0 | E36: =Data!E44 -> 0 | F36: =Data!F44 -> 0 | G36: =Data!G44 -> 0
C37: Avg | D37: =AVERAGE(D34:D36) -> 0 | E37: =AVERAGE(E34:E36) -> 0 | F37: =AVERAGE(F34:F36) -> 0 | G37: =AVERAGE(G34:G36) -> 0
C38: SE | D38: =STDEV(D34:D36)/SQRT(3) -> 0 | E38: =STDEV(E34:E36)/SQRT(3) -> 0 | F38: =STDEV(F34:F36)/SQRT(3) -> 0 | G38: =STDEV(G34:G36)/SQRT(3) -> 0
B39: N Fix | C39: T0 | F39: =Data!F46 -> 0
C40: T1 | F40: =Data!F48 -> 0
C41: T2 | F41: =Data!F50 -> 0
C42: Avg | F42: =AVERAGE(F39:F41) -> 0
...
