Workbook

Sheet Data
A1: Run Date | C1: time | D1: RoomTemp:
A3: N2 w/pump off:
A4: N2 w/pump on:
D5: =D3/D4 -> #DIV/0!
A6: Site Name
A7: Sampling Date
A9: Sample | B9: Index | C9: Time | D9: N28 | E9: N29 | F9: N30 | G9: Ar | H9: O2 | I9: Time
A10: Calibrate_20C | B10: 4384 | C10: 0.52340278 | D10: 2.818135e-10 | G10: 1.203577e-11 | H10: 1.360045e-10 | I10: =N10-N$10 -> 0 | J10: 0.52340278 | K10: 12 | L10: 33 | M10: 42 | N10: =(K10)*60+L10+M10/60 -> 753.7
A11: Calibrate_20C | B11: 4391 | C11: 0.52351852 | D11: 2.81585e-10 | G11: 1.203473e-11 | H11: 1.3596e-10 | I11: =N11-N$10 -> 0.16666667 | J11: 0.52351852 | K11: 12 | L11: 33 | M11: 52 | N11: =(K11)*60+L11+M11/60 -> 753.86667
A12: Calibrate_20C | B12: 4395 | C12: 0.52359954 | D12: 2.815194e-10 | G12: 1.202796e-11 | H12: 1.359599e-10 | I12: =N12-N$10 -> 0.28333333 | J12: 0.52359954 | K12: 12 | L12: 33 | M12: 59 | N12: =(K12)*60+L12+M12/60 -> 753.98333
A13: Calibrate_30C | B13: 4628 | C13: 0.52775463 | D13: 2.498668e-10 | G13: 1.013802e-11 | H13: 1.15499e-10 | I13: =N13-N$10 -> 6.2666667 | J13: 0.52775463 | K13: 12 | L13: 39 | M13: 58 | N13: =(K13)*60+L13+M13/60 -> 759.96667
A14: Calibrate_30C | B14: 4633 | C14: 0.52784722 | D14: 2.501551e-10 | G14: 1.014492e-11 | H14: 1.155769e-10 | I14: =N14-N$10 -> 6.4 | J14: 0.52784722 | K14: 12 | L14: 40 | M14: 6 | N14: =(K14)*60+L14+M14/60 -> 760.1
A15: Calibrate_30C | B15: 4635 | C15: 0.52788194 | D15: 2.499926e-10 | G15: 1.013835e-11 | H15: 1.154703e-10 | I15: =N15-N$10 -> 6.45 | J15: 0.52788194 | K15: 12 | L15: 40 | M15: 9 | N15: =(K15)*60+L15+M15/60 -> 760.15
A16: grassesIN_T0_1 | B16: 4942 | C16: 0.53335648 | D16: 2.531977e-10 | G16: 1.058717e-11 | H16: 9.673242e-11 | I16: =N16-N$10 -> 14.333333 | J16: 0.53335648 | K16: 12 | L16: 48 | M16: 2 | N16: =(K16)*60+L16+M16/60 -> 768.03333
A17: grassesIN_T0_2 | B17: 4946 | C17: 0.53342593 | D17: 2.532855e-10 | G17: 1.059599e-11 | H17: 9.665579e-11 | I17: =N17-N$10 -> 14.433333 | J17: 0.53342593 | K17: 12 | L17: 48 | M17: 8 | N17: =(K17)*60+L17+M17/60 -> 768.13333
A18: grassesIN_T0_3 | B18: 4950 | C18: 0.53350694 | D18: 2.534145e-10 | G18: 1.060106e-11 | H18: 9.669117e-11 | I18: =N18-N$10 -> 14.55 | J18: 0.53350694 | K18: 12 | L18: 48 | M18: 15 | N18: =(K18)*60+L18+M18/60 -> 768.25
A19: 1_T0_1 | B19: 5065 | C19: 0.53555556 | D19: 2.468768e-10 | G19: 1.030786e-11 | H19: 7.128617e-11 | I19: =N19-N$10 -> 17.5 | J19: 0.53555556 | K19: 12 | L19: 51 | M19: 12 | N19: =(K19)*60+L19+M19/60 -> 771.2
A20: 1_T0_2 | B20: 5068 | C20: 0.53561343 | D20: 2.467791e-10 | G20: 1.03053e-11 | H20: 7.111498e-11 | I20: =N20-N$10 -> 17.583333 | J20: 0.53561343 | K20: 12 | L20: 51 | M20: 17 | N20: =(K20)*60+L20+M20/60 -> 771.28333
A21: 1_T0_3 | B21: 5070 | C21: 0.53564815 | D21: 2.467689e-10 | G21: 1.030689e-11 | H21: 7.102859e-11 | I21: =N21-N$10 -> 17.633333 | J21: 0.53564815 | K21: 12 | L21: 51 | M21: 20 | N21: =(K21)*60+L21+M21/60 -> 771.33333
... A27: Calibrate_20C | B27: 5382 | C27: 0.54121528 | D27: 2.823771e-10 | G27: 1.196707e-11 | H27: 1.337087e-10 | I27: =N27-N$10 -> 25.65 | J27: 0.54121528 | K27: 12 | L27: 59 | M27: 21 | N27: =(K27)*60+L27+M27/60 -> 779.35
A28: Calibrate_30C | B28: 5549 | C28: 0.54420139 | D28: 2.423149e-10 | G28: 9.894056e-12 | H28: 1.120657e-10 | I28: =N28-N$10 -> 29.95 | J28: 0.54420139 | K28: 1 | L28: 3 | M28: 39 | N28: =(12+K28)*60+L28+M28/60 -> 783.65
A29: Calibrate_30C | B29: 5554 | C29: 0.54428241 | D29: 2.421794e-10 | G29: 9.884355e-12 | H29: 1.120074e-10 | I29: =N29-N$10 -> 30.066667 | J29: 0.54428241 | K29: 1 | L29: 3 | M29: 46 | N29: =(12+K29)*60+L29+M29/60 -> 783.76667
A30: Calibrate_30C | B30: 5558 | C30: 0.54435185 | D30: 2.421555e-10 | G30: 9.884537e-12 | H30: 1.120135e-10 | I30: =N30-N$10 -> 30.166667 | J30: 0.54435185 | K30: 1 | L30: 3 | M30: 52 | N30: =(12+K30)*60+L30+M30/60 -> 783.86667
A31: 3_T0_1 | B31: 5740 | C31: 0.54760417 | D31: 2.4775e-10 | G31: 1.037639e-11 | H31: 9.744901e-11 | I31: =N31-N$10 -> 34.85 | J31: 0.54760417 | K31: 1 | L31: 8 | M31: 33 | N31: =(12+K31)*60+L31+M31/60 -> 788.55
A32: 3_T0_2 | B32: 5744 | C32: 0.54767361 | D32: 2.477313e-10 | G32: 1.037721e-11 | H32: 9.742399e-11 | I32: =N32-N$10 -> 34.95 | J32: 0.54767361 | K32: 1 | L32: 8 | M32: 39 | N32: =(12+K32)*60+L32+M32/60 -> 788.65
A33: 3_T0_3 | B33: 5745 | C33: 0.54769676 | D33: 2.476856e-10 | G33: 1.037691e-11 | H33: 9.744171e-11 | I33: =N33-N$10 -> 34.983333 | J33: 0.54769676 | K33: 1 | L33: 8 | M33: 41 | N33: =(12+K33)*60+L33+M33/60 -> 788.68333
A34: openwaterIN_T0_1 | B34: 5895 | C34: 0.55037037 | D34: 2.504726e-10 | G34: 1.047354e-11 | H34: 9.500548e-11 | I34: =N34-N$10 -> 38.833333 | J34: 0.55037037 | K34: 1 | L34: 12 | M34: 32 | N34: =(12+K34)*60+L34+M34/60 -> 792.53333
A35: openwaterIN_T0_2 | B35: 5900 | C35: 0.55046296 | D35: 2.503256e-10 | G35: 1.046105e-11 | H35: 9.496401e-11 | I35: =N35-N$10 -> 38.966667 | J35: 0.55046296 | K35: 1 | L35: 12 | M35: 40 | N35: =(12+K35)*60+L35+M35/60 -> 792.66667
A36: openwaterIN_T0_3 | B36: 5906 | C36: 0.55056713 | D36: 2.502046e-10 | G36: 1.045602e-11 | H36: 9.489412e-11 | I36: =N36-N$10 -> 39.116667 | J36: 0.55056713 | K36: 1 | L36: 12 | M36: 49 | N36: =(12+K36)*60+L36+M36/60 -> 792.81667
A37: 4_T0_1 | B37: 6016 | C37: 0.55253472 | D37: 2.483189e-10 | G37: 1.038426e-11 | H37: 7.975403e-11 | I37: =N37-N$10 -> 41.95 | J37: 0.55253472 | K37: 1 | L37: 15 | M37: 39 | N37: =(12+K37)*60+L37+M37/60 -> 795.65
A38: 4_T0_2 | B38: 6019 | C38: 0.55258102 | D38: 2.482318e-10 | G38: 1.038185e-11 | H38: 7.963923e-11 | I38: =N38-N$10 -> 42.016667 | J38: 0.55258102 | K38: 1 | L38: 15 | M38: 43 | N38: =(12+K38)*60+L38+M38/60 -> 795.71667
A39: 4_T0_3 | B39: 6023 | C39: 0.55266204 | D39: 2.482256e-10 | G39: 1.037825e-11 | H39: 7.953364e-11 | I39: =N39-N$10 -> 42.133333 | J39: 0.55266204 | K39: 1 | L39: 15 | M39: 50 | N39: =(12+K39)*60+L39+M39/60 -> 795.83333
... A255: Calibrate_30C | B255: 16246 | C255: 0.73518519 | D255: 2.007826e-10 | G255: 8.202767e-12 | H255: 9.349865e-11 | I255: =N255-N$10 -> 304.96667 | J255: 0.73518519 | K255: 5 | L255: 38 | M255: 40 | N255: =(12+K255)*60+L255+M255/60 -> 1058.6667

Sheet Regs
A1: 20/0 | D1: SUMMARY OUTPUT
A3: N2/Ar | B3: time(min) | D3: Regression Statistics
A4: =Data!D10/Data!G10 -> 23.414663 | B4: =Data!I10 -> 0 | D4: Multiple R | E4: 0.32819059
A5: =Data!D11/Data!G11 -> 23.3977 | B5: =Data!I11 -> 0.16666667 | D5: R Square | E5: 0.10770906
A6: =Data!D12/Data!G12 -> 23.405415 | B6: =Data!I12 -> 0.28333333 | D6: Adjusted R Square | E6: 0.05194088
A7: =Data!D25/Data!G25 -> 23.638415 | B7: =Data!I25 -> 25.45 | D7: Standard Error | E7: 0.073523614
A8: =Data!D26/Data!G26 -> 23.597249 | B8: =Data!I26 -> 25.55 | D8: Observations | E8: 18
A9: =Data!D27/Data!G27 -> 23.596177 | B9: =Data!I27 -> 25.65
A10: =Data!D100/Data!G100 -> 23.529014 | B10: =Data!I100 -> 119.13333 | D10: ANOVA
A11: =Data!D101/Data!G101 -> 23.538164 | B11: =Data!I101 -> 119.23333 | E11: df | F11: SS | G11: MS | H11: F | I11: Significance F
A12: =Data!D102/Data!G102 -> 23.507808 | B12: =Data!I102 -> 119.3 | D12: Regression | E12: 1 | F12: 0.010440455 | G12: 0.010440455 | H12: 1.9313712 | I12: 0.18364418
A13: =Data!D115/Data!G115 -> 23.551483 | B13: =Data!I115 -> 145.83333 | D13: Residual | E13: 16 | F13: 0.086491549 | G13: 0.0054057218
A14: =Data!D116/Data!G116 -> 23.543678 | B14: =Data!I116 -> 145.91667 | D14: Total | E14: 17 | F14: 0.096932004
A15: =Data!D117/Data!G117 -> 23.555497 | B15: =Data!I117 -> 145.98333
A16: =Data!D205/Data!G205 -> 23.460173 | B16: =Data!I205 -> 253.75 | E16: Coefficients | F16: Standard Error | G16: t Stat | H16: P-value | I16: Lower 95% | J16: Upper 95% | K16: Lower 95.0% | L16: Upper 95.0%
A17: =Data!D206/Data!G206 -> 23.463449 | B17: =Data!I206 -> 253.8 | D17: Intercept | E17: 23.528266 | F17: 0.02823562 | G17: 833.28312 | H17: 1.5606357e-38 | I17: 23.468409 | J17: 23.588122 | K17: 23.468409 | L17: 23.588122
A18: =Data!D207/Data!G207 -> 23.494448 | B18: =Data!I207 -> 253.9 | D18: X Variable 1 | E18: -0.00021974378 | F18: 0.00015811888 | G18: -1.3897378 | H18: 0.18364418 | I18: -0.00055494082 | J18: 0.00011545326 | K18: -0.00055494082 | L18: 0.00011545326
A19: =Data!D250/Data!G250 -> 23.419945 | B19: =Data!I250 -> 301.11667
A20: =Data!D251/Data!G251 -> 23.419502 | B20: =Data!I251 -> 301.25
A21: =Data!D252/Data!G252 -> 23.418358 | B21: =Data!I252 -> 301.36667
A23: 30/0 | D23: SUMMARY OUTPUT
A25: N2/Ar | B25: time(min) | D25: Regression Statistics
A26: =Data!D13/Data!G13 -> 24.646509 | B26: =Data!I13 -> 6.2666667 | D26: Multiple R | E26: 0.21109726
A27: =Data!D14/Data!G14 -> 24.658164 | B27: =Data!I14 -> 6.4 | D27: R Square | E27: 0.044562053
A28: =Data!D15/Data!G15 -> 24.658115 | B28: =Data!I15 -> 6.45 | D28: Adjusted R Square | E28: -0.015152818
A29: =Data!D28/Data!G28 -> 24.490957 | B29: =Data!I28 -> 29.95 | D29: Standard Error | E29: 0.14595492
A30: =Data!D29/Data!G29 -> 24.501285 | B30: =Data!I29 -> 30.066667 | D30: Observations | E30: 18
A31: =Data!D30/Data!G30 -> 24.498416 | B31: =Data!I30 -> 30.166667
A32: =Data!D103/Data!G103 -> 24.277982 | B32: =Data!I103 -> 128.9 | D32: ANOVA
A33: =Data!D104/Data!G104 -> 24.278899 | B33: =Data!I104 -> 128.96667 | E33: df | F33: SS | G33: MS | H33: F | I33: Significance F
A34: =Data!D105/Data!G105 -> 24.272016 | B34: =Data!I105 -> 129.08333 | D34: Regression | E34: 1 | F34: 0.015897182 | G34: 0.015897182 | H34: 0.74624716 | I34: 0.40043227
A35: =Data!D118/Data!G118 -> 24.248081 | B35: =Data!I118 -> 149.2 | D35: Residual | E35: 16 | F35: 0.34084541 | G35: 0.021302838
A36: =Data!D119/Data!G119 -> 24.243371 | B36: =Data!I119 -> 149.25 | D36: Total | E36: 17 | F36: 0.35674259
A37: =Data!D120/Data!G120 -> 24.263284 | B37: =Data!I120 -> 149.28333
A38: =Data!D208/Data!G208 -> 24.508789 | B38: =Data!I208 -> 256.98333 | E38: Coefficients | F38: Standard Error | G38: t Stat | H38: P-value | I38: Lower 95% | J38: Upper 95% | K38: Lower 95.0% | L38: Upper 95.0%
A39: =Data!D209/Data!G209 -> 24.515191 | B39: =Data!I209 -> 257.06667 | D39: Intercept | E39: 24.486005 | F39: 0.05765327 | G39: 424.71148 | H39: 7.52079e-34 | I39: 24.363786 | J39: 24.608225 | K39: 24.363786 | L39: 24.608225
A40: =Data!D210/Data!G210 -> 24.525299 | B40: =Data!I210 -> 257.2 | D40: X Variable 1 | E40: -0.00027354826 | F40: 0.00031665957 | G40: -0.86385598 | H40: 0.40043227 | I40: -0.00094483656 | J40: 0.00039774003 | K40: -0.00094483656 | L40: 0.00039774003
A41: =Data!D253/Data!G253 -> 24.481075 | B41: =Data!I253 -> 304.76667
A42: =Data!D254/Data!G254 -> 24.483854 | B42: =Data!I254 -> 304.86667
A43: =Data!D255/Data!G255 -> 24.477423 | B43: =Data!I255 -> 304.96667
...

Sheet 28N2-O2
C1: Actual | G1: N2(20/0) | H1: O2(20/0)
B2: N2/Ar | C2: O2/Ar | D2: Ar | F2: r2 | G2: =Regs!E5 -> 0.10770906 | H2: =Regs!E49 -> 0.252402
A3: 20/0 | B3: 38.187 | C3: 20.393 | D3: 13.9 | F3: intercept | G3: =Regs!E17 -> 23.528266 | H3: =Regs!E61 -> 11.213162
A4: 30/0 | B4: 38.861 | C4: 20.38 | D4: 11.6 | F4: slope | G4: =Regs!E18 -> -0.00021974378 | H4: =Regs!E62 -> -0.00053602621
A6: D= | B6: =(Regs!E39+Regs!E40*(Data!I255/2))-(Regs!E17+Regs!E18*(Data!I255/2)) -> 0.94953558
A7: Avg CF= | B7: =AVERAGE(D13:D15,D28:D30,D103:D105,D118:D120,D208:D210,D253:D255) -> 1.6251823 | C7: =AVERAGE(F13:F15,F28:F30,F103:F105,F118:F120,F208:F210,F253:F255) -> 1.8312083
A8: Adj. D= | B8: =B6*B7 -> 1.5431684
A9: Factor= | B9: =B8/(B4-B3) -> 2.2895674
E11: Measured | J11: Actual
A12: Sample ID | B12: time (min) | C12: N2/Ar | D12: CF | E12: O2/Ar | F12: CF | G12: N2 D | H12: O2 D | I12: N2/Ar | J12: O2/Ar | K12: N2 | L12: O2 | M12: Avg N2 | N12: Avg O2 | O12: Sample ID
A13: =Data!A10 -> Calibrate_20C | B13: =Data!I10 -> 0 | C13: =Data!D10/Data!G10 -> 23.414663 | D13: =B$3/C13 -> 1.6309011 | E13: =Data!H10/Data!G10 -> 11.300025 | F13: =C$3/E13 -> 1.8046863 | G13: =C13-(G$3+G$4*B13) -> -0.11360241 | H13: =E13-(H$3+H$4*B13) -> 0.086862567 | I13: =G13*(B$7/B$9)+B$3 -> 38.106363 | J13: =H13*(C$7)+C$3 -> 20.552063 | K13: =I13*D$3 -> 529.67844 | L13: =J13*D$3 -> 285.67368 | O13: =Data!A10 -> Calibrate_20C
B14: =Data!I11 -> 0.16666667 | C14: =Data!D11/Data!G11 -> 23.3977 | D14: =B$3/C14 -> 1.6320835 | E14: =Data!H11/Data!G11 -> 11.297304 | F14: =C$3/E14 -> 1.805121 | G14: =C14-(G$3+G$4*B14) -> -0.13052908 | H14: =E14-(H$3+H$4*B14) -> 0.084230783 | I14: =G14*(B$7/B$9)+B$3 -> 38.094348 | J14: =H14*(C$7)+C$3 -> 20.547244 | K14: =I14*D$3 -> 529.51143 | L14: =J14*D$3 -> 285.60669
B15: =Data!I12 -> 0.28333333 | C15: =Data!D12/Data!G12 -> 23.405415 | D15: =B$3/C15 -> 1.6315455 | E15: =Data!H12/Data!G12 -> 11.303654 | F15: =C$3/E15 -> 1.8041069 | G15: =C15-(G$3+G$4*B15) -> -0.12278789 | H15: =E15-(H$3+H$4*B15) -> 0.090643751 | I15: =G15*(B$7/B$9)+B$3 -> 38.099843 | J15: =H15*(C$7)+C$3 -> 20.558988 | K15: =I15*D$3 -> 529.58781 | L15: =J15*D$3 -> 285.76993
A16: =Data!A13 -> Calibrate_30C | B16: =Data!I13 -> 6.2666667 | C16: =Data!D13/Data!G13 -> 24.646509 | D16: =B$4/C16 -> 1.5767345 | E16: =Data!H13/Data!G13 -> 11.392659 | F16: =C$4/E16 -> 1.7888713 | G16: =C16-(G$3+G$4*B16) -> 1.1196204 | H16: =E16-(H$3+H$4*B16) -> 0.18285535 | I16: =G16*(B$7/B$9)+B$3 -> 38.98173 | J16: =H16*(C$7)+C$3 -> 20.727846 | K16: =I16*D$3 -> 541.84604 | L16: =J16*D$3 -> 288.11706 | O16: =Data!A13 -> Calibrate_30C
B17: =Data!I14 -> 6.4 | C17: =Data!D14/Data!G14 -> 24.658164 | D17: =B$4/C17 -> 1.5759892 | E17: =Data!H14/Data!G14 -> 11.392589 | F17: =C$4/E17 -> 1.7888823 | G17: =C17-(G$3+G$4*B17) -> 1.1313047 | H17: =E17-(H$3+H$4*B17) -> 0.1828569 | I17: =G17*(B$7/B$9)+B$3 -> 38.990023 | J17: =H17*(C$7)+C$3 -> 20.727849 | K17: =I17*D$3 -> 541.96133 | L17: =J17*D$3 -> 288.1171
B18: =Data!I15 -> 6.45 | C18: =Data!D15/Data!G15 -> 24.658115 | D18: =B$4/C18 -> 1.5759923 | E18: =Data!H15/Data!G15 -> 11.389457 | F18: =C$4/E18 -> 1.7893742 | G18: =C18-(G$3+G$4*B18) -> 1.1312668 | H18: =E18-(H$3+H$4*B18) -> 0.17975196 | I18: =G18*(B$7/B$9)+B$3 -> 38.989997 | J18: =H18*(C$7)+C$3 -> 20.722163 | K18: =I18*D$3 -> 541.96095 | L18: =J18*D$3 -> 288.03807
A19: =Data!A16 -> grassesIN_T0_1 | B19: =Data!I16 -> 14.333333 | C19: =Data!D16/Data!G16 -> 23.915522 | D19: =B$3/C19 -> 1.5967454 | E19: =Data!H16/Data!G16 -> 9.1367589 | F19: =C$3/E19 -> 2.2319731 | G19: =C19-(G$3+G$4*B19) -> 0.39040641 | H19: =E19-(H$3+H$4*B19) -> -2.0687203 | I19: =G19*(B$7/B$9)+B$3 -> 38.464119 | J19: =H19*(C$7)+C$3 -> 16.604742 | K19: =I19*D$3 -> 534.65125 | L19: =J19*D$3 -> 230.80592 | M19: =AVERAGE(K19:K21) -> 534.57746 | N19: =AVERAGE(L19:L21) -> 230.54688 | O19: =Data!A16 -> grassesIN_T0_1 | P19: =STDEV(K19:K21)/SQRT(3) -> 0.03695755 | Q19: =STDEV(L19:L21)/SQRT(3) -> 0.1297109
B20: =Data!I17 -> 14.433333 | C20: =Data!D17/Data!G17 -> 23.903901 | D20: =B$3/C20 -> 1.5975217 | E20: =Data!H17/Data!G17 -> 9.1219216 | F20: =C$3/E20 -> 2.2356035 | G20: =C20-(G$3+G$4*B20) -> 0.37880749 | H20: =E20-(H$3+H$4*B20) -> -2.083504 | I20: =G20*(B$7/B$9)+B$3 -> 38.455885 | J20: =H20*(C$7)+C$3 -> 16.57767 | K20: =I20*D$3 -> 534.53681 | L20: =J20*D$3 -> 230.42961
B21: =Data!I18 -> 14.55 | C21: =Data!D18/Data!G18 -> 23.904638 | D21: =B$3/C21 -> 1.5974724 | E21: =Data!H18/Data!G18 -> 9.1208964 | F21: =C$3/E21 -> 2.2358548 | G21: =C21-(G$3+G$4*B21) -> 0.37956958 | H21: =E21-(H$3+H$4*B21) -> -2.0844667 | I21: =G21*(B$7/B$9)+B$3 -> 38.456426 | J21: =H21*(C$7)+C$3 -> 16.575907 | K21: =I21*D$3 -> 534.54433 | L21: =J21*D$3 -> 230.40511
A22: =Data!A19 -> 1_T0_1 | B22: =Data!I19 -> 17.5 | C22: =Data!D19/Data!G19 -> 23.950345 | D22: =B$4/C22 -> 1.6225654 | E22: =Data!H19/Data!G19 -> 6.91571 | F22: =C$4/E22 -> 2.9469136 | G22: =C22-(G$3+G$4*B22) -> 0.42592467 | H22: =E22-(H$3+H$4*B22) -> -4.2880719 | I22: =G22*(B$7/B$9)+B$3 -> 38.48933 | J22: =H22*(C$7)+C$3 -> 12.540647 | K22: =I22*D$3 -> 535.00169 | L22: =J22*D$3 -> 174.31499 | M22: =AVERAGE(K22:K24) -> 534.96322 | N22: =AVERAGE(L22:L24) -> 173.98309 | O22: =Data!A19 -> 1_T0_1 | P22: =STDEV(K22:K24)/SQRT(3) -> 0.023391763 | Q22: =STDEV(L22:L24)/SQRT(3) -> 0.17980519
B23: =Data!I20 -> 17.583333 | C23: =Data!D20/Data!G20 -> 23.946814 | D23: =B$4/C23 -> 1.6228046 | E23: =Data!H20/Data!G20 -> 6.9008161 | F23: =C$4/E23 -> 2.9532739 | G23: =C23-(G$3+G$4*B23) -> 0.42241207 | H23: =E23-(H$3+H$4*B23) -> -4.3029211 | I23: =G23*(B$7/B$9)+B$3 -> 38.486837 | J23: =H23*(C$7)+C$3 -> 12.513455 | K23: =I23*D$3 -> 534.96703 | L23: =J23*D$3 -> 173.93703
B24: =Data!I21 -> 17.633333 | C24: =Data!D21/Data!G21 -> 23.94213 | D24: =B$4/C24 -> 1.6231221 | E24: =Data!H21/Data!G21 -> 6.8913698 | F24: =C$4/E24 -> 2.9573221 | G24: =C24-(G$3+G$4*B24) -> 0.41773926 | H24: =E24-(H$3+H$4*B24) -> -4.3123406 | I24: =G24*(B$7/B$9)+B$3 -> 38.48352 | J24: =H24*(C$7)+C$3 -> 12.496206 | K24: =I24*D$3 -> 534.92093 | L24: =J24*D$3 -> 173.69726
A25: =Data!A22 -> 2_T0_1 | B25: =Data!I22 -> 21.35 | C25: =Data!D22/Data!G22 -> 23.876689 | E25: =Data!H22/Data!G22 -> 8.6803599 | G25: =C25-(G$3+G$4*B25) -> 0.35311531 | H25: =E25-(H$3+H$4*B25) -> -2.5213582 | I25: =G25*(B$7/B$9)+B$3 -> 38.437649 | J25: =H25*(C$7)+C$3 -> 15.775868 | K25: =I25*D$3 -> 534.28331 | L25: =J25*D$3 -> 219.28456 | M25: =AVERAGE(K25:K27) -> 534.33696 | N25: =AVERAGE(L25:L27) -> 219.52894 | O25: =Data!A22 -> 2_T0_1 | P25: =STDEV(K25:K27)/SQRT(3) -> 0.026902823 | Q25: =STDEV(L25:L27)/SQRT(3) -> 0.14353151
B26: =Data!I23 -> 21.466667 | C26: =Data!D23/Data!G23 -> 23.88445 | E26: =Data!H23/Data!G23 -> 8.6895739 | G26: =C26-(G$3+G$4*B26) -> 0.36090114 | H26: =E26-(H$3+H$4*B26) -> -2.5120817 | I26: =G26*(B$7/B$9)+B$3 -> 38.443175 | J26: =H26*(C$7)+C$3 -> 15.792855 | K26: =I26*D$3 -> 534.36013 | L26: =J26*D$3 -> 219.52069
B27: =Data!I24 -> 21.583333 | C27: =Data!D24/Data!G24 -> 23.885162 | E27: =Data!H24/Data!G24 -> 8.6997605 | G27: =C27-(G$3+G$4*B27) -> 0.3616395 | H27: =E27-(H$3+H$4*B27) -> -2.5018325 | I27: =G27*(B$7/B$9)+B$3 -> 38.443699 | J27: =H27*(C$7)+C$3 -> 15.811623 | K27: =I27*D$3 -> 534.36742 | L27: =J27*D$3 -> 219.78157
A28: =Data!A25 -> Calibrate_20C | B28: =Data!I25 -> 25.45 | C28: =Data!D25/Data!G25 -> 23.638415 | D28: =B$3/C28 -> 1.6154636 | E28: =Data!H25/Data!G25 -> 11.174578 | F28: =C$3/E28 -> 1.8249459 | G28: =C28-(G$3+G$4*B28) -> 0.11574207 | H28: =E28-(H$3+H$4*B28) -> -0.024942282 | I28: =G28*(B$7/B$9)+B$3 -> 38.269156 | J28: =H28*(C$7)+C$3 -> 20.347325 | K28: =I28*D$3 -> 531.94127 | L28: =J28*D$3 -> 282.82782 | M28: =AVERAGE(K28:K30) -> 531.66718 | N28: =AVERAGE(L28:L30) -> 282.76337 | O28: =Data!A25 -> Calibrate_20C | P28: =STDEV(K28:K30)/SQRT(3) -> 0.13707635 | Q28: =STDEV(L28:L30)/SQRT(3) -> 0.047559086
B29: =Data!I26 -> 25.55 | C29: =Data!D26/Data!G26 -> 23.597249 | D29: =B$3/C29 -> 1.6182819 | E29: =Data!H26/Data!G26 -> 11.168346 | F29: =C$3/E29 -> 1.8259642 | G29: =C29-(G$3+G$4*B29) -> 0.074597651 | H29: =E29-(H$3+H$4*B29) -> -0.031120617 | I29: =G29*(B$7/B$9)+B$3 -> 38.239951 | J29: =H29*(C$7)+C$3 -> 20.336012 | K29: =I29*D$3 -> 531.53532 | L29: =J29*D$3 -> 282.67056
B30: =Data!I27 -> 25.65 | C30: =Data!D27/Data!G27 -> 23.596177 | D30: =B$3/C30 -> 1.6183554 | E30: =Data!H27/Data!G27 -> 11.173052 | F30: =C$3/E30 -> 1.8251951 | G30: =C30-(G$3+G$4*B30) -> 0.073547738 | H30: =E30-(H$3+H$4*B30) -> -0.026360818 | I30: =G30*(B$7/B$9)+B$3 -> 38.239206 | J30: =H30*(C$7)+C$3 -> 20.344728 | K30: =I30*D$3 -> 531.52496 | L30: =J30*D$3 -> 282.79172
A31: =Data!A28 -> Calibrate_30C | B31: =Data!I28 -> 29.95 | C31: =Data!D28/Data!G28 -> 24.490957 | D31: =B$4/C31 -> 1.5867489 | E31: =Data!H28/Data!G28 -> 11.326568 | F31: =C$4/E31 -> 1.7993093 | G31: =C31-(G$3+G$4*B31) -> 0.96927279 | H31: =E31-(H$3+H$4*B31) -> 0.1294599 | I31: =G31*(B$7/B$9)+B$3 -> 38.87501 | J31: =H31*(C$7)+C$3 -> 20.630068 | K31: =I31*D$3 -> 540.36264 | L31: =J31*D$3 -> 286.75795 | M31: =AVERAGE(K31:K33) -> 540.42138 | N31: =AVERAGE(L31:L33) -> 286.85148 | O31: =Data!A28 -> Calibrate_30C | P31: =STDEV(K31:K33)/SQRT(3) -> 0.030468918 | Q31: =STDEV(L31:L33)/SQRT(3) -> 0.046888731
B32: =Data!I29 -> 30.066667 | C32: =Data!D29/Data!G29 -> 24.501285 | D32: =B$4/C32 -> 1.5860801 | E32: =Data!H29/Data!G29 -> 11.331786 | F32: =C$4/E32 -> 1.7984808 | G32: =C32-(G$3+G$4*B32) -> 0.97962654 | H32: =E32-(H$3+H$4*B32) -> 0.13474069 | I32: =G32*(B$7/B$9)+B$3 -> 38.882359 | J32: =H32*(C$7)+C$3 -> 20.639738 | K32: =I32*D$3 -> 540.46479 | L32: =J32*D$3 -> 286.89236
B33: =Data!I30 -> 30.166667 | C33: =Data!D30/Data!G30 -> 24.498416 | D33: =B$4/C33 -> 1.5862658 | E33: =Data!H30/Data!G30 -> 11.332195 | F33: =C$4/E33 -> 1.7984159 | G33: =C33-(G$3+G$4*B33) -> 0.97677947 | H33: =E33-(H$3+H$4*B33) -> 0.13520277 | I33: =G33*(B$7/B$9)+B$3 -> 38.880338 | J33: =H33*(C$7)+C$3 -> 20.640584 | K33: =I33*D$3 -> 540.4367 | L33: =J33*D$3 -> 286.90412
A34: =Data!A31 -> 3_T0_1 | B34: =Data!I31 -> 34.85 | C34: =Data!D31/Data!G31 -> 23.876319 | E34: =Data!H31/Data!G31 -> 9.3914174 | G34: =C34-(G$3+G$4*B34) -> 0.35571176 | H34: =E34-(H$3+H$4*B34) -> -1.8030643 | I34: =G34*(B$7/B$9)+B$3 -> 38.439492 | J34: =H34*(C$7)+C$3 -> 17.091214 | K34: =I34*D$3 -> 534.30893 | L34: =J34*D$3 -> 237.56787 | M34: =AVERAGE(K34:K36) -> 534.27262 | N34: =AVERAGE(L34:L36) -> 237.53221 | O34: =Data!A31 -> 3_T0_1 | P34: =STDEV(K34:K36)/SQRT(3) -> 0.021000733 | Q34: =STDEV(L34:L36)/SQRT(3) -> 0.023088966
B35: =Data!I32 -> 34.95 | C35: =Data!D32/Data!G32 -> 23.872631 | E35: =Data!H32/Data!G32 -> 9.3882643 | G35: =C35-(G$3+G$4*B35) -> 0.35204502 | H35: =E35-(H$3+H$4*B35) -> -1.8061639 | I35: =G35*(B$7/B$9)+B$3 -> 38.436889 | J35: =H35*(C$7)+C$3 -> 17.085538 | K35: =I35*D$3 -> 534.27275 | L35: =J35*D$3 -> 237.48897
B36: =Data!I33 -> 34.983333 | C36: =Data!D33/Data!G33 -> 23.868917 | E36: =Data!H33/Data!G33 -> 9.3902433 | G36: =C36-(G$3+G$4*B36) -> 0.3483385 | H36: =E36-(H$3+H$4*B36) -> -1.804167 | I36: =G36*(B$7/B$9)+B$3 -> 38.434258 | J36: =H36*(C$7)+C$3 -> 17.089194 | K36: =I36*D$3 -> 534.23618 | L36: =J36*D$3 -> 237.5398
A37: =Data!A34 -> openwaterIN_T0_1 | B37: =Data!I34 -> 38.833333 | C37: =Data!D34/Data!G34 -> 23.914799 | E37: =Data!H34/Data!G34 -> 9.0709999 | G37: =C37-(G$3+G$4*B37) -> 0.39506648 | H37: =E37-(H$3+H$4*B37) -> -2.1213467 | I37: =G37*(B$7/B$9)+B$3 -> 38.467426 | J37: =H37*(C$7)+C$3 -> 16.508372 | K37: =I37*D$3 -> 534.69723 | L37: =J37*D$3 -> 229.46637 | M37: =AVERAGE(K37:K39) -> 534.79271 | N37: =AVERAGE(L37:L39) -> 229.56512 | O37: =Data!A34 -> openwaterIN_T0_1 | P37: =STDEV(K37:K39)/SQRT(3) -> 0.04774212 | Q37: =STDEV(L37:L39)/SQRT(3) -> 0.052037284
B38: =Data!I35 -> 38.966667 | C38: =Data!D35/Data!G35 -> 23.9293 | E38: =Data!H35/Data!G35 -> 9.077866 | G38: =C38-(G$3+G$4*B38) -> 0.40959679 | H38: =E38-(H$3+H$4*B38) -> -2.1144091 | I38: =G38*(B$7/B$9)+B$3 -> 38.47774 | J38: =H38*(C$7)+C$3 -> 16.521076 | K38: =I38*D$3 -> 534.84059 | L38: =J38*D$3 -> 229.64296
B39: =Data!I36 -> 39.116667 | C39: =Data!D36/Data!G36 -> 23.929239 | E39: =Data!H36/Data!G36 -> 9.0755488 | G39: =C39-(G$3+G$4*B39) -> 0.40956896 | H39: =E39-(H$3+H$4*B39) -> -2.1166459 | I39: =G39*(B$7/B$9)+B$3 -> 38.477721 | J39: =H39*(C$7)+C$3 -> 16.51698 | K39: =I39*D$3 -> 534.84032 | L39: =J39*D$3 -> 229.58603
A40: =Data!A37 -> 4_T0_1 | B40: =Data!I37 -> 41.95 | C40: =Data!D37/Data!G37 -> 23.913009 | E40: =Data!H37/Data!G37 -> 7.6802805 | G40: =C40-(G$3+G$4*B40) -> 0.39396145 | H40: =E40-(H$3+H$4*B40) -> -3.5103954 | I40: =G40*(B$7/B$9)+B$3 -> 38.466642 | J40: =H40*(C$7)+C$3 -> 13.964735 | K40: =I40*D$3 -> 534.68632 | L40: =J40*D$3 -> 194.10981 | M40: =AVERAGE(K40:K42) -> 534.69315 | N40: =AVERAGE(L40:L42) -> 193.88981 | O40: =Data!A37 -> 4_T0_1 | P40: =STDEV(K40:K42)/SQRT(3) -> 0.022257357 | Q40: =STDEV(L40:L42)/SQRT(3) -> 0.12286959
B41: =Data!I38 -> 42.016667 | C41: =Data!D38/Data!G38 -> 23.91017 | E41: =Data!H38/Data!G38 -> 7.6710056 | G41: =C41-(G$3+G$4*B41) -> 0.39113752 | H41: =E41-(H$3+H$4*B41) -> -3.5196346 | I41: =G41*(B$7/B$9)+B$3 -> 38.464638 | J41: =H41*(C$7)+C$3 -> 13.947816 | K41: =I41*D$3 -> 534.65846 | L41: =J41*D$3 -> 193.87464
B42: =Data!I39 -> 42.133333 | C42: =Data!D39/Data!G39 -> 23.917867 | E42: =Data!H39/Data!G39 -> 7.6634924 | G42: =C42-(G$3+G$4*B42) -> 0.3988597 | H42: =E42-(H$3+H$4*B42) -> -3.5270853 | I42: =G42*(B$7/B$9)+B$3 -> 38.470119 | J42: =H42*(C$7)+C$3 -> 13.934172 | K42: =I42*D$3 -> 534.73465 | L42: =J42*D$3 -> 193.68499
...

Sheet 30N2
A1: 531.2 | B1: =actual N2 at 20/0
A2: =AVERAGE(Data!D10:D12,Data!D16:D18,Data!D76:D78,Data!D136:D138,Data!D196:D198,Data!D202:D204) -> 2.4164917e-10 | B2: =average measured N2 at 20/0
C4: x | D4: y | F4: N30 based
B5: N2*O2 | C5: SQRT | D5: N30 | E5: Excess | F5: on N2 | H5: SUMMARY OUTPUT
A7: =Data!A10 -> Calibrate_20C | B7: =Data!D10*Data!H10 -> 3.8327904e-20 | C7: =SQRT(B7) -> 1.9577514e-10 | D7: =Data!F10 -> 0 | E7: =D7-(C7*I$22+I$21) -> -1.4461059e-13 | F7: =A$1*E7/A$2 -> -0.31788707 | H7: Regression Statistics
B8: =Data!D11*Data!H11 -> 3.8284297e-20 | C8: =SQRT(B8) -> 1.9566373e-10 | D8: =Data!F11 -> 0 | E8: =D8-(C8*I$22+I$21) -> -1.4456178e-13 | F8: =A$1*E8/A$2 -> -0.31777976 | H8: Multiple R | I8: 0.92093908
B9: =Data!D12*Data!H12 -> 3.8275349e-20 | C9: =SQRT(B9) -> 1.9564087e-10 | D9: =Data!F12 -> 0 | E9: =D9-(C9*I$22+I$21) -> -1.4455176e-13 | F9: =A$1*E9/A$2 -> -0.31775774 | H9: R Square | I9: 0.84812879
A10: =Data!A13 -> Calibrate_30C | B10: =Data!D13*Data!H13 -> 2.8859366e-20 | C10: =SQRT(B10) -> 1.6988044e-10 | D10: =Data!F13 -> 0 | E10: =D10-(C10*I$22+I$21) -> -1.3326433e-13 | F10: =A$1*E10/A$2 -> -0.2929454 | H10: Adjusted R Square | I10: 0.84366199
B11: =Data!D14*Data!H14 -> 2.8912151e-20 | C11: =SQRT(B11) -> 1.7003573e-10 | D11: =Data!F14 -> 0 | E11: =D11-(C11*I$22+I$21) -> -1.3333237e-13 | F11: =A$1*E11/A$2 -> -0.29309497 | H11: Standard Error | I11: 6.5089012e-15
B12: =Data!D15*Data!H15 -> 2.8866721e-20 | C12: =SQRT(B12) -> 1.6990209e-10 | D12: =Data!F15 -> 0 | E12: =D12-(C12*I$22+I$21) -> -1.3327381e-13 | F12: =A$1*E12/A$2 -> -0.29296625 | H12: Observations | I12: 36
A13: =Data!A16 -> grassesIN_T0_1 | B13: =Data!D16*Data!H16 -> 2.4492426e-20 | C13: =SQRT(B13) -> 1.5650056e-10 | D13: =Data!F16 -> 0 | E13: =D13-(C13*I$22+I$21) -> -1.2740168e-13 | F13: =A$1*E13/A$2 -> -0.28005795
B14: =Data!D17*Data!H17 -> 2.448151e-20 | C14: =SQRT(B14) -> 1.5646568e-10 | D14: =Data!F17 -> 0 | E14: =D14-(C14*I$22+I$21) -> -1.2738639e-13 | F14: =A$1*E14/A$2 -> -0.28002435 | H14: ANOVA
B15: =Data!D18*Data!H18 -> 2.4502944e-20 | C15: =SQRT(B15) -> 1.5653416e-10 | D15: =Data!F18 -> 0 | E15: =D15-(C15*I$22+I$21) -> -1.274164e-13 | F15: =A$1*E15/A$2 -> -0.28009031 | I15: df | J15: SS | K15: MS | L15: F | M15: Significance F
A16: =Data!A19 -> 1_T0_1 | B16: =Data!D19*Data!H19 -> 1.7598902e-20 | C16: =SQRT(B16) -> 1.3266085e-10 | D16: =Data!F19 -> 0 | E16: =D16-(C16*I$22+I$21) -> -1.1695585e-13 | F16: =A$1*E16/A$2 -> -0.25709563 | H16: Regression | I16: 1 | J16: 8.044159e-27 | K16: 8.044159e-27 | L16: 189.87391 | M16: 1.7853515e-15
B17: =Data!D20*Data!H20 -> 1.7549691e-20 | C17: =SQRT(B17) -> 1.3247525e-10 | D17: =Data!F20 -> 0 | E17: =D17-(C17*I$22+I$21) -> -1.1687452e-13 | F17: =A$1*E17/A$2 -> -0.25691686 | H17: Residual | I17: 34 | J17: 1.440437e-27 | K17: 4.2365795e-29
B18: =Data!D21*Data!H21 -> 1.7527647e-20 | C18: =SQRT(B18) -> 1.3239202e-10 | D18: =Data!F21 -> 0 | E18: =D18-(C18*I$22+I$21) -> -1.1683805e-13 | F18: =A$1*E18/A$2 -> -0.2568367 | H18: Total | I18: 35 | J18: 9.484596e-27
A19: =Data!A76 -> typhaIN_T0_1 | B19: =Data!D76*Data!H76 -> 2.0458949e-20 | C19: =SQRT(B19) -> 1.4303478e-10 | D19: =Data!F76 -> 0 | E19: =D19-(C19*I$22+I$21) -> -1.2150138e-13 | F19: =A$1*E19/A$2 -> -0.26708776
B20: =Data!D77*Data!H77 -> 2.0444555e-20 | C20: =SQRT(B20) -> 1.4298446e-10 | D20: =Data!F77 -> 0 | E20: =D20-(C20*I$22+I$21) -> -1.2147933e-13 | F20: =A$1*E20/A$2 -> -0.26703929 | I20: Coefficients | J20: Standard Error | K20: t Stat | L20: P-value | M20: Lower 95% | N20: Upper 95% | O20: Lower 95.0% | P20: Upper 95.0%
B21: =Data!D78*Data!H78 -> 2.0462075e-20 | C21: =SQRT(B21) -> 1.4304571e-10 | D21: =Data!F78 -> 0 | E21: =D21-(C21*I$22+I$21) -> -1.2150617e-13 | F21: =A$1*E21/A$2 -> -0.26709829 | H21: Intercept | I21: 5.8827932e-14 | J21: 1.175924e-14 | K21: 5.0026985 | L21: 1.7040094e-05 | M21: 3.4930281e-14 | N21: 8.2725583e-14 | O21: 3.4930281e-14 | P21: 8.2725583e-14
A22: =Data!A79 -> 10_T0_1 | B22: =Data!D79*Data!H79 -> 1.7316832e-20 | C22: =SQRT(B22) -> 1.3159344e-10 | D22: =Data!F79 -> 0 | E22: =D22-(C22*I$22+I$21) -> -1.1648814e-13 | F22: =A$1*E22/A$2 -> -0.2560675 | H22: X Variable 1 | I22: 0.00043816931 | J22: 3.1798696e-05 | K22: 13.779474 | L22: 1.7853515e-15 | M22: 0.00037354659 | N22: 0.00050279204 | O22: 0.00037354659 | P22: 0.00050279204
B23: =Data!D80*Data!H80 -> 1.7312234e-20 | C23: =SQRT(B23) -> 1.3157596e-10 | D23: =Data!F80 -> 0 | E23: =D23-(C23*I$22+I$21) -> -1.1648048e-13 | F23: =A$1*E23/A$2 -> -0.25605067
B24: =Data!D81*Data!H81 -> 1.7276771e-20 | C24: =SQRT(B24) -> 1.3144113e-10 | D24: =Data!F81 -> 0 | E24: =D24-(C24*I$22+I$21) -> -1.164214e-13 | F24: =A$1*E24/A$2 -> -0.2559208
A25: =Data!A136 -> hardwoodsIN_T1_1 | B25: =Data!D136*Data!H136 -> 2.3860725e-20 | C25: =SQRT(B25) -> 1.5446917e-10 | D25: =Data!F136 -> 0 | E25: =D25-(C25*I$22+I$21) -> -1.2651158e-13 | F25: =A$1*E25/A$2 -> -0.27810132
B26: =Data!D137*Data!H137 -> 2.3850371e-20 | C26: =SQRT(B26) -> 1.5443565e-10 | D26: =Data!F137 -> 0 | E26: =D26-(C26*I$22+I$21) -> -1.264969e-13 | F26: =A$1*E26/A$2 -> -0.27806904
B27: =Data!D138*Data!H138 -> 2.3853207e-20 | C27: =SQRT(B27) -> 1.5444484e-10 | D27: =Data!F138 -> 0 | E27: =D27-(C27*I$22+I$21) -> -1.2650092e-13 | F27: =A$1*E27/A$2 -> -0.27807788
A28: =Data!A139 -> 7_T1_1 | B28: =Data!D139*Data!H139 -> 1.9112783e-20 | C28: =SQRT(B28) -> 1.3824899e-10 | D28: =Data!F139 -> 0 | E28: =D28-(C28*I$22+I$21) -> -1.194044e-13 | F28: =A$1*E28/A$2 -> -0.2624781
B29: =Data!D140*Data!H140 -> 1.9096266e-20 | C29: =SQRT(B29) -> 1.3818924e-10 | D29: =Data!F140 -> 0 | E29: =D29-(C29*I$22+I$21) -> -1.1937822e-13 | F29: =A$1*E29/A$2 -> -0.26242055
B30: =Data!D141*Data!H141 -> 1.9096998e-20 | C30: =SQRT(B30) -> 1.3819189e-10 | D30: =Data!F141 -> 0 | E30: =D30-(C30*I$22+I$21) -> -1.1937938e-13 | F30: =A$1*E30/A$2 -> -0.26242311
A31: =Data!A196 -> openwaterIN_T2_1 | B31: =Data!D196*Data!H196 -> 1.7719102e-20 | C31: =SQRT(B31) -> 1.3311312e-10 | D31: =Data!F196 -> 0 | E31: =D31-(C31*I$22+I$21) -> -1.1715402e-13 | F31: =A$1*E31/A$2 -> -0.25753125
B32: =Data!D197*Data!H197 -> 1.7713078e-20 | C32: =SQRT(B32) -> 1.3309049e-10 | D32: =Data!F197 -> 0 | E32: =D32-(C32*I$22+I$21) -> -1.171441e-13 | F32: =A$1*E32/A$2 -> -0.25750946
B33: =Data!D198*Data!H198 -> 1.7706992e-20 | C33: =SQRT(B33) -> 1.3306762e-10 | D33: =Data!F198 -> 0 | E33: =D33-(C33*I$22+I$21) -> -1.1713408e-13 | F33: =A$1*E33/A$2 -> -0.25748743
A34: =Data!A199 -> 4_T2_1 | B34: =Data!D199*Data!H199 -> 1.0325922e-20 | C34: =SQRT(B34) -> 1.0161654e-10 | D34: =Data!F199 -> 0 | E34: =D34-(C34*I$22+I$21) -> -1.0335318e-13 | F34: =A$1*E34/A$2 -> -0.22719388
B35: =Data!D200*Data!H200 -> 1.0284714e-20 | C35: =SQRT(B35) -> 1.0141358e-10 | D35: =Data!F200 -> 0 | E35: =D35-(C35*I$22+I$21) -> -1.0326425e-13 | F35: =A$1*E35/A$2 -> -0.22699838
B36: =Data!D201*Data!H201 -> 1.0250937e-20 | C36: =SQRT(B36) -> 1.0124691e-10 | D36: =Data!F201 -> 0 | E36: =D36-(C36*I$22+I$21) -> -1.0319122e-13 | F36: =A$1*E36/A$2 -> -0.22683785
A37: =Data!A202 -> 5_T2_1 | B37: =Data!D202*Data!H202 -> 1.0971583e-20 | C37: =SQRT(B37) -> 1.0474532e-10 | D37: =Data!F202 -> 0 | E37: =D37-(C37*I$22+I$21) -> -1.0472412e-13 | F37: =A$1*E37/A$2 -> -0.2302075
B38: =Data!D203*Data!H203 -> 1.097997e-20 | C38: =SQRT(B38) -> 1.0478535e-10 | D38: =Data!F203 -> 0 | E38: =D38-(C38*I$22+I$21) -> -1.0474166e-13 | F38: =A$1*E38/A$2 -> -0.23024606
B39: =Data!D204*Data!H204 -> 1.0980417e-20 | C39: =SQRT(B39) -> 1.0478748e-10 | D39: =Data!F204 -> 0 | E39: =D39-(C39*I$22+I$21) -> -1.0474259e-13 | F39: =A$1*E39/A$2 -> -0.23024811
A40: =Data!A205 -> Calibrate_20C | B40: =Data!D205*Data!H205 -> 2.777014e-20 | C40: =SQRT(B40) -> 1.6664375e-10 | D40: =Data!F205 -> 0 | E40: =D40-(C40*I$22+I$21) -> -1.3184611e-13 | F40: =A$1*E40/A$2 -> -0.28982783
B41: =Data!D206*Data!H206 -> 2.7772878e-20 | C41: =SQRT(B41) -> 1.6665197e-10 | D41: =Data!F206 -> 0 | E41: =D41-(C41*I$22+I$21) -> -1.3184971e-13 | F41: =A$1*E41/A$2 -> -0.28983574
B42: =Data!D207*Data!H207 -> 2.778231e-20 | C42: =SQRT(B42) -> 1.6668026e-10 | D42: =Data!F207 -> 0 | E42: =D42-(C42*I$22+I$21) -> -1.3186211e-13 | F42: =A$1*E42/A$2 -> -0.289863
...

Sheet 29N2
A1: ='30N2'!A1 -> 531.2 | B1: =actual N2 at 20/0
A2: ='30N2'!A2 -> 2.4164917e-10 | B2: =average measured N2 at 20/0
B4: x | C4: y | E4: N29 based
B5: N28 | C5: N29 | D5: Excess | E5: on N2 | G5: SUMMARY OUTPUT
A7: ='30N2'!A7 -> Calibrate_20C | B7: =Data!D10 -> 2.818135e-10 | C7: =Data!E10 -> 0 | D7: =C7-(B7*H$22+H$21) -> -2.0490065e-12 | E7: =A$1*D7/A$2 -> -4.5041838 | G7: Regression Statistics
B8: =Data!D11 -> 2.81585e-10 | C8: =Data!E11 -> 0 | D8: =C8-(B8*H$22+H$21) -> -2.0473097e-12 | E8: =A$1*D8/A$2 -> -4.5004539 | G8: Multiple R | H8: 0.99969729
B9: =Data!D12 -> 2.815194e-10 | C9: =Data!E12 -> 0 | D9: =C9-(B9*H$22+H$21) -> -2.0468226e-12 | E9: =A$1*D9/A$2 -> -4.499383 | G9: R Square | H9: 0.99939467
A10: ='30N2'!A10 -> Calibrate_30C | B10: =Data!D13 -> 2.498668e-10 | C10: =Data!E13 -> 0 | D10: =C10-(B10*H$22+H$21) -> -1.8117777e-12 | E10: =A$1*D10/A$2 -> -3.9827008 | G10: Adjusted R Square | H10: 0.99937686
B11: =Data!D14 -> 2.501551e-10 | C11: =Data!E14 -> 0 | D11: =C11-(B11*H$22+H$21) -> -1.8139186e-12 | E11: =A$1*D11/A$2 -> -3.9874069 | G11: Standard Error | H11: 8.6787409e-15
B12: =Data!D15 -> 2.499926e-10 | C12: =Data!E15 -> 0 | D12: =C12-(B12*H$22+H$21) -> -1.8127119e-12 | E12: =A$1*D12/A$2 -> -3.9847543 | G12: Observations | H12: 36
A13: ='30N2'!A13 -> grassesIN_T0_1 | B13: =Data!D16 -> 2.531977e-10 | C13: =Data!E16 -> 0 | D13: =C13-(B13*H$22+H$21) -> -1.8365122e-12 | E13: =A$1*D13/A$2 -> -4.0370728
B14: =Data!D17 -> 2.532855e-10 | C14: =Data!E17 -> 0 | D14: =C14-(B14*H$22+H$21) -> -1.8371642e-12 | E14: =A$1*D14/A$2 -> -4.0385061 | G14: ANOVA
B15: =Data!D18 -> 2.534145e-10 | C15: =Data!E18 -> 0 | D15: =C15-(B15*H$22+H$21) -> -1.8381221e-12 | E15: =A$1*D15/A$2 -> -4.0406118 | H15: df | I15: SS | J15: MS | K15: F | L15: Significance F
A16: ='30N2'!A16 -> 1_T0_1 | B16: =Data!D19 -> 2.468768e-10 | C16: =Data!E19 -> 0 | D16: =C16-(B16*H$22+H$21) -> -1.7895747e-12 | E16: =A$1*D16/A$2 -> -3.9338934 | G16: Regression | H16: 1 | I16: 4.2279906e-24 | J16: 4.2279906e-24 | K16: 56133.298 | L16: 2.6733352e-56
B17: =Data!D20 -> 2.467791e-10 | C17: =Data!E20 -> 0 | D17: =C17-(B17*H$22+H$21) -> -1.7888492e-12 | E17: =A$1*D17/A$2 -> -3.9322986 | G17: Residual | H17: 34 | I17: 2.5608985e-27 | J17: 7.5320544e-29
B18: =Data!D21 -> 2.467689e-10 | C18: =Data!E21 -> 0 | D18: =C18-(B18*H$22+H$21) -> -1.7887734e-12 | E18: =A$1*D18/A$2 -> -3.9321321 | G18: Total | H18: 35 | I18: 4.2305515e-24
A19: ='30N2'!A19 -> typhaIN_T0_1 | B19: =Data!D76 -> 2.378664e-10 | C19: =Data!E76 -> 0 | D19: =C19-(B19*H$22+H$21) -> -1.7226655e-12 | E19: =A$1*D19/A$2 -> -3.7868119
B20: =Data!D77 -> 2.378535e-10 | C20: =Data!E77 -> 0 | D20: =C20-(B20*H$22+H$21) -> -1.7225697e-12 | E20: =A$1*D20/A$2 -> -3.7866013 | H20: Coefficients | I20: Standard Error | J20: t Stat | K20: P-value | L20: Lower 95% | M20: Upper 95% | N20: Lower 95.0% | O20: Upper 95.0%
B21: =Data!D78 -> 2.380547e-10 | C21: =Data!E78 -> 0 | D21: =C21-(B21*H$22+H$21) -> -1.7240638e-12 | E21: =A$1*D21/A$2 -> -3.7898856 | G21: Intercept | H21: -4.3675242e-14 | I21: 1.6222072e-14 | J21: -2.6923344 | K21: 0.01093146 | L21: -7.6642458e-14 | M21: -1.0708026e-14 | N21: -7.6642458e-14 | O21: -1.0708026e-14
A22: ='30N2'!A22 -> 10_T0_1 | B22: =Data!D79 -> 2.412477e-10 | C22: =Data!E79 -> 0 | D22: =C22-(B22*H$22+H$21) -> -1.7477743e-12 | E22: =A$1*D22/A$2 -> -3.8420066 | G22: X Variable 1 | H22: 0.0074257683 | I22: 3.1342318e-05 | J22: 236.92467 | K22: 2.6733352e-56 | L22: 0.0073620731 | M22: 0.0074894636 | N22: 0.0073620731 | O22: 0.0074894636
B23: =Data!D80 -> 2.412482e-10 | C23: =Data!E80 -> 0 | D23: =C23-(B23*H$22+H$21) -> -1.747778e-12 | E23: =A$1*D23/A$2 -> -3.8420148
B24: =Data!D81 -> 2.411756e-10 | C24: =Data!E81 -> 0 | D24: =C24-(B24*H$22+H$21) -> -1.7472389e-12 | E24: =A$1*D24/A$2 -> -3.8408297
A25: ='30N2'!A25 -> hardwoodsIN_T1_1 | B25: =Data!D136 -> 2.327946e-10 | C25: =Data!E136 -> 0 | D25: =C25-(B25*H$22+H$21) -> -1.6850035e-12 | E25: =A$1*D25/A$2 -> -3.7040222
B26: =Data!D137 -> 2.327683e-10 | C26: =Data!E137 -> 0 | D26: =C26-(B26*H$22+H$21) -> -1.6848082e-12 | E26: =A$1*D26/A$2 -> -3.7035929
B27: =Data!D138 -> 2.327317e-10 | C27: =Data!E138 -> 0 | D27: =C27-(B27*H$22+H$21) -> -1.6845364e-12 | E27: =A$1*D27/A$2 -> -3.7029954
A28: ='30N2'!A28 -> 7_T1_1 | B28: =Data!D139 -> 2.293899e-10 | C28: =Data!E139 -> 0 | D28: =C28-(B28*H$22+H$21) -> -1.659721e-12 | E28: =A$1*D28/A$2 -> -3.6484454
B29: =Data!D140 -> 2.294201e-10 | C29: =Data!E140 -> 0 | D29: =C29-(B29*H$22+H$21) -> -1.6599453e-12 | E29: =A$1*D29/A$2 -> -3.6489384
B30: =Data!D141 -> 2.294357e-10 | C30: =Data!E141 -> 0 | D30: =C30-(B30*H$22+H$21) -> -1.6600611e-12 | E30: =A$1*D30/A$2 -> -3.6491931
A31: ='30N2'!A31 -> openwaterIN_T2_1 | B31: =Data!D196 -> 2.220956e-10 | C31: =Data!E196 -> 0 | D31: =C31-(B31*H$22+H$21) -> -1.6055552e-12 | E31: =A$1*D31/A$2 -> -3.5293767
B32: =Data!D197 -> 2.222002e-10 | C32: =Data!E197 -> 0 | D32: =C32-(B32*H$22+H$21) -> -1.606332e-12 | E32: =A$1*D32/A$2 -> -3.5310841
B33: =Data!D198 -> 2.222089e-10 | C33: =Data!E198 -> 0 | D33: =C33-(B33*H$22+H$21) -> -1.6063966e-12 | E33: =A$1*D33/A$2 -> -3.5312261
A34: ='30N2'!A34 -> 4_T2_1 | B34: =Data!D199 -> 2.155292e-10 | C34: =Data!E199 -> 0 | D34: =C34-(B34*H$22+H$21) -> -1.5567947e-12 | E34: =A$1*D34/A$2 -> -3.4221898
B35: =Data!D200 -> 2.15308e-10 | C35: =Data!E200 -> 0 | D35: =C35-(B35*H$22+H$21) -> -1.5551521e-12 | E35: =A$1*D35/A$2 -> -3.4185791
B36: =Data!D201 -> 2.151609e-10 | C36: =Data!E201 -> 0 | D36: =C36-(B36*H$22+H$21) -> -1.5540598e-12 | E36: =A$1*D36/A$2 -> -3.4161779
A37: ='30N2'!A37 -> 5_T2_1 | B37: =Data!D202 -> 2.220316e-10 | C37: =Data!E202 -> 0 | D37: =C37-(B37*H$22+H$21) -> -1.60508e-12 | E37: =A$1*D37/A$2 -> -3.528332
B38: =Data!D203 -> 2.221286e-10 | C38: =Data!E203 -> 0 | D38: =C38-(B38*H$22+H$21) -> -1.6058003e-12 | E38: =A$1*D38/A$2 -> -3.5299154
B39: =Data!D204 -> 2.221353e-10 | C39: =Data!E204 -> 0 | D39: =C39-(B39*H$22+H$21) -> -1.60585e-12 | E39: =A$1*D39/A$2 -> -3.5300247
A40: ='30N2'!A40 -> Calibrate_20C | B40: =Data!D205 -> 2.43419e-10 | C40: =Data!E205 -> 0 | D40: =C40-(B40*H$22+H$21) -> -1.7638979e-12 | E40: =A$1*D40/A$2 -> -3.8774499
B41: =Data!D206 -> 2.433758e-10 | C41: =Data!E206 -> 0 | D41: =C41-(B41*H$22+H$21) -> -1.7635771e-12 | E41: =A$1*D41/A$2 -> -3.8767447
B42: =Data!D207 -> 2.432977e-10 | C42: =Data!E207 -> 0 | D42: =C42-(B42*H$22+H$21) -> -1.7629971e-12 | E42: =A$1*D42/A$2 -> -3.8754699
...
