Workbook

Sheet Data
A1: 052121-Lake Superior-Cores+Respirations-May2021
A6: Sample | B6: Time | C6: N28 | D6: N29 | E6: N30 | F6: Ar | G6: O2 | H6: Time
A8: 20/0 | B8: 0.42827546 | C8: 6.241656e-08 | D8: 4.392797e-10 | E8: 1.134001e-11 | F8: 1.235414e-09 | G8: 3.008099e-08 | H8: =M8-M$8 -> 0 | I8: 0.42827546 | J8: 10 | K8: 16 | L8: 43 | M8: =J8*60+K8+L8/60 -> 616.71667
B9: 0.42836806 | C9: 6.249566e-08 | D9: 4.396584e-10 | E9: 1.150738e-11 | F9: 1.236902e-09 | G9: 3.009104e-08 | H9: =M9-M$8 -> 0.13333333 | I9: 0.42836806 | J9: 10 | K9: 16 | L9: 51 | M9: =J9*60+K9+L9/60 -> 616.85
B10: 0.4284838 | C10: 6.239389e-08 | D10: 4.406928e-10 | E10: 1.144119e-11 | F10: 1.236542e-09 | G10: 3.006695e-08 | H10: =M10-M$8 -> 0.3 | I10: 0.4284838 | J10: 10 | K10: 17 | L10: 1 | M10: =J10*60+K10+L10/60 -> 617.01667
A11: 30/0 | B11: 0.43180556 | C11: 5.282325e-08 | D11: 3.717482e-10 | E11: 1.067302e-11 | F11: 1.029773e-09 | G11: 2.508122e-08 | H11: =M11-M$8 -> 5.0833333 | I11: 0.43180556 | J11: 10 | K11: 21 | L11: 48 | M11: =J11*60+K11+L11/60 -> 621.8
B12: 0.43189815 | C12: 5.277345e-08 | D12: 3.715286e-10 | E12: 1.037504e-11 | F12: 1.031077e-09 | G12: 2.510491e-08 | H12: =M12-M$8 -> 5.2166667 | I12: 0.43189815 | J12: 10 | K12: 21 | L12: 56 | M12: =J12*60+K12+L12/60 -> 621.93333
B13: 0.43199074 | C13: 5.278764e-08 | D13: 3.717964e-10 | E13: 1.031778e-11 | F13: 1.031453e-09 | G13: 2.505815e-08 | H13: =M13-M$8 -> 5.35 | I13: 0.43199074 | J13: 10 | K13: 22 | L13: 4 | M13: =J13*60+K13+L13/60 -> 622.06667
A14: 20/0 | B14: 0.435 | C14: 6.211614e-08 | D14: 4.365749e-10 | E14: 1.131205e-11 | F14: 1.227347e-09 | G14: 2.991718e-08 | H14: =M14-M$8 -> 9.6833333 | I14: 0.435 | J14: 10 | K14: 26 | L14: 24 | M14: =J14*60+K14+L14/60 -> 626.4
B15: 0.43509259 | C15: 6.218553e-08 | D15: 4.370271e-10 | E15: 1.140981e-11 | F15: 1.22477e-09 | G15: 2.991536e-08 | H15: =M15-M$8 -> 9.8166667 | I15: 0.43509259 | J15: 10 | K15: 26 | L15: 32 | M15: =J15*60+K15+L15/60 -> 626.53333
B16: 0.43524306 | C16: 6.21415e-08 | D16: 4.381185e-10 | E16: 1.137642e-11 | F16: 1.225743e-09 | G16: 2.993014e-08 | H16: =M16-M$8 -> 10.033333 | I16: 0.43524306 | J16: 10 | K16: 26 | L16: 45 | M16: =J16*60+K16+L16/60 -> 626.75
A17: 30/0 | B17: 0.43967593 | C17: 5.255534e-08 | D17: 3.704886e-10 | E17: 1.021252e-11 | F17: 1.023957e-09 | G17: 2.495164e-08 | H17: =M17-M$8 -> 16.416667 | I17: 0.43967593 | J17: 10 | K17: 33 | L17: 8 | M17: =J17*60+K17+L17/60 -> 633.13333
B18: 0.43976852 | C18: 5.247932e-08 | D18: 3.698069e-10 | E18: 1.027509e-11 | F18: 1.024448e-09 | G18: 2.498054e-08 | H18: =M18-M$8 -> 16.55 | I18: 0.43976852 | J18: 10 | K18: 33 | L18: 16 | M18: =J18*60+K18+L18/60 -> 633.26667
B19: 0.43986111 | C19: 5.245805e-08 | D19: 3.689866e-10 | E19: 1.044589e-11 | F19: 1.024887e-09 | G19: 2.493537e-08 | H19: =M19-M$8 -> 16.683333 | I19: 0.43986111 | J19: 10 | K19: 33 | L19: 24 | M19: =J19*60+K19+L19/60 -> 633.4
A20: 051221-LS-WM-5m-To | B20: 0.44369213 | C20: 8.369335e-08 | D20: 5.885065e-10 | E20: 1.373352e-11 | F20: 1.702544e-09 | G20: 4.095919e-08 | H20: =M20-M$8 -> 22.2 | I20: 0.44369213 | J20: 10 | K20: 38 | L20: 55 | M20: =J20*60+K20+L20/60 -> 638.91667
B21: 0.44378472 | C21: 8.366315e-08 | D21: 5.894184e-10 | E21: 1.338887e-11 | F21: 1.703002e-09 | G21: 4.096912e-08 | H21: =M21-M$8 -> 22.333333 | I21: 0.44378472 | J21: 10 | K21: 39 | L21: 3 | M21: =J21*60+K21+L21/60 -> 639.05
B22: 0.44387731 | C22: 8.368348e-08 | D22: 5.874513e-10 | E22: 1.347484e-11 | F22: 1.704461e-09 | G22: 4.099073e-08 | H22: =M22-M$8 -> 22.466667 | I22: 0.44387731 | J22: 10 | K22: 39 | L22: 11 | M22: =J22*60+K22+L22/60 -> 639.18333
A23: 051221-LS-WM-5m-To | B23: 0.44821759 | C23: 8.772465e-08 | D23: 6.163563e-10 | E23: 1.407899e-11 | F23: 1.748913e-09 | G23: 4.239406e-08 | H23: =M23-M$8 -> 28.716667 | I23: 0.44821759 | J23: 10 | K23: 45 | L23: 26 | M23: =J23*60+K23+L23/60 -> 645.43333
B24: 0.44827546 | C24: 8.776044e-08 | D24: 6.175508e-10 | E24: 1.406122e-11 | F24: 1.750506e-09 | G24: 4.241434e-08 | H24: =M24-M$8 -> 28.8 | I24: 0.44827546 | J24: 10 | K24: 45 | L24: 31 | M24: =J24*60+K24+L24/60 -> 645.51667
B25: 0.44842593 | C25: 8.769108e-08 | D25: 6.160784e-10 | E25: 1.397767e-11 | F25: 1.746226e-09 | G25: 4.233169e-08 | H25: =M25-M$8 -> 29.016667 | I25: 0.44842593 | J25: 10 | K25: 45 | L25: 44 | M25: =J25*60+K25+L25/60 -> 645.73333
A26: 051221-LS-WM-35m-To | B26: 0.45291667 | C26: 9.918642e-08 | D26: 6.715734e-10 | E26: 1.491213e-11 | F26: 1.796851e-09 | G26: 4.372049e-08 | H26: =M26-M$8 -> 35.483333 | I26: 0.45291667 | J26: 10 | K26: 52 | L26: 12 | M26: =J26*60+K26+L26/60 -> 652.2
B27: 0.45300926 | C27: 9.90812e-08 | D27: 6.724103e-10 | E27: 1.489012e-11 | F27: 1.797083e-09 | G27: 4.364009e-08 | H27: =M27-M$8 -> 35.616667 | I27: 0.45300926 | J27: 10 | K27: 52 | L27: 20 | M27: =J27*60+K27+L27/60 -> 652.33333
B28: 0.45306713 | C28: 9.915436e-08 | D28: 6.715082e-10 | E28: 1.477661e-11 | F28: 1.797481e-09 | G28: 4.364976e-08 | H28: =M28-M$8 -> 35.7 | I28: 0.45306713 | J28: 10 | K28: 52 | L28: 25 | M28: =J28*60+K28+L28/60 -> 652.41667
A29: 051221-LS-WM-35m-To | B29: 0.456875 | C29: 8.274705e-08 | D29: 5.821241e-10 | E29: 1.379609e-11 | F29: 1.683016e-09 | G29: 4.055909e-08 | H29: =M29-M$8 -> 41.183333 | I29: 0.456875 | J29: 10 | K29: 57 | L29: 54 | M29: =J29*60+K29+L29/60 -> 657.9
B30: 0.45696759 | C30: 8.263995e-08 | D30: 5.804103e-10 | E30: 1.360536e-11 | F30: 1.681118e-09 | G30: 4.054422e-08 | H30: =M30-M$8 -> 41.316667 | I30: 0.45696759 | J30: 10 | K30: 58 | L30: 2 | M30: =J30*60+K30+L30/60 -> 658.03333
B31: 0.45711806 | C31: 8.257612e-08 | D31: 5.815192e-10 | E31: 1.400818e-11 | F31: 1.681388e-09 | G31: 4.058659e-08 | H31: =M31-M$8 -> 41.533333 | I31: 0.45711806 | J31: 10 | K31: 58 | L31: 15 | M31: =J31*60+K31+L31/60 -> 658.25
A32: 051221-LS-WM-163m-To | B32: 0.45880787 | C32: 8.32091e-08 | D32: 5.844462e-10 | E32: 1.366695e-11 | F32: 1.688964e-09 | G32: 4.07717e-08 | H32: =M32-M$8 -> 43.966667 | I32: 0.45880787 | J32: 11 | K32: 0 | L32: 41 | M32: =J32*60+K32+L32/60 -> 660.68333
B33: 0.45886574 | C33: 8.319522e-08 | D33: 5.830397e-10 | E33: 1.378303e-11 | F33: 1.688733e-09 | G33: 4.077571e-08 | H33: =M33-M$8 -> 44.05 | I33: 0.45886574 | J33: 11 | K33: 0 | L33: 46 | M33: =J33*60+K33+L33/60 -> 660.76667
B34: 0.45895833 | C34: 8.315403e-08 | D34: 5.831506e-10 | E34: 1.380467e-11 | F34: 1.686605e-09 | G34: 4.074053e-08 | H34: =M34-M$8 -> 44.183333 | I34: 0.45895833 | J34: 11 | K34: 0 | L34: 54 | M34: =J34*60+K34+L34/60 -> 660.9
A35: 051221-LS-WM-163m-To | B35: 0.46100694 | C35: 8.286748e-08 | D35: 5.81196e-10 | E35: 1.391308e-11 | F35: 1.684062e-09 | G35: 4.045518e-08 | H35: =M35-M$8 -> 47.133333 | I35: 0.46100694 | J35: 11 | K35: 3 | L35: 51 | M35: =J35*60+K35+L35/60 -> 663.85
B36: 0.46109954 | C36: 8.282901e-08 | D36: 5.823343e-10 | E36: 1.362905e-11 | F36: 1.682973e-09 | G36: 4.042251e-08 | H36: =M36-M$8 -> 47.266667 | I36: 0.46109954 | J36: 11 | K36: 3 | L36: 59 | M36: =J36*60+K36+L36/60 -> 663.98333
B37: 0.46115741 | C37: 8.278225e-08 | D37: 5.817004e-10 | E37: 1.375205e-11 | F37: 1.683692e-09 | G37: 4.042223e-08 | H37: =M37-M$8 -> 47.35 | I37: 0.46115741 | J37: 11 | K37: 4 | L37: 4 | M37: =J37*60+K37+L37/60 -> 664.06667
A38: 051321-LS-WM-5m-Tf | B38: 0.46443287 | C38: 8.191422e-08 | D38: 5.757809e-10 | E38: 1.37583e-11 | F38: 1.665374e-09 | G38: 4.035187e-08 | H38: =M38-M$8 -> 52.066667 | I38: 0.46443287 | J38: 11 | K38: 8 | L38: 47 | M38: =J38*60+K38+L38/60 -> 668.78333
B39: 0.46449074 | C39: 8.181505e-08 | D39: 5.764165e-10 | E39: 1.377982e-11 | F39: 1.667224e-09 | G39: 4.035892e-08 | H39: =M39-M$8 -> 52.15 | I39: 0.46449074 | J39: 11 | K39: 8 | L39: 52 | M39: =J39*60+K39+L39/60 -> 668.86667
B40: 0.46452546 | C40: 8.189531e-08 | D40: 5.760992e-10 | E40: 1.364116e-11 | F40: 1.665748e-09 | G40: 4.034915e-08 | H40: =M40-M$8 -> 52.2 | I40: 0.46452546 | J40: 11 | K40: 8 | L40: 55 | M40: =J40*60+K40+L40/60 -> 668.91667
A41: 051321-LS-WM-5m-Tf | B41: 0.46744213 | C41: 8.141865e-08 | D41: 5.702153e-10 | E41: 1.368905e-11 | F41: 1.656426e-09 | G41: 4.001969e-08 | H41: =M41-M$8 -> 56.4 | I41: 0.46744213 | J41: 11 | K41: 13 | L41: 7 | M41: =J41*60+K41+L41/60 -> 673.11667
B42: 0.4675 | C42: 8.123205e-08 | D42: 5.712569e-10 | E42: 1.355985e-11 | F42: 1.655184e-09 | G42: 4.000205e-08 | H42: =M42-M$8 -> 56.483333 | I42: 0.4675 | J42: 11 | K42: 13 | L42: 12 | M42: =J42*60+K42+L42/60 -> 673.2
B43: 0.46755787 | C43: 8.131914e-08 | D43: 5.712657e-10 | E43: 1.360399e-11 | F43: 1.651587e-09 | G43: 4.006628e-08 | H43: =M43-M$8 -> 56.566667 | I43: 0.46755787 | J43: 11 | K43: 13 | L43: 17 | M43: =J43*60+K43+L43/60 -> 673.28333
A44: 051321-LS-WM-35m-Tf | B44: 0.47011574 | C44: 8.365682e-08 | D44: 5.860307e-10 | E44: 1.393801e-11 | F44: 1.677715e-09 | G44: 4.056869e-08 | H44: =M44-M$8 -> 60.25 | I44: 0.47011574 | J44: 11 | K44: 16 | L44: 58 | M44: =J44*60+K44+L44/60 -> 676.96667
B45: 0.47017361 | C45: 8.366891e-08 | D45: 5.86553e-10 | E45: 1.369811e-11 | F45: 1.678263e-09 | G45: 4.057621e-08 | H45: =M45-M$8 -> 60.333333 | I45: 0.47017361 | J45: 11 | K45: 17 | L45: 3 | M45: =J45*60+K45+L45/60 -> 677.05
...

Sheet Regs
A1: 20/0 N2 | D1: SUMMARY OUTPUT
A3: N2/Ar | B3: time(min) | D3: Regression Statistics
A4: =Data!C8/Data!F8 -> 50.522788 | B4: =Data!H8 -> 0 | D4: Multiple R | E4: 0.37205777
A5: =Data!C9/Data!F9 -> 50.525959 | B5: =Data!H9 -> 0.13333333 | D5: R Square | E5: 0.13842698
A6: =Data!C10/Data!F10 -> 50.458367 | B6: =Data!H10 -> 0.3 | D6: Adjusted R Square | E6: 0.099264575
A7: =Data!C14/Data!F14 -> 50.610088 | B7: =Data!H14 -> 9.6833333 | D7: Standard Error | E7: 0.11557942
A8: =Data!C15/Data!F15 -> 50.773231 | B8: =Data!H15 -> 9.8166667 | D8: Observations | E8: 24
A9: =Data!C16/Data!F16 -> 50.697006 | B9: =Data!H16 -> 10.033333
A10: =Data!C56/Data!F56 -> 50.766782 | B10: =Data!H56 -> 77.916667 | D10: ANOVA
A11: =Data!C57/Data!F57 -> 50.835575 | B11: =Data!H57 -> 78 | E11: df | F11: SS | G11: MS | H11: F | I11: Significance F
A12: =Data!C58/Data!F58 -> 50.759243 | B12: =Data!H58 -> 78.133333 | D12: Regression | E12: 1 | F12: 0.047218523 | G12: 0.047218523 | H12: 3.5346902 | I12: 0.073404918
A13: =Data!C86/Data!F86 -> 50.671341 | B13: =Data!H86 -> 131.91667 | D13: Residual | E13: 22 | F13: 0.29388927 | G13: 0.013358603
A14: =Data!C87/Data!F87 -> 50.476653 | B14: =Data!H87 -> 132.13333 | D14: Total | E14: 23 | F14: 0.34110779
A15: =Data!C88/Data!F88 -> 50.501787 | B15: =Data!H88 -> 132.43333
A16: =Data!C92/Data!F92 -> 50.599724 | B16: =Data!H92 -> 146.03333 | E16: Coefficients | F16: Standard Error | G16: t Stat | H16: P-value | I16: Lower 95% | J16: Upper 95% | K16: Lower 95.0% | L16: Upper 95.0%
A17: =Data!C93/Data!F93 -> 50.472232 | B17: =Data!H93 -> 146.13333 | D17: Intercept | E17: 50.635992 | F17: 0.037517724 | G17: 1349.6552 | H17: 1.34118e-55 | I17: 50.558185 | J17: 50.713799 | K17: 50.558185 | L17: 50.713799
A18: =Data!C94/Data!F94 -> 50.646817 | B18: =Data!H94 -> 146.21667 | D18: X Variable 1 | E18: -0.00031869096 | F18: 0.00016950951 | G18: -1.8800772 | H18: 0.073404918 | I18: -0.00067023217 | J18: 3.2850248e-05 | K18: -0.00067023217 | L18: 3.2850248e-05
A19: =Data!C152/Data!F152 -> 50.47751 | B19: =Data!H152 -> 270.83333
A20: =Data!C153/Data!F153 -> 50.441875 | B20: =Data!H153 -> 270.96667
A21: =Data!C154/Data!F154 -> 50.423413 | B21: =Data!H154 -> 271.05
A22: =Data!C212/Data!F212 -> 50.583895 | B22: =Data!H212 -> 364.51667
A23: =Data!C213/Data!F213 -> 50.541285 | B23: =Data!H213 -> 364.65
A24: =Data!C214/Data!F214 -> 50.638356 | B24: =Data!H214 -> 364.78333
A25: =Data!C218/Data!F218 -> 50.619541 | B25: =Data!H218 -> 374.73333
A26: =Data!C219/Data!F219 -> 50.473698 | B26: =Data!H219 -> 374.86667
A27: =Data!C220/Data!F220 -> 50.430367 | B27: =Data!H220 -> 374.95
A28: =Data!C416/Data!F416 -> #DIV/0! | B28: =Data!H416 -> 0
A29: =Data!C417/Data!F417 -> #DIV/0! | B29: =Data!H417 -> 0
A30: =Data!C418/Data!F418 -> #DIV/0! | B30: =Data!H418 -> 0
A31: =Data!C542/Data!F542 -> #DIV/0! | B31: =Data!H542 -> 0
A32: =Data!C543/Data!F543 -> #DIV/0! | B32: =Data!H543 -> 0
A33: =Data!C544/Data!F544 -> #DIV/0! | B33: =Data!H544 -> 0
A34: =Data!C608/Data!F608 -> #DIV/0! | B34: =Data!H608 -> 0
A35: =Data!C609/Data!F609 -> #DIV/0! | B35: =Data!H609 -> 0
A36: =Data!C610/Data!F610 -> #DIV/0! | B36: =Data!H610 -> 0
A37: =Data!C614/Data!F614 -> #DIV/0! | B37: =Data!H614 -> 0
A38: =Data!C615/Data!F615 -> #DIV/0! | B38: =Data!H615 -> 0
A39: =Data!C616/Data!F616 -> #DIV/0! | B39: =Data!H616 -> 0
A41: 30/0 N2 | D41: SUMMARY OUTPUT
A43: N2/Ar | B43: time(min) | D43: Regression Statistics
...

Sheet 28N2-O2
C1: Actual | G1: N2(20/0) | H1: O2(20/0)
B2: N2/Ar | C2: O2/Ar | D2: Ar | F2: r2 | G2: =Regs!E5 -> 0.13842698 | H2: =Regs!E85 -> 0.002298157
A3: 20/0 | B3: 38.187 | C3: 20.393 | D3: 13.9 | F3: intercept | G3: =Regs!E17 -> 50.635992 | H3: =Regs!E97 -> 24.408931
A4: 30/0 | B4: 38.861 | C4: 20.38 | D4: 11.6 | F4: slope | G4: =Regs!E18 -> -0.00031869096 | H4: =Regs!E98 -> -1.8582266e-05
A6: D= | B6: =(Regs!E57+Regs!E58*(Data!H223/2))-(Regs!E17+Regs!E18*(Data!H223/2)) -> 0.75064937
A7: Avg CF= | B7: =AVERAGE(D13:D15,D19:D21,D61:D63,D91:D93,D97:D99,D157:D159,D217:D219,D223:D225) -> 0.75496927 | C7: =AVERAGE(F13:F15,F19:F21,F61:F63,F91:F93,F97:F99,F157:F159,F217:F219,F223:F225) -> 0.83558644
A8: Adj. D= | B8: =B6*B7 -> 0.56671721
A9: Factor= | B9: =B8/(B4-B3) -> 0.84082672
E11: Measured | J11: Actual
A12: Sample ID | B12: time (min) | C12: N2/Ar | D12: CF | E12: O2/Ar | F12: CF | G12: N2 D | H12: O2 D | I12: N2/Ar | J12: O2/Ar | K12: N2 | L12: O2 | M12: Avg N2 | N12: Avg O2 | O12: Sample ID
A13: =Data!A8 -> 20/0 | B13: =Data!H8 -> 0 | C13: =Data!C8/Data!F8 -> 50.522788 | D13: =B$3/C13 -> 0.75583714 | E13: =Data!G8/Data!F8 -> 24.348915 | F13: =C$3/E13 -> 0.8375322 | G13: =C13-(G$3+G$4*B13) -> -0.11320337 | H13: =E13-(H$3+H$4*B13) -> -0.060016348 | I13: =G13*(B$7/B$9)+B$3 -> 38.085356 | J13: =H13*(C$7)+C$3 -> 20.342851 | K13: =I13*D$3 -> 529.38645 | L13: =J13*D$3 -> 282.76563 | O13: =Data!A8 -> 20/0
B14: =Data!H9 -> 0.13333333 | C14: =Data!C9/Data!F9 -> 50.525959 | D14: =B$3/C14 -> 0.75578971 | E14: =Data!G9/Data!F9 -> 24.327748 | F14: =C$3/E14 -> 0.83826091 | G14: =C14-(G$3+G$4*B14) -> -0.10998998 | H14: =E14-(H$3+H$4*B14) -> -0.081180612 | I14: =G14*(B$7/B$9)+B$3 -> 38.088241 | J14: =H14*(C$7)+C$3 -> 20.325167 | K14: =I14*D$3 -> 529.42655 | L14: =J14*D$3 -> 282.51982
B15: =Data!H10 -> 0.3 | C15: =Data!C10/Data!F10 -> 50.458367 | D15: =B$3/C15 -> 0.75680214 | E15: =Data!G10/Data!F10 -> 24.315349 | F15: =C$3/E15 -> 0.83868836 | G15: =C15-(G$3+G$4*B15) -> -0.17752911 | H15: =E15-(H$3+H$4*B15) -> -0.093576617 | I15: =G15*(B$7/B$9)+B$3 -> 38.027599 | J15: =H15*(C$7)+C$3 -> 20.314809 | K15: =I15*D$3 -> 528.58362 | L15: =J15*D$3 -> 282.37584
A16: =Data!A11 -> 30/0 | B16: =Data!H11 -> 5.0833333 | C16: =Data!C11/Data!F11 -> 51.296014 | D16: =B$4/C16 -> 0.75758323 | E16: =Data!G11/Data!F11 -> 24.356067 | F16: =C$4/E16 -> 0.83675251 | G16: =C16-(G$3+G$4*B16) -> 0.66164211 | H16: =E16-(H$3+H$4*B16) -> -0.052769681 | I16: =G16*(B$7/B$9)+B$3 -> 38.781081 | J16: =H16*(C$7)+C$3 -> 20.348906 | K16: =I16*D$3 -> 539.05703 | L16: =J16*D$3 -> 282.8498 | O16: =Data!A11 -> 30/0
B17: =Data!H12 -> 5.2166667 | C17: =Data!C12/Data!F12 -> 51.182841 | D17: =B$4/C17 -> 0.75925836 | E17: =Data!G12/Data!F12 -> 24.34824 | F17: =C$4/E17 -> 0.83702149 | G17: =C17-(G$3+G$4*B17) -> 0.54851167 | H17: =E17-(H$3+H$4*B17) -> -0.060594272 | I17: =G17*(B$7/B$9)+B$3 -> 38.679503 | J17: =H17*(C$7)+C$3 -> 20.342368 | K17: =I17*D$3 -> 537.64509 | L17: =J17*D$3 -> 282.75892
B18: =Data!H13 -> 5.35 | C18: =Data!C13/Data!F13 -> 51.17794 | D18: =B$4/C18 -> 0.75933107 | E18: =Data!G13/Data!F13 -> 24.29403 | F18: =C$4/E18 -> 0.83888923 | G18: =C18-(G$3+G$4*B18) -> 0.54365356 | H18: =E18-(H$3+H$4*B18) -> -0.11480167 | I18: =G18*(B$7/B$9)+B$3 -> 38.675141 | J18: =H18*(C$7)+C$3 -> 20.297073 | K18: =I18*D$3 -> 537.58446 | L18: =J18*D$3 -> 282.12932
A19: =Data!A14 -> 20/0 | B19: =Data!H14 -> 9.6833333 | C19: =Data!C14/Data!F14 -> 50.610088 | D19: =B$3/C19 -> 0.75453336 | E19: =Data!G14/Data!F14 -> 24.375486 | F19: =C$3/E19 -> 0.83661921 | G19: =C19-(G$3+G$4*B19) -> -0.02281743 | H19: =E19-(H$3+H$4*B19) -> -0.033264711 | I19: =G19*(B$7/B$9)+B$3 -> 38.166512 | J19: =H19*(C$7)+C$3 -> 20.365204 | K19: =I19*D$3 -> 530.51452 | L19: =J19*D$3 -> 283.07634 | O19: =Data!A14 -> 20/0
B20: =Data!H15 -> 9.8166667 | C20: =Data!C15/Data!F15 -> 50.773231 | D20: =B$3/C20 -> 0.75210892 | E20: =Data!G15/Data!F15 -> 24.425288 | F20: =C$3/E20 -> 0.83491339 | G20: =C20-(G$3+G$4*B20) -> 0.14036769 | H20: =E20-(H$3+H$4*B20) -> 0.016539466 | I20: =G20*(B$7/B$9)+B$3 -> 38.313035 | J20: =H20*(C$7)+C$3 -> 20.40682 | K20: =I20*D$3 -> 532.55118 | L20: =J20*D$3 -> 283.6548
B21: =Data!H16 -> 10.033333 | C21: =Data!C16/Data!F16 -> 50.697006 | D21: =B$3/C21 -> 0.75323975 | E21: =Data!G16/Data!F16 -> 24.417957 | F21: =C$3/E21 -> 0.83516405 | G21: =C21-(G$3+G$4*B21) -> 0.064211664 | H21: =E21-(H$3+H$4*B21) -> 0.0092125877 | I21: =G21*(B$7/B$9)+B$3 -> 38.244655 | J21: =H21*(C$7)+C$3 -> 20.400698 | K21: =I21*D$3 -> 531.6007 | L21: =J21*D$3 -> 283.5697
A22: =Data!A17 -> 30/0 | B22: =Data!H17 -> 16.416667 | C22: =Data!C17/Data!F17 -> 51.325729 | D22: =B$4/C22 -> 0.75714462 | E22: =Data!G17/Data!F17 -> 24.367859 | F22: =C$4/E22 -> 0.83634758 | G22: =C22-(G$3+G$4*B22) -> 0.69496966 | H22: =E22-(H$3+H$4*B22) -> -0.040766707 | I22: =G22*(B$7/B$9)+B$3 -> 38.811006 | J22: =H22*(C$7)+C$3 -> 20.358936 | K22: =I22*D$3 -> 539.47298 | L22: =J22*D$3 -> 282.98921 | O22: =Data!A17 -> 30/0
B23: =Data!H18 -> 16.55 | C23: =Data!C18/Data!F18 -> 51.226924 | D23: =B$4/C23 -> 0.75860498 | E23: =Data!G18/Data!F18 -> 24.38439 | F23: =C$4/E23 -> 0.83578058 | G23: =C23-(G$3+G$4*B23) -> 0.59620681 | H23: =E23-(H$3+H$4*B23) -> -0.024233003 | I23: =G23*(B$7/B$9)+B$3 -> 38.722328 | J23: =H23*(C$7)+C$3 -> 20.372751 | K23: =I23*D$3 -> 538.24035 | L23: =J23*D$3 -> 283.18124
B24: =Data!H19 -> 16.683333 | C24: =Data!C19/Data!F19 -> 51.184228 | D24: =B$4/C24 -> 0.75923779 | E24: =Data!G19/Data!F19 -> 24.329872 | F24: =C$4/E24 -> 0.83765338 | G24: =C24-(G$3+G$4*B24) -> 0.55355326 | H24: =E24-(H$3+H$4*B24) -> -0.078748485 | I24: =G24*(B$7/B$9)+B$3 -> 38.68403 | J24: =H24*(C$7)+C$3 -> 20.327199 | K24: =I24*D$3 -> 537.70801 | L24: =J24*D$3 -> 282.54806
A25: =Data!A20 -> 051221-LS-WM-5m-To | B25: =Data!H20 -> 22.2 | C25: =Data!C20/Data!F20 -> 49.157819 | E25: =Data!G20/Data!F20 -> 24.05764 | G25: =C25-(G$3+G$4*B25) -> -1.4710976 | H25: =E25-(H$3+H$4*B25) -> -0.35087881 | I25: =G25*(B$7/B$9)+B$3 -> 36.866117 | J25: =H25*(C$7)+C$3 -> 20.09981 | K25: =I25*D$3 -> 512.43903 | L25: =J25*D$3 -> 279.38736 | M25: =AVERAGE(K25:K27) -> 512.05669 | N25: =AVERAGE(L25:L27) -> 279.35181 | O25: =Data!A20 -> 051221-LS-WM-5m-To
B26: =Data!H21 -> 22.333333 | C26: =Data!C21/Data!F21 -> 49.126865 | E26: =Data!G21/Data!F21 -> 24.057001 | G26: =C26-(G$3+G$4*B26) -> -1.5020089 | H26: =E26-(H$3+H$4*B26) -> -0.35151544 | I26: =G26*(B$7/B$9)+B$3 -> 36.838362 | J26: =H26*(C$7)+C$3 -> 20.099278 | K26: =I26*D$3 -> 512.05324 | L26: =J26*D$3 -> 279.37997
B27: =Data!H22 -> 22.466667 | C27: =Data!C22/Data!F22 -> 49.096741 | E27: =Data!G22/Data!F22 -> 24.049086 | G27: =C27-(G$3+G$4*B27) -> -1.5320909 | H27: =E27-(H$3+H$4*B27) -> -0.359427 | I27: =G27*(B$7/B$9)+B$3 -> 36.811352 | J27: =H27*(C$7)+C$3 -> 20.092668 | K27: =I27*D$3 -> 511.67779 | L27: =J27*D$3 -> 279.28808
A28: =Data!A23 -> 051221-LS-WM-5m-To | B28: =Data!H23 -> 28.716667 | C28: =Data!C23/Data!F23 -> 50.159528 | E28: =Data!G23/Data!F23 -> 24.240234 | G28: =C28-(G$3+G$4*B28) -> -0.46731228 | H28: =E28-(H$3+H$4*B28) -> -0.16816355 | I28: =G28*(B$7/B$9)+B$3 -> 37.767405 | J28: =H28*(C$7)+C$3 -> 20.252485 | K28: =I28*D$3 -> 524.96693 | L28: =J28*D$3 -> 281.50954 | M28: =AVERAGE(K28:K29) -> 524.80984 | N28: =AVERAGE(L28:L30) -> 281.47514 | O28: =Data!A23 -> 051221-LS-WM-5m-To
B29: =Data!H24 -> 28.8 | C29: =Data!C24/Data!F24 -> 50.134327 | E29: =Data!G24/Data!F24 -> 24.22976 | G29: =C29-(G$3+G$4*B29) -> -0.49248651 | H29: =E29-(H$3+H$4*B29) -> -0.17863594 | I29: =G29*(B$7/B$9)+B$3 -> 37.744802 | J29: =H29*(C$7)+C$3 -> 20.243734 | K29: =I29*D$3 -> 524.65274 | L29: =J29*D$3 -> 281.38791
B30: =Data!H25 -> 29.016667 | C30: =Data!C25/Data!F25 -> 50.217486 | E30: =Data!G25/Data!F25 -> 24.241816 | G30: =C30-(G$3+G$4*B30) -> -0.40925817 | H30: =E30-(H$3+H$4*B30) -> -0.16657542 | I30: =G30*(B$7/B$9)+B$3 -> 37.819531 | J30: =H30*(C$7)+C$3 -> 20.253812 | K30: =I30*D$3 -> 525.69149 | L30: =J30*D$3 -> 281.52798
A31: =Data!A26 -> 051221-LS-WM-35m-To | B31: =Data!H26 -> 35.483333 | C31: =Data!C26/Data!F26 -> 55.200136 | E31: =Data!G26/Data!F26 -> 24.331728 | G31: =C31-(G$3+G$4*B31) -> 4.5754528 | H31: =E31-(H$3+H$4*B31) -> -0.076543484 | I31: =G31*(B$7/B$9)+B$3 -> 42.29525 | J31: =H31*(C$7)+C$3 -> 20.329041 | K31: =I31*D$3 -> 587.90397 | L31: =J31*D$3 -> 282.57367 | M31: =AVERAGE(K31:K33) -> 587.47652 | N31: =AVERAGE(L31:L33) -> 282.20297 | O31: =Data!A26 -> 051221-LS-WM-35m-To
B32: =Data!H27 -> 35.616667 | C32: =Data!C27/Data!F27 -> 55.13446 | E32: =Data!G27/Data!F27 -> 24.283848 | G32: =C32-(G$3+G$4*B32) -> 4.5098186 | H32: =E32-(H$3+H$4*B32) -> -0.12442136 | I32: =G32*(B$7/B$9)+B$3 -> 42.236318 | J32: =H32*(C$7)+C$3 -> 20.289035 | K32: =I32*D$3 -> 587.08482 | L32: =J32*D$3 -> 282.01759
B33: =Data!H28 -> 35.7 | C33: =Data!C28/Data!F28 -> 55.162953 | E33: =Data!G28/Data!F28 -> 24.283851 | G33: =C33-(G$3+G$4*B33) -> 4.5383386 | H33: =E33-(H$3+H$4*B33) -> -0.12441701 | I33: =G33*(B$7/B$9)+B$3 -> 42.261925 | J33: =H33*(C$7)+C$3 -> 20.289039 | K33: =I33*D$3 -> 587.44076 | L33: =J33*D$3 -> 282.01764
A34: =Data!A29 -> 051221-LS-WM-35m-To | B34: =Data!H29 -> 41.183333 | C34: =Data!C29/Data!F29 -> 49.165932 | E34: =Data!G29/Data!F29 -> 24.099052 | G34: =C34-(G$3+G$4*B34) -> -1.4569351 | H34: =E34-(H$3+H$4*B34) -> -0.30911374 | I34: =G34*(B$7/B$9)+B$3 -> 36.878834 | J34: =H34*(C$7)+C$3 -> 20.134709 | K34: =I34*D$3 -> 512.61579 | L34: =J34*D$3 -> 279.87245 | M34: =AVERAGE(K34:K36) -> 512.35744 | N34: =AVERAGE(L34:L36) -> 280.09724 | O34: =Data!A29 -> 051221-LS-WM-35m-To
B35: =Data!H30 -> 41.316667 | C35: =Data!C30/Data!F30 -> 49.157733 | E35: =Data!G30/Data!F30 -> 24.117415 | G35: =C35-(G$3+G$4*B35) -> -1.4650913 | H35: =E35-(H$3+H$4*B35) -> -0.29074849 | I35: =G35*(B$7/B$9)+B$3 -> 36.87151 | J35: =H35*(C$7)+C$3 -> 20.150055 | K35: =I35*D$3 -> 512.51399 | L35: =J35*D$3 -> 280.08576
B36: =Data!H31 -> 41.533333 | C36: =Data!C31/Data!F31 -> 49.111877 | E36: =Data!G31/Data!F31 -> 24.138741 | G36: =C36-(G$3+G$4*B36) -> -1.5108788 | H36: =E36-(H$3+H$4*B36) -> -0.26941785 | I36: =G36*(B$7/B$9)+B$3 -> 36.830398 | J36: =H36*(C$7)+C$3 -> 20.167878 | K36: =I36*D$3 -> 511.94253 | L36: =J36*D$3 -> 280.33351
A37: =Data!A32 -> 051221-LS-WM-163m-To | B37: =Data!H32 -> 43.966667 | C37: =Data!C32/Data!F32 -> 49.266355 | E37: =Data!G32/Data!F32 -> 24.140065 | G37: =C37-(G$3+G$4*B37) -> -1.3556249 | H37: =E37-(H$3+H$4*B37) -> -0.2680494 | I37: =G37*(B$7/B$9)+B$3 -> 36.969799 | J37: =H37*(C$7)+C$3 -> 20.169022 | K37: =I37*D$3 -> 513.88021 | L37: =J37*D$3 -> 280.3494 | M37: =AVERAGE(K37:K39) -> 514.02528 | N37: =AVERAGE(L37:L39) -> 280.43057 | O37: =Data!A32 -> 051221-LS-WM-163m-To
B38: =Data!H33 -> 44.05 | C38: =Data!C33/Data!F33 -> 49.264875 | E38: =Data!G33/Data!F33 -> 24.145741 | G38: =C38-(G$3+G$4*B38) -> -1.3570784 | H38: =E38-(H$3+H$4*B38) -> -0.2623712 | I38: =G38*(B$7/B$9)+B$3 -> 36.968494 | J38: =H38*(C$7)+C$3 -> 20.173766 | K38: =I38*D$3 -> 513.86206 | L38: =J38*D$3 -> 280.41535
B39: =Data!H34 -> 44.183333 | C39: =Data!C34/Data!F34 -> 49.302611 | E39: =Data!G34/Data!F34 -> 24.155348 | G39: =C39-(G$3+G$4*B39) -> -1.3193 | H39: =E39-(H$3+H$4*B39) -> -0.25276236 | I39: =G39*(B$7/B$9)+B$3 -> 37.002415 | J39: =H39*(C$7)+C$3 -> 20.181795 | K39: =I39*D$3 -> 514.33356 | L39: =J39*D$3 -> 280.52695
A40: =Data!A35 -> 051221-LS-WM-163m-To | B40: =Data!H35 -> 47.133333 | C40: =Data!C35/Data!F35 -> 49.206906 | E40: =Data!G35/Data!F35 -> 24.022382 | G40: =C40-(G$3+G$4*B40) -> -1.414065 | H40: =E40-(H$3+H$4*B40) -> -0.38567352 | I40: =G40*(B$7/B$9)+B$3 -> 36.917326 | J40: =H40*(C$7)+C$3 -> 20.070736 | K40: =I40*D$3 -> 513.15083 | L40: =J40*D$3 -> 278.98324 | M40: =AVERAGE(K40:K42) -> 513.02306 | N40: =AVERAGE(L40:L42) -> 278.91296 | O40: =Data!A35 -> 051221-LS-WM-163m-To
B41: =Data!H36 -> 47.266667 | C41: =Data!C36/Data!F36 -> 49.215888 | E41: =Data!G36/Data!F36 -> 24.018514 | G41: =C41-(G$3+G$4*B41) -> -1.4050406 | H41: =E41-(H$3+H$4*B41) -> -0.38953898 | I41: =G41*(B$7/B$9)+B$3 -> 36.925429 | J41: =H41*(C$7)+C$3 -> 20.067507 | K41: =I41*D$3 -> 513.26346 | L41: =J41*D$3 -> 278.93834
B42: =Data!H37 -> 47.35 | C42: =Data!C37/Data!F37 -> 49.167098 | E42: =Data!G37/Data!F37 -> 24.008091 | G42: =C42-(G$3+G$4*B42) -> -1.4538034 | H42: =E42-(H$3+H$4*B42) -> -0.39996054 | I42: =G42*(B$7/B$9)+B$3 -> 36.881646 | J42: =H42*(C$7)+C$3 -> 20.058798 | K42: =I42*D$3 -> 512.65487 | L42: =J42*D$3 -> 278.8173
...

Sheet 30N2
A1: 531.2 | B1: =actual N2 at 20/0
A2: =AVERAGE(Data!C8:C10,Data!C14:C16,Data!C56:C58,Data!C86:C88,Data!C92:C94,Data!C152:C154,Data!C212:C214,Data!C218:C220) -> 5.9219521e-08 | B2: =average measured N2 at 20/0
C4: x | D4: y | F4: N30 based
B5: N2*O2 | C5: SQRT | D5: N30 | E5: Excess | F5: on N2 | H5: SUMMARY OUTPUT
A7: =Data!A8 -> 20/0 | B7: =Data!C8*Data!G8 -> 1.8775519e-15 | C7: =SQRT(B7) -> 4.3330727e-08 | D7: =Data!E8 -> 1.134001e-11 | E7: =D7-(C7*I$22+I$21) -> 4.8318881e-14 | F7: =A$1*E7/A$2 -> 0.00043342109 | H7: Regression Statistics
B8: =Data!C9*Data!G9 -> 1.8805594e-15 | C8: =SQRT(B8) -> 4.3365417e-08 | D8: =Data!E9 -> 1.150738e-11 | E8: =D8-(C8*I$22+I$21) -> 2.0966596e-13 | F8: =A$1*E8/A$2 -> 0.0018807068 | H8: Multiple R | I8: 0.92521334
B9: =Data!C10*Data!G10 -> 1.875994e-15 | C9: =SQRT(B9) -> 4.3312746e-08 | D9: =Data!E10 -> 1.144119e-11 | E9: =D9-(C9*I$22+I$21) -> 1.5262079e-13 | F9: =A$1*E9/A$2 -> 0.0013690108 | H9: R Square | I9: 0.85601973
A10: =Data!A11 -> 30/0 | B10: =Data!C11*Data!G11 -> 1.3248716e-15 | C10: =SQRT(B10) -> 3.6398785e-08 | D10: =Data!E11 -> 1.067302e-11 | E10: =D10-(C10*I$22+I$21) -> 5.8486274e-13 | F10: =A$1*E10/A$2 -> 0.0052462276 | H10: Adjusted R Square | I10: 0.85288973
B11: =Data!C12*Data!G12 -> 1.3248727e-15 | C11: =SQRT(B11) -> 3.6398801e-08 | D11: =Data!E12 -> 1.037504e-11 | E11: =D11-(C11*I$22+I$21) -> 2.8687998e-13 | F11: =A$1*E11/A$2 -> 0.0025733177 | H11: Standard Error | I11: 2.4535244e-13
B12: =Data!C13*Data!G13 -> 1.3227606e-15 | C12: =SQRT(B12) -> 3.6369776e-08 | D12: =Data!E13 -> 1.031778e-11 | E12: =D12-(C12*I$22+I$21) -> 2.3465935e-13 | F12: =A$1*E12/A$2 -> 0.0021048979 | H12: Observations | I12: 48
A13: =Data!A14 -> 20/0 | B13: =Data!C14*Data!G14 -> 1.8583397e-15 | C13: =SQRT(B13) -> 4.3108465e-08 | D13: =Data!E14 -> 1.131205e-11 | E13: =D13-(C13*I$22+I$21) -> 5.8948389e-14 | F13: =A$1*E13/A$2 -> 0.00052876794
B14: =Data!C15*Data!G15 -> 1.8603025e-15 | C14: =SQRT(B14) -> 4.3131224e-08 | D14: =Data!E15 -> 1.140981e-11 | E14: =D14-(C14*I$22+I$21) -> 1.5275684e-13 | F14: =A$1*E14/A$2 -> 0.0013702312 | H14: ANOVA
B15: =Data!C16*Data!G16 -> 1.8599038e-15 | C15: =SQRT(B15) -> 4.3126602e-08 | D15: =Data!E16 -> 1.137642e-11 | E15: =D15-(C15*I$22+I$21) -> 1.201694e-13 | F15: =A$1*E15/A$2 -> 0.0010779213 | I15: df | J15: SS | K15: MS | L15: F | M15: Significance F
A16: =Data!A17 -> 30/0 | B16: =Data!C17*Data!G17 -> 1.3113419e-15 | C16: =SQRT(B16) -> 3.6212455e-08 | D16: =Data!E17 -> 1.021252e-11 | E16: =D16-(C16*I$22+I$21) -> 1.5671357e-13 | F16: =A$1*E16/A$2 -> 0.0014057231 | H16: Regression | I16: 1 | J16: 1.6463395e-23 | K16: 1.6463395e-23 | L16: 273.48823 | M16: 5.5133839e-21
B17: =Data!C18*Data!G18 -> 1.3109618e-15 | C17: =SQRT(B17) -> 3.6207206e-08 | D17: =Data!E18 -> 1.027509e-11 | E17: =D17-(C17*I$22+I$21) -> 2.2019501e-13 | F17: =A$1*E17/A$2 -> 0.0019751526 | H17: Residual | I17: 46 | J17: 2.7690996e-24 | K17: 6.0197818e-26
B18: =Data!C19*Data!G19 -> 1.3080609e-15 | C18: =SQRT(B18) -> 3.6167124e-08 | D18: =Data!E19 -> 1.044589e-11 | E18: =D18-(C18*I$22+I$21) -> 3.97954e-13 | F18: =A$1*E18/A$2 -> 0.0035696534 | H18: Total | I18: 47 | J18: 1.9232494e-23
A19: =Data!A56 -> 20/0 | B19: =Data!C56*Data!G56 -> 1.6755065e-15 | C19: =SQRT(B19) -> 4.0932952e-08 | D19: =Data!E56 -> 1.096884e-11 | E19: =D19-(C19*I$22+I$21) -> 9.3454146e-14 | F19: =A$1*E19/A$2 -> 0.00083828511
B20: =Data!C57*Data!G57 -> 1.6727244e-15 | C20: =SQRT(B20) -> 4.0898953e-08 | D20: =Data!E57 -> 1.133998e-11 | E20: =D20-(C20*I$22+I$21) -> 4.7049698e-13 | F20: =A$1*E20/A$2 -> 0.0042203651 | I20: Coefficients | J20: Standard Error | K20: t Stat | L20: P-value | M20: Lower 95% | N20: Upper 95% | O20: Lower 95.0% | P20: Upper 95.0%
B21: =Data!C58*Data!G58 -> 1.6759674e-15 | C21: =SQRT(B21) -> 4.0938581e-08 | D21: =Data!E58 -> 1.120492e-11 | E21: =D21-(C21*I$22+I$21) -> 3.2855685e-13 | F21: =A$1*E21/A$2 -> 0.00294716 | H21: Intercept | I21: 3.7685473e-12 | J21: 3.9988768e-13 | K21: 9.4240145 | L21: 2.5937484e-12 | M21: 2.9636152e-12 | N21: 4.5734795e-12 | O21: 2.9636152e-12 | P21: 4.5734795e-12
A22: =Data!A59 -> 30/0 | B22: =Data!C59*Data!G59 -> 1.1974746e-15 | C22: =SQRT(B22) -> 3.4604546e-08 | D22: =Data!E59 -> 1.00296e-11 | E22: =D22-(C22*I$22+I$21) -> 2.5296112e-13 | F22: =A$1*E22/A$2 -> 0.0022690651 | H22: X Variable 1 | I22: 0.00017362145 | J22: 1.0498665e-05 | K22: 16.537479 | L22: 5.5133839e-21 | M22: 0.00015248874 | N22: 0.00019475417 | O22: 0.00015248874 | P22: 0.00019475417
B23: =Data!C60*Data!G60 -> 1.1981711e-15 | C23: =SQRT(B23) -> 3.4614608e-08 | D23: =Data!E60 -> 1.006122e-11 | E23: =D23-(C23*I$22+I$21) -> 2.828341e-13 | F23: =A$1*E23/A$2 -> 0.0025370262
B24: =Data!C61*Data!G61 -> 1.2001427e-15 | C24: =SQRT(B24) -> 3.4643076e-08 | D24: =Data!E61 -> 1.012706e-11 | E24: =D24-(C24*I$22+I$21) -> 3.4373145e-13 | F24: =A$1*E24/A$2 -> 0.0030832763
A25: =Data!A86 -> 20/0 | B25: =Data!C86*Data!G86 -> 1.6296127e-15 | C25: =SQRT(B25) -> 4.0368461e-08 | D25: =Data!E86 -> 1.085515e-11 | E25: =D25-(C25*I$22+I$21) -> 7.7771764e-14 | F25: =A$1*E25/A$2 -> 0.00069761391
B26: =Data!C87*Data!G87 -> 1.6297321e-15 | C26: =SQRT(B26) -> 4.036994e-08 | D26: =Data!E87 -> 1.090813e-11 | E26: =D26-(C26*I$22+I$21) -> 1.3049505e-13 | F26: =A$1*E26/A$2 -> 0.0011705426
B27: =Data!C88*Data!G88 -> 1.6291764e-15 | C27: =SQRT(B27) -> 4.0363058e-08 | D27: =Data!E88 -> 1.070526e-11 | E27: =D27-(C27*I$22+I$21) -> -7.1180067e-14 | F27: =A$1*E27/A$2 -> -0.00063848628
A28: =Data!A89 -> 30/0 | B28: =Data!C89*Data!G89 -> 1.1747177e-15 | C28: =SQRT(B28) -> 3.4274155e-08 | D28: =Data!E89 -> 9.739623e-12 | E28: =D28-(C28*I$22+I$21) -> 2.0347034e-14 | F28: =A$1*E28/A$2 -> 0.0001825132
B29: =Data!C90*Data!G90 -> 1.1748895e-15 | C29: =SQRT(B29) -> 3.4276661e-08 | D29: =Data!E90 -> 9.829698e-12 | E29: =D29-(C29*I$22+I$21) -> 1.0998701e-13 | F29: =A$1*E29/A$2 -> 0.00098658513
B30: =Data!C91*Data!G91 -> 1.174514e-15 | C30: =SQRT(B30) -> 3.4271183e-08 | D30: =Data!E91 -> 9.622466e-12 | E30: =D30-(C30*I$22+I$21) -> -9.6293867e-14 | F30: =A$1*E30/A$2 -> -0.00086375745
A31: =Data!A92 -> 20/0 | B31: =Data!C92*Data!G92 -> 1.6447719e-15 | C31: =SQRT(B31) -> 4.0555788e-08 | D31: =Data!E92 -> 1.054258e-11 | E31: =D31-(C31*I$22+I$21) -> -2.6732215e-13 | F31: =A$1*E31/A$2 -> -0.0023978838
B32: =Data!C93*Data!G93 -> 1.6435994e-15 | C32: =SQRT(B32) -> 4.054133e-08 | D32: =Data!E93 -> 1.075568e-11 | E32: =D32-(C32*I$22+I$21) -> -5.1711877e-14 | F32: =A$1*E32/A$2 -> -0.00046385632
B33: =Data!C94*Data!G94 -> 1.6431168e-15 | C33: =SQRT(B33) -> 4.0535377e-08 | D33: =Data!E94 -> 1.088942e-11 | E33: =D33-(C33*I$22+I$21) -> 8.306169e-14 | F33: =A$1*E33/A$2 -> 0.00074506462
A34: =Data!A95 -> 30/0 | B34: =Data!C95*Data!G95 -> 1.1733169e-15 | C34: =SQRT(B34) -> 3.4253714e-08 | D34: =Data!E95 -> 9.571112e-12 | E34: =D34-(C34*I$22+I$21) -> -1.4461496e-13 | F34: =A$1*E34/A$2 -> -0.0012971984
B35: =Data!C96*Data!G96 -> 1.1744975e-15 | C35: =SQRT(B35) -> 3.4270943e-08 | D35: =Data!E96 -> 9.732601e-12 | E35: =D35-(C35*I$22+I$21) -> 1.3882748e-14 | F35: =A$1*E35/A$2 -> 0.00012452846
B36: =Data!C97*Data!G97 -> 1.1758868e-15 | C36: =SQRT(B36) -> 3.4291206e-08 | D36: =Data!E97 -> 9.625016e-12 | E36: =D36-(C36*I$22+I$21) -> -9.7220325e-14 | F36: =A$1*E36/A$2 -> -0.00087206779
A37: =Data!A152 -> 20/0 | B37: =Data!C152*Data!G152 -> 1.6256397e-15 | C37: =SQRT(B37) -> 4.0319223e-08 | D37: =Data!E152 -> 1.052609e-11 | E37: =D37-(C37*I$22+I$21) -> -2.4273934e-13 | F37: =A$1*E37/A$2 -> -0.0021773755
B38: =Data!C153*Data!G153 -> 1.6252108e-15 | C38: =SQRT(B38) -> 4.0313904e-08 | D38: =Data!E153 -> 1.049335e-11 | E38: =D38-(C38*I$22+I$21) -> -2.7455584e-13 | F38: =A$1*E38/A$2 -> -0.00246277
B39: =Data!C154*Data!G154 -> 1.6251483e-15 | C39: =SQRT(B39) -> 4.0313128e-08 | D39: =Data!E154 -> 1.055976e-11 | E39: =D39-(C39*I$22+I$21) -> -2.0801115e-13 | F39: =A$1*E39/A$2 -> -0.0018658632
A40: =Data!A155 -> 30/0 | B40: =Data!C155*Data!G155 -> 1.1644953e-15 | C40: =SQRT(B40) -> 3.4124702e-08 | D40: =Data!E155 -> 9.793371e-12 | E40: =D40-(C40*I$22+I$21) -> 1.0004341e-13 | F40: =A$1*E40/A$2 -> 0.00089739093
B41: =Data!C156*Data!G156 -> 1.1614751e-15 | C41: =SQRT(B41) -> 3.4080421e-08 | D41: =Data!E156 -> 9.511184e-12 | E41: =D41-(C41*I$22+I$21) -> -1.7445559e-13 | F41: =A$1*E41/A$2 -> -0.0015648692
B42: =Data!C157*Data!G157 -> 1.1642867e-15 | C42: =SQRT(B42) -> 3.4121646e-08 | D42: =Data!E157 -> 9.450335e-12 | E42: =D42-(C42*I$22+I$21) -> -2.4246207e-13 | F42: =A$1*E42/A$2 -> -0.0021748885
...

Sheet 29N2
A1: ='30N2'!A1 -> 531.2 | B1: =actual N2 at 20/0
A2: ='30N2'!A2 -> 5.9219521e-08 | B2: =average measured N2 at 20/0
B4: x | C4: y | E4: N29 based
B5: N28 | C5: N29 | D5: Excess | E5: on N2 | G5: SUMMARY OUTPUT
A7: ='30N2'!A7 -> 20/0 | B7: =Data!C8 -> 6.241656e-08 | C7: =Data!D8 -> 4.392797e-10 | D7: =C7-(B7*H$22+H$21) -> -8.6571328e-14 | E7: =A$1*D7/A$2 -> -0.00077654613 | G7: Regression Statistics
B8: =Data!C9 -> 6.249566e-08 | C8: =Data!D9 -> 4.396584e-10 | D8: =C8-(B8*H$22+H$21) -> -2.6121078e-13 | E8: =A$1*D8/A$2 -> -0.0023430646 | G8: Multiple R | H8: 0.9998193
B9: =Data!C10 -> 6.239389e-08 | C9: =Data!D10 -> 4.406928e-10 | D9: =C9-(B9*H$22+H$21) -> 1.4851153e-12 | E9: =A$1*D9/A$2 -> 0.013321507 | G9: R Square | H9: 0.99963863
A10: ='30N2'!A10 -> 30/0 | B10: =Data!C11 -> 5.282325e-08 | C10: =Data!D11 -> 3.717482e-10 | D10: =C10-(B10*H$22+H$21) -> -5.0862945e-13 | E10: =A$1*D10/A$2 -> -0.0045624138 | G10: Adjusted R Square | H10: 0.99963077
B11: =Data!C12 -> 5.277345e-08 | C11: =Data!D12 -> 3.715286e-10 | D11: =C11-(B11*H$22+H$21) -> -3.7985644e-13 | E11: =A$1*D11/A$2 -> -0.0034073181 | G11: Standard Error | H11: 6.367191e-13
B12: =Data!C13 -> 5.278764e-08 | C12: =Data!D13 -> 3.717964e-10 | D12: =C12-(B12*H$22+H$21) -> -2.1132176e-13 | E12: =A$1*D12/A$2 -> -0.0018955594 | G12: Observations | H12: 48
A13: ='30N2'!A13 -> 20/0 | B13: =Data!C14 -> 6.211614e-08 | C13: =Data!D14 -> 4.365749e-10 | D13: =C13-(B13*H$22+H$21) -> -6.898007e-13 | E13: =A$1*D13/A$2 -> -0.0061875227
B14: =Data!C15 -> 6.218553e-08 | C14: =Data!D15 -> 4.370271e-10 | D14: =C14-(B14*H$22+H$21) -> -7.2301441e-13 | E14: =A$1*D14/A$2 -> -0.0064854502 | G14: ANOVA
B15: =Data!C16 -> 6.21415e-08 | C15: =Data!D16 -> 4.381185e-10 | D15: =C15-(B15*H$22+H$21) -> 6.763949e-13 | E15: =A$1*D15/A$2 -> 0.0060672725 | H15: df | I15: SS | J15: MS | K15: F | L15: Significance F
A16: ='30N2'!A16 -> 30/0 | B16: =Data!C17 -> 5.255534e-08 | C16: =Data!D17 -> 3.704886e-10 | D16: =C16-(B16*H$22+H$21) -> 1.0591937e-13 | E16: =A$1*D16/A$2 -> 0.00095009836 | G16: Regression | H16: 1 | I16: 5.1586937e-20 | J16: 5.1586937e-20 | K16: 127245.96 | L16: 7.9668052e-81
B17: =Data!C18 -> 5.247932e-08 | C17: =Data!D18 -> 3.698069e-10 | D17: =C17-(B17*H$22+H$21) -> -4.3987143e-14 | E17: =A$1*D17/A$2 -> -0.00039456534 | G17: Residual | H17: 46 | I17: 1.8648916e-23 | J17: 4.0541121e-25
B18: =Data!C19 -> 5.245805e-08 | C18: =Data!D19 -> 3.689866e-10 | D18: =C18-(B18*H$22+H$21) -> -7.154941e-13 | E18: =A$1*D18/A$2 -> -0.0064179929 | G18: Total | H18: 47 | I18: 5.1605586e-20
A19: ='30N2'!A19 -> 20/0 | B19: =Data!C56 -> 5.895125e-08 | C19: =Data!D56 -> 4.149025e-10 | D19: =C19-(B19*H$22+H$21) -> -2.2239687e-13 | E19: =A$1*D19/A$2 -> -0.0019949033
B20: =Data!C57 -> 5.887273e-08 | C20: =Data!D57 -> 4.145086e-10 | D20: =C20-(B20*H$22+H$21) -> -6.7014774e-14 | E20: =A$1*D20/A$2 -> -0.00060112354 | H20: Coefficients | I20: Standard Error | J20: t Stat | K20: P-value | L20: Lower 95% | M20: Upper 95% | N20: Lower 95.0% | O20: Upper 95.0%
B21: =Data!C58 -> 5.897757e-08 | C21: =Data!D58 -> 4.152285e-10 | D21: =C21-(B21*H$22+H$21) -> -8.0516894e-14 | E21: =A$1*D21/A$2 -> -0.00072223776 | G21: Intercept | H21: 2.7348578e-12 | I21: 1.0787438e-12 | J21: 2.5352245 | K21: 0.014701501 | L21: 5.6345907e-13 | M21: 4.9062565e-12 | N21: 5.6345907e-13 | O21: 4.9062565e-12
A22: ='30N2'!A22 -> 30/0 | B22: =Data!C59 -> 5.015424e-08 | C22: =Data!D59 -> 3.543148e-10 | D22: =C22-(B22*H$22+H$21) -> 7.288747e-13 | E22: =A$1*D22/A$2 -> 0.0065380171 | G22: X Variable 1 | H22: 0.0069954418 | I22: 1.9610703e-05 | J22: 356.71551 | K22: 7.9668052e-81 | L22: 0.0069559675 | M22: 0.0070349161 | N22: 0.0069559675 | O22: 0.0070349161
B23: =Data!C60 -> 5.017883e-08 | C23: =Data!D60 -> 3.538924e-10 | D23: =C23-(B23*H$22+H$21) -> 1.3445679e-13 | E23: =A$1*D23/A$2 -> 0.0012060794
B24: =Data!C61 -> 5.023872e-08 | C24: =Data!D61 -> 3.543515e-10 | D24: =C24-(B24*H$22+H$21) -> 1.7459978e-13 | E24: =A$1*D24/A$2 -> 0.0015661627
A25: ='30N2'!A25 -> 20/0 | B25: =Data!C86 -> 5.804696e-08 | C25: =Data!D86 -> 4.084777e-10 | D25: =C25-(B25*H$22+H$21) -> -3.2128879e-13 | E25: =A$1*D25/A$2 -> -0.0028819653
B26: =Data!C87 -> 5.809676e-08 | C26: =Data!D87 -> 4.091306e-10 | D26: =C26-(B26*H$22+H$21) -> -1.6761792e-14 | E26: =A$1*D26/A$2 -> -0.00015035353
B27: =Data!C88 -> 5.808155e-08 | C27: =Data!D88 -> 4.07538e-10 | D27: =C27-(B27*H$22+H$21) -> -1.5029611e-12 | E27: =A$1*D27/A$2 -> -0.013481584
A28: ='30N2'!A28 -> 30/0 | B28: =Data!C89 -> 4.972186e-08 | C28: =Data!D89 -> 3.519018e-10 | D28: =C28-(B28*H$22+H$21) -> 1.3405638e-12 | E28: =A$1*D28/A$2 -> 0.012024878
B29: =Data!C90 -> 4.972269e-08 | C29: =Data!D90 -> 3.500491e-10 | D29: =C29-(B29*H$22+H$21) -> -5.1794238e-13 | E29: =A$1*D29/A$2 -> -0.004645951
B30: =Data!C91 -> 4.971675e-08 | C30: =Data!D91 -> 3.499057e-10 | D30: =C30-(B30*H$22+H$21) -> -6.1978946e-13 | E30: =A$1*D30/A$2 -> -0.0055595208
A31: ='30N2'!A31 -> 20/0 | B31: =Data!C92 -> 5.835403e-08 | C31: =Data!D92 -> 4.114449e-10 | D31: =C31-(B31*H$22+H$21) -> 4.9782089e-13 | E31: =A$1*D31/A$2 -> 0.004465461
B32: =Data!C93 -> 5.830093e-08 | C32: =Data!D93 -> 4.100867e-10 | D32: =C32-(B32*H$22+H$21) -> -4.8892115e-13 | E32: =A$1*D32/A$2 -> -0.0043856301
B33: =Data!C94 -> 5.833318e-08 | C33: =Data!D94 -> 4.105515e-10 | D33: =C33-(B33*H$22+H$21) -> -2.4972414e-13 | E33: =A$1*D33/A$2 -> -0.0022400294
A34: ='30N2'!A34 -> 30/0 | B34: =Data!C95 -> 4.964097e-08 | C34: =Data!D95 -> 3.499651e-10 | D34: =C34-(B34*H$22+H$21) -> -3.0274878e-14 | E34: =A$1*D34/A$2 -> -0.00027156612
B35: =Data!C96 -> 4.970524e-08 | C35: =Data!D96 -> 3.501202e-10 | D35: =C35-(B35*H$22+H$21) -> -3.2477192e-13 | E35: =A$1*D35/A$2 -> -0.0029132091
B36: =Data!C97 -> 4.973888e-08 | C36: =Data!D97 -> 3.503465e-10 | D36: =C36-(B36*H$22+H$21) -> -3.3379859e-13 | E36: =A$1*D36/A$2 -> -0.0029941784
A37: ='30N2'!A37 -> 20/0 | B37: =Data!C152 -> 5.799245e-08 | C37: =Data!D152 -> 4.085233e-10 | D37: =C37-(B37*H$22+H$21) -> 1.0563274e-13 | E37: =A$1*D37/A$2 -> 0.00094752731
B38: =Data!C153 -> 5.803257e-08 | C38: =Data!D153 -> 4.087445e-10 | D38: =C38-(B38*H$22+H$21) -> 4.6175618e-14 | E38: =A$1*D38/A$2 -> 0.00041419599
B39: =Data!C154 -> 5.802207e-08 | C39: =Data!D154 -> 4.091817e-10 | D39: =C39-(B39*H$22+H$21) -> 5.5682776e-13 | E39: =A$1*D39/A$2 -> 0.0049947534
A40: ='30N2'!A40 -> 30/0 | B40: =Data!C155 -> 4.950477e-08 | C40: =Data!D155 -> 3.487987e-10 | D40: =C40-(B40*H$22+H$21) -> -2.438957e-13 | E40: =A$1*D40/A$2 -> -0.0021877482
B41: =Data!C156 -> 4.943274e-08 | C41: =Data!D156 -> 3.482881e-10 | D41: =C41-(B41*H$22+H$21) -> -2.5061403e-13 | E41: =A$1*D41/A$2 -> -0.0022480116
B42: =Data!C157 -> 4.950727e-08 | C42: =Data!D157 -> 3.489865e-10 | D42: =C42-(B42*H$22+H$21) -> -7.3584308e-14 | E42: =A$1*D42/A$2 -> -0.00066005236
...
