Workbook

Sheet Data
A1: 052121-Lake Superior-Cores+Respirations-May2021
A6: Sample | B6: Time | C6: N2 | D6: O2 | E6: Ar | F6: N2_Ar | G6: O2_Ar | H6: Time
A8: 20 | B8: 0.54027778 | C8: 1.690634e-10 | D8: 7.996655e-11 | E8: 6.329942e-12 | F8: 26.70852 | G8: 12.63306 | H8: =M8-M$8 -> 0 | I8: 0.46233796 | J8: 10 | K8: 16 | L8: 43 | M8: =J8*60+K8+L8/60 -> 616.71667
A9: 20 | B9: 0.54042824 | C9: 1.689836e-10 | D9: 7.998829e-11 | E9: 6.329542e-12 | F9: 26.69761 | G9: 12.63729 | H9: =M9-M$8 -> 0.13333333 | I9: 0.46243056 | J9: 10 | K9: 16 | L9: 51 | M9: =J9*60+K9+L9/60 -> 616.85
A10: 20 | B10: 0.54047454 | C10: 1.689786e-10 | D10: 7.99964e-11 | E10: 6.328629e-12 | F10: 26.70067 | G10: 12.6404 | H10: =M10-M$8 -> 0.3 | I10: 0.46253472 | J10: 10 | K10: 17 | L10: 1 | M10: =J10*60+K10+L10/60 -> 617.01667
A11: 30 | B11: 0.54293981 | C11: 1.464004e-10 | D11: 6.847302e-11 | E11: 5.361757e-12 | F11: 27.30455 | G11: 12.77063 | H11: =M11-M$8 -> 5.0833333 | I11: 0.46653935 | J11: 10 | K11: 21 | L11: 48 | M11: =J11*60+K11+L11/60 -> 621.8
A12: 30 | B12: 0.54299769 | C12: 1.463889e-10 | D12: 6.846379e-11 | E12: 5.362715e-12 | F12: 27.29753 | G12: 12.76663 | H12: =M12-M$8 -> 5.2166667 | I12: 0.46664352 | J12: 10 | K12: 21 | L12: 56 | M12: =J12*60+K12+L12/60 -> 621.93333
A13: 30 | B13: 0.54326389 | C13: 1.462323e-10 | D13: 6.839896e-11 | E13: 5.355685e-12 | F13: 27.30412 | G13: 12.77128 | H13: =M13-M$8 -> 5.35 | I13: 0.46677083 | J13: 10 | K13: 22 | L13: 4 | M13: =J13*60+K13+L13/60 -> 622.06667
A14: Hardwoods_IN_T1_1 | B14: 0.54819444 | C14: 1.703647e-10 | D14: 6.002009e-11 | E14: 6.348015e-12 | F14: 26.83747 | G14: 9.454938 | H14: =M14-M$8 -> 9.6833333 | I14: 0.46967593 | J14: 10 | K14: 26 | L14: 24 | M14: =J14*60+K14+L14/60 -> 626.4
A15: Hardwoods_IN_T1_2 | B15: 0.54829861 | C15: 1.703934e-10 | D15: 6.002097e-11 | E15: 6.350166e-12 | F15: 26.8329 | G15: 9.451875 | H15: =M15-M$8 -> 9.8166667 | I15: 0.46969907 | J15: 10 | K15: 26 | L15: 32 | M15: =J15*60+K15+L15/60 -> 626.53333
A16: Hardwoods_IN_T1_3 | B16: 0.54835648 | C16: 1.704076e-10 | D16: 6.001982e-11 | E16: 6.352163e-12 | F16: 26.8267 | G16: 9.448721 | H16: =M16-M$8 -> 10.033333 | I16: 0.46976852 | J16: 10 | K16: 26 | L16: 45 | M16: =J16*60+K16+L16/60 -> 626.75
A17: Hardwoods_13_T1_1 | B17: 0.55128472 | C17: 1.682895e-10 | D17: 4.941083e-11 | E17: 6.275724e-12 | F17: 26.81594 | G17: 7.873327 | H17: =M17-M$8 -> 16.416667 | I17: 0.47162037 | J17: 10 | K17: 33 | L17: 8 | M17: =J17*60+K17+L17/60 -> 633.13333
A18: Hardwoods_13_T1_2 | B18: 0.55138889 | C18: 1.683322e-10 | D18: 4.940059e-11 | E18: 6.277455e-12 | F18: 26.81536 | G18: 7.869526 | H18: =M18-M$8 -> 16.55 | I18: 0.47168981 | J18: 10 | K18: 33 | L18: 16 | M18: =J18*60+K18+L18/60 -> 633.26667
A19: Hardwoods_13_T1_3 | B19: 0.5515162 | C19: 1.683272e-10 | D19: 4.938328e-11 | E19: 6.276681e-12 | F19: 26.81787 | G19: 7.867737 | H19: =M19-M$8 -> 16.683333 | I19: 0.47184028 | J19: 10 | K19: 33 | L19: 24 | M19: =J19*60+K19+L19/60 -> 633.4
A20: Hardwoods_14_T1_1 | B20: 0.55454861 | C20: 1.678446e-10 | D20: 5.783908e-11 | E20: 6.259296e-12 | F20: 26.81525 | G20: 9.240508 | H20: =M20-M$8 -> 22.2 | I20: 0.47496528 | J20: 10 | K20: 38 | L20: 55 | M20: =J20*60+K20+L20/60 -> 638.91667
A21: Hardwoods_14_T1_2 | B21: 0.5547338 | C21: 1.678652e-10 | D21: 5.785856e-11 | E21: 6.26218e-12 | F21: 26.8062 | G21: 9.239364 | H21: =M21-M$8 -> 22.333333 | I21: 0.47513889 | J21: 10 | K21: 39 | L21: 3 | M21: =J21*60+K21+L21/60 -> 639.05
A22: Hardwoods_14_T1_3 | B22: 0.55480324 | C22: 1.678641e-10 | D22: 5.786206e-11 | E22: 6.262415e-12 | F22: 26.80501 | G22: 9.239575 | H22: =M22-M$8 -> 22.466667 | I22: 0.47533565 | J22: 10 | K22: 39 | L22: 11 | M22: =J22*60+K22+L22/60 -> 639.18333
A23: 20 | B23: 0.55832176 | C23: 1.668713e-10 | D23: 7.890976e-11 | E23: 6.251678e-12 | F23: 26.69224 | G23: 12.62217 | H23: =M23-M$8 -> 28.716667 | I23: 0.47762731 | J23: 10 | K23: 45 | L23: 26 | M23: =J23*60+K23+L23/60 -> 645.43333
A24: 20 | B24: 0.55844907 | C24: 1.66814e-10 | D24: 7.891462e-11 | E24: 6.248129e-12 | F24: 26.69823 | G24: 12.63012 | H24: =M24-M$8 -> 28.8 | I24: 0.47770833 | J24: 10 | K24: 45 | L24: 31 | M24: =J24*60+K24+L24/60 -> 645.51667
A25: 20 | B25: 0.55849537 | C25: 1.667948e-10 | D25: 7.891983e-11 | E25: 6.246936e-12 | F25: 26.70026 | G25: 12.63337 | H25: =M25-M$8 -> 29.016667 | I25: 0.47782407 | J25: 10 | K25: 45 | L25: 44 | M25: =J25*60+K25+L25/60 -> 645.73333
A26: 30 | B26: 0.5608912 | C26: 1.449711e-10 | D26: 6.76494e-11 | E26: 5.302363e-12 | F26: 27.34084 | G26: 12.75835 | H26: =M26-M$8 -> 35.483333 | I26: 0.48113426 | J26: 10 | K26: 52 | L26: 12 | M26: =J26*60+K26+L26/60 -> 652.2
A27: 30 | B27: 0.56115741 | C27: 1.447126e-10 | D27: 6.754768e-11 | E27: 5.295215e-12 | F27: 27.32894 | G27: 12.75636 | H27: =M27-M$8 -> 35.616667 | I27: 0.48121528 | J27: 10 | K27: 52 | L27: 20 | M27: =J27*60+K27+L27/60 -> 652.33333
A28: 30 | B28: 0.56127315 | C28: 1.446565e-10 | D28: 6.75252e-11 | E28: 5.293078e-12 | F28: 27.32938 | G28: 12.75726 | H28: =M28-M$8 -> 35.7 | I28: 0.4812963 | J28: 10 | K28: 52 | L28: 25 | M28: =J28*60+K28+L28/60 -> 652.41667

Sheet Regs
A1: 20/0 N2 | D1: SUMMARY OUTPUT
A3: N2/Ar | B3: time(min) | D3: Regression Statistics
A4: =Data!F8 -> 26.70852 | B4: =Data!H8 -> 0 | D4: Multiple R | E4: 0.55214209
A5: =Data!F9 -> 26.69761 | B5: =Data!H9 -> 0.13333333 | D5: R Square | E5: 0.30486088
A6: =Data!F10 -> 26.70067 | B6: =Data!H10 -> 0.3 | D6: Adjusted R Square | E6: 0.13107611
A7: =Data!F23 -> 26.69224 | B7: =Data!H23 -> 28.716667 | D7: Standard Error | E7: 0.004952796
A8: =Data!F24 -> 26.69823 | B8: =Data!H24 -> 28.8 | D8: Observations | E8: 6
A9: =Data!F25 -> 26.70026 | B9: =Data!H25 -> 29.016667
A10: =Data!#REF! -> #REF! | B10: =Data!#REF! -> #REF! | D10: ANOVA
A11: =Data!#REF! -> #REF! | B11: =Data!#REF! -> #REF! | E11: df | F11: SS | G11: MS | H11: F | I11: Significance F
A12: =Data!#REF! -> #REF! | B12: =Data!#REF! -> #REF! | D12: Regression | E12: 1 | F12: 4.3031932e-05 | G12: 4.3031932e-05 | H12: 1.7542439 | I12: 0.25595013
A13: =Data!#REF! -> #REF! | B13: =Data!#REF! -> #REF! | D13: Residual | E13: 4 | F13: 9.8120751e-05 | G13: 2.4530188e-05
A14: =Data!#REF! -> #REF! | B14: =Data!#REF! -> #REF! | D14: Total | E14: 5 | F14: 0.00014115268
A15: =Data!#REF! -> #REF! | B15: =Data!#REF! -> #REF!
A16: =Data!#REF! -> #REF! | B16: =Data!#REF! -> #REF! | E16: Coefficients | F16: Standard Error | G16: t Stat | H16: P-value | I16: Lower 95% | J16: Upper 95% | K16: Lower 95.0% | L16: Upper 95.0%
A17: =Data!#REF! -> #REF! | B17: =Data!#REF! -> #REF! | D17: Intercept | E17: 26.702293 | F17: 0.002873871 | G17: 9291.4029 | H17: 8.0505593e-16 | I17: 26.694314 | J17: 26.710272 | K17: 26.694314 | L17: 26.710272
A18: =Data!#REF! -> #REF! | B18: =Data!#REF! -> #REF! | D18: X Variable 1 | E18: -0.00018661714 | F18: 0.00014089856 | G18: -1.3244787 | H18: 0.25595013 | I18: -0.00057781424 | J18: 0.00020457997 | K18: -0.00057781424 | L18: 0.00020457997
B19: =Data!#REF! -> #REF!
B20: =Data!#REF! -> #REF!
B21: =Data!#REF! -> #REF!
B22: =Data!#REF! -> #REF!
B23: =Data!#REF! -> #REF!
B24: =Data!#REF! -> #REF!
A28: =Data!C145/Data!F145 -> #DIV/0! | B28: =Data!H220 -> 0
A29: =Data!C146/Data!F146 -> #DIV/0! | B29: =Data!H221 -> 0
A30: =Data!C147/Data!F147 -> #DIV/0! | B30: =Data!H222 -> 0
A31: =Data!C271/Data!F271 -> #DIV/0! | B31: =Data!H346 -> 0
A32: =Data!C272/Data!F272 -> #DIV/0! | B32: =Data!H347 -> 0
A33: =Data!C273/Data!F273 -> #DIV/0! | B33: =Data!H348 -> 0
A34: =Data!C337/Data!F337 -> #DIV/0! | B34: =Data!H412 -> 0
A35: =Data!C338/Data!F338 -> #DIV/0! | B35: =Data!H413 -> 0
A36: =Data!C339/Data!F339 -> #DIV/0! | B36: =Data!H414 -> 0
A37: =Data!C343/Data!F343 -> #DIV/0! | B37: =Data!H418 -> 0
A38: =Data!C344/Data!F344 -> #DIV/0! | B38: =Data!H419 -> 0
A39: =Data!C345/Data!F345 -> #DIV/0! | B39: =Data!H420 -> 0
A41: 30/0 N2 | D41: SUMMARY OUTPUT
A43: N2/Ar | B43: time(min) | D43: Regression Statistics
A44: =Data!#REF!/Data!#REF! -> #REF! | B44: =Data!H11 -> 5.0833333 | D44: Multiple R | E44: 0.44806265
A45: =Data!#REF!/Data!#REF! -> #REF! | B45: =Data!H12 -> 5.2166667 | D45: R Square | E45: 0.20076013
A46: =Data!#REF!/Data!#REF! -> #REF! | B46: =Data!H13 -> 5.35 | D46: Adjusted R Square | E46: 0.16443105
...

Sheet 28N2-O2
C1: Actual | G1: N2(20/0) | H1: O2(20/0)
B2: N2/Ar | C2: O2/Ar | D2: Ar | F2: r2 | G2: =Regs!E5 -> 0.30486088 | H2: =Regs!E85 -> 0.002298157
A3: 20/0 | B3: 38.187 | C3: 20.393 | D3: 13.9 | F3: intercept | G3: =Regs!E17 -> 26.702293 | H3: =Regs!E97 -> 24.408931
A4: 30/0 | B4: 38.861 | C4: 20.38 | D4: 11.6 | F4: slope | G4: =Regs!E18 -> -0.00018661714 | H4: =Regs!E98 -> -1.8582266e-05
A6: D= | B6: =(Regs!E57+Regs!E58*(Data!#REF!/2))-(Regs!E17+Regs!E18*(Data!#REF!/2)) -> #REF!
A7: Avg CF= | B7: =AVERAGE(D13:D15,D19:D21,D61:D63,D91:D93,D97:D99,D157:D159,D217:D219,D223:D225) -> #REF! | C7: =AVERAGE(F13:F15,F19:F21,F61:F63,F91:F93,F97:F99,F157:F159,F217:F219,F223:F225) -> #REF!
A8: Adj. D= | B8: =B6*B7 -> #REF!
A9: Factor= | B9: =B8/(B4-B3) -> #REF!
E11: Measured | J11: Actual
A12: Sample ID | B12: time (min) | C12: N2/Ar | D12: CF | E12: O2/Ar | F12: CF | G12: N2 D | H12: O2 D | I12: N2/Ar | J12: O2/Ar | K12: N2 | L12: O2 | M12: Avg N2 | N12: Avg O2 | O12: Sample ID
A13: =Data!#REF! -> #REF! | B13: =Data!H8 -> 0 | C13: =Data!#REF!/Data!#REF! -> #REF! | D13: =B$3/C13 -> #REF! | E13: =Data!#REF!/Data!#REF! -> #REF! | F13: =C$3/E13 -> #REF! | G13: =C13-(G$3+G$4*B13) -> #REF! | H13: =E13-(H$3+H$4*B13) -> #REF! | I13: =G13*(B$7/B$9)+B$3 -> #REF! | J13: =H13*(C$7)+C$3 -> #REF! | K13: =I13*D$3 -> #REF! | L13: =J13*D$3 -> #REF! | O13: =Data!#REF! -> #REF!
B14: =Data!H9 -> 0.13333333 | C14: =Data!#REF!/Data!#REF! -> #REF! | D14: =B$3/C14 -> #REF! | E14: =Data!#REF!/Data!#REF! -> #REF! | F14: =C$3/E14 -> #REF! | G14: =C14-(G$3+G$4*B14) -> #REF! | H14: =E14-(H$3+H$4*B14) -> #REF! | I14: =G14*(B$7/B$9)+B$3 -> #REF! | J14: =H14*(C$7)+C$3 -> #REF! | K14: =I14*D$3 -> #REF! | L14: =J14*D$3 -> #REF!
B15: =Data!H10 -> 0.3 | C15: =Data!#REF!/Data!#REF! -> #REF! | D15: =B$3/C15 -> #REF! | E15: =Data!#REF!/Data!#REF! -> #REF! | F15: =C$3/E15 -> #REF! | G15: =C15-(G$3+G$4*B15) -> #REF! | H15: =E15-(H$3+H$4*B15) -> #REF! | I15: =G15*(B$7/B$9)+B$3 -> #REF! | J15: =H15*(C$7)+C$3 -> #REF! | K15: =I15*D$3 -> #REF! | L15: =J15*D$3 -> #REF!
A16: =Data!#REF! -> #REF! | B16: =Data!H11 -> 5.0833333 | C16: =Data!#REF!/Data!#REF! -> #REF! | D16: =B$4/C16 -> #REF! | E16: =Data!#REF!/Data!#REF! -> #REF! | F16: =C$4/E16 -> #REF! | G16: =C16-(G$3+G$4*B16) -> #REF! | H16: =E16-(H$3+H$4*B16) -> #REF! | I16: =G16*(B$7/B$9)+B$3 -> #REF! | J16: =H16*(C$7)+C$3 -> #REF! | K16: =I16*D$3 -> #REF! | L16: =J16*D$3 -> #REF! | O16: =Data!#REF! -> #REF!
B17: =Data!H12 -> 5.2166667 | C17: =Data!#REF!/Data!#REF! -> #REF! | D17: =B$4/C17 -> #REF! | E17: =Data!#REF!/Data!#REF! -> #REF! | F17: =C$4/E17 -> #REF! | G17: =C17-(G$3+G$4*B17) -> #REF! | H17: =E17-(H$3+H$4*B17) -> #REF! | I17: =G17*(B$7/B$9)+B$3 -> #REF! | J17: =H17*(C$7)+C$3 -> #REF! | K17: =I17*D$3 -> #REF! | L17: =J17*D$3 -> #REF!
B18: =Data!H13 -> 5.35 | C18: =Data!#REF!/Data!#REF! -> #REF! | D18: =B$4/C18 -> #REF! | E18: =Data!#REF!/Data!#REF! -> #REF! | F18: =C$4/E18 -> #REF! | G18: =C18-(G$3+G$4*B18) -> #REF! | H18: =E18-(H$3+H$4*B18) -> #REF! | I18: =G18*(B$7/B$9)+B$3 -> #REF! | J18: =H18*(C$7)+C$3 -> #REF! | K18: =I18*D$3 -> #REF! | L18: =J18*D$3 -> #REF!
A19: =Data!#REF! -> #REF! | B19: =Data!H14 -> 9.6833333 | C19: =Data!#REF!/Data!#REF! -> #REF! | D19: =B$3/C19 -> #REF! | E19: =Data!#REF!/Data!#REF! -> #REF! | F19: =C$3/E19 -> #REF! | G19: =C19-(G$3+G$4*B19) -> #REF! | H19: =E19-(H$3+H$4*B19) -> #REF! | I19: =G19*(B$7/B$9)+B$3 -> #REF! | J19: =H19*(C$7)+C$3 -> #REF! | K19: =I19*D$3 -> #REF! | L19: =J19*D$3 -> #REF! | O19: =Data!#REF! -> #REF!
B20: =Data!H15 -> 9.8166667 | C20: =Data!#REF!/Data!#REF! -> #REF! | D20: =B$3/C20 -> #REF! | E20: =Data!#REF!/Data!#REF! -> #REF! | F20: =C$3/E20 -> #REF! | G20: =C20-(G$3+G$4*B20) -> #REF! | H20: =E20-(H$3+H$4*B20) -> #REF! | I20: =G20*(B$7/B$9)+B$3 -> #REF! | J20: =H20*(C$7)+C$3 -> #REF! | K20: =I20*D$3 -> #REF! | L20: =J20*D$3 -> #REF!
B21: =Data!H16 -> 10.033333 | C21: =Data!#REF!/Data!#REF! -> #REF! | D21: =B$3/C21 -> #REF! | E21: =Data!#REF!/Data!#REF! -> #REF! | F21: =C$3/E21 -> #REF! | G21: =C21-(G$3+G$4*B21) -> #REF! | H21: =E21-(H$3+H$4*B21) -> #REF! | I21: =G21*(B$7/B$9)+B$3 -> #REF! | J21: =H21*(C$7)+C$3 -> #REF! | K21: =I21*D$3 -> #REF! | L21: =J21*D$3 -> #REF!
A22: =Data!#REF! -> #REF! | B22: =Data!H17 -> 16.416667 | C22: =Data!#REF!/Data!#REF! -> #REF! | D22: =B$4/C22 -> #REF! | E22: =Data!#REF!/Data!#REF! -> #REF! | F22: =C$4/E22 -> #REF! | G22: =C22-(G$3+G$4*B22) -> #REF! | H22: =E22-(H$3+H$4*B22) -> #REF! | I22: =G22*(B$7/B$9)+B$3 -> #REF! | J22: =H22*(C$7)+C$3 -> #REF! | K22: =I22*D$3 -> #REF! | L22: =J22*D$3 -> #REF! | O22: =Data!#REF! -> #REF!
B23: =Data!H18 -> 16.55 | C23: =Data!#REF!/Data!#REF! -> #REF! | D23: =B$4/C23 -> #REF! | E23: =Data!#REF!/Data!#REF! -> #REF! | F23: =C$4/E23 -> #REF! | G23: =C23-(G$3+G$4*B23) -> #REF! | H23: =E23-(H$3+H$4*B23) -> #REF! | I23: =G23*(B$7/B$9)+B$3 -> #REF! | J23: =H23*(C$7)+C$3 -> #REF! | K23: =I23*D$3 -> #REF! | L23: =J23*D$3 -> #REF!
B24: =Data!H19 -> 16.683333 | C24: =Data!#REF!/Data!#REF! -> #REF! | D24: =B$4/C24 -> #REF! | E24: =Data!#REF!/Data!#REF! -> #REF! | F24: =C$4/E24 -> #REF! | G24: =C24-(G$3+G$4*B24) -> #REF! | H24: =E24-(H$3+H$4*B24) -> #REF! | I24: =G24*(B$7/B$9)+B$3 -> #REF! | J24: =H24*(C$7)+C$3 -> #REF! | K24: =I24*D$3 -> #REF! | L24: =J24*D$3 -> #REF!
A25: =Data!#REF! -> #REF! | B25: =Data!H20 -> 22.2 | C25: =Data!#REF!/Data!#REF! -> #REF! | E25: =Data!#REF!/Data!#REF! -> #REF! | G25: =C25-(G$3+G$4*B25) -> #REF! | H25: =E25-(H$3+H$4*B25) -> #REF! | I25: =G25*(B$7/B$9)+B$3 -> #REF! | J25: =H25*(C$7)+C$3 -> #REF! | K25: =I25*D$3 -> #REF! | L25: =J25*D$3 -> #REF! | M25: =AVERAGE(K25:K27) -> #REF! | N25: =AVERAGE(L25:L27) -> #REF! | O25: =Data!#REF! -> #REF!
B26: =Data!H21 -> 22.333333 | C26: =Data!#REF!/Data!#REF! -> #REF! | E26: =Data!#REF!/Data!#REF! -> #REF! | G26: =C26-(G$3+G$4*B26) -> #REF! | H26: =E26-(H$3+H$4*B26) -> #REF! | I26: =G26*(B$7/B$9)+B$3 -> #REF! | J26: =H26*(C$7)+C$3 -> #REF! | K26: =I26*D$3 -> #REF! | L26: =J26*D$3 -> #REF!
B27: =Data!H22 -> 22.466667 | C27: =Data!#REF!/Data!#REF! -> #REF! | E27: =Data!#REF!/Data!#REF! -> #REF! | G27: =C27-(G$3+G$4*B27) -> #REF! | H27: =E27-(H$3+H$4*B27) -> #REF! | I27: =G27*(B$7/B$9)+B$3 -> #REF! | J27: =H27*(C$7)+C$3 -> #REF! | K27: =I27*D$3 -> #REF! | L27: =J27*D$3 -> #REF!
A28: =Data!#REF! -> #REF! | B28: =Data!H23 -> 28.716667 | C28: =Data!#REF!/Data!#REF! -> #REF! | E28: =Data!#REF!/Data!#REF! -> #REF! | G28: =C28-(G$3+G$4*B28) -> #REF! | H28: =E28-(H$3+H$4*B28) -> #REF! | I28: =G28*(B$7/B$9)+B$3 -> #REF! | J28: =H28*(C$7)+C$3 -> #REF! | K28: =I28*D$3 -> #REF! | L28: =J28*D$3 -> #REF! | M28: =AVERAGE(K28:K29) -> #REF! | N28: =AVERAGE(L28:L30) -> #REF! | O28: =Data!#REF! -> #REF!
B29: =Data!H24 -> 28.8 | C29: =Data!#REF!/Data!#REF! -> #REF! | E29: =Data!#REF!/Data!#REF! -> #REF! | G29: =C29-(G$3+G$4*B29) -> #REF! | H29: =E29-(H$3+H$4*B29) -> #REF! | I29: =G29*(B$7/B$9)+B$3 -> #REF! | J29: =H29*(C$7)+C$3 -> #REF! | K29: =I29*D$3 -> #REF! | L29: =J29*D$3 -> #REF!
B30: =Data!H25 -> 29.016667 | C30: =Data!#REF!/Data!#REF! -> #REF! | E30: =Data!#REF!/Data!#REF! -> #REF! | G30: =C30-(G$3+G$4*B30) -> #REF! | H30: =E30-(H$3+H$4*B30) -> #REF! | I30: =G30*(B$7/B$9)+B$3 -> #REF! | J30: =H30*(C$7)+C$3 -> #REF! | K30: =I30*D$3 -> #REF! | L30: =J30*D$3 -> #REF!
A31: =Data!#REF! -> #REF! | B31: =Data!H26 -> 35.483333 | C31: =Data!#REF!/Data!#REF! -> #REF! | E31: =Data!#REF!/Data!#REF! -> #REF! | G31: =C31-(G$3+G$4*B31) -> #REF! | H31: =E31-(H$3+H$4*B31) -> #REF! | I31: =G31*(B$7/B$9)+B$3 -> #REF! | J31: =H31*(C$7)+C$3 -> #REF! | K31: =I31*D$3 -> #REF! | L31: =J31*D$3 -> #REF! | M31: =AVERAGE(K31:K33) -> #REF! | N31: =AVERAGE(L31:L33) -> #REF! | O31: =Data!#REF! -> #REF!
B32: =Data!H27 -> 35.616667 | C32: =Data!#REF!/Data!#REF! -> #REF! | E32: =Data!#REF!/Data!#REF! -> #REF! | G32: =C32-(G$3+G$4*B32) -> #REF! | H32: =E32-(H$3+H$4*B32) -> #REF! | I32: =G32*(B$7/B$9)+B$3 -> #REF! | J32: =H32*(C$7)+C$3 -> #REF! | K32: =I32*D$3 -> #REF! | L32: =J32*D$3 -> #REF!
B33: =Data!H28 -> 35.7 | C33: =Data!#REF!/Data!#REF! -> #REF! | E33: =Data!#REF!/Data!#REF! -> #REF! | G33: =C33-(G$3+G$4*B33) -> #REF! | H33: =E33-(H$3+H$4*B33) -> #REF! | I33: =G33*(B$7/B$9)+B$3 -> #REF! | J33: =H33*(C$7)+C$3 -> #REF! | K33: =I33*D$3 -> #REF! | L33: =J33*D$3 -> #REF!
A34: =Data!#REF! -> #REF! | B34: =Data!#REF! -> #REF! | C34: =Data!#REF!/Data!#REF! -> #REF! | E34: =Data!#REF!/Data!#REF! -> #REF! | G34: =C34-(G$3+G$4*B34) -> #REF! | H34: =E34-(H$3+H$4*B34) -> #REF! | I34: =G34*(B$7/B$9)+B$3 -> #REF! | J34: =H34*(C$7)+C$3 -> #REF! | K34: =I34*D$3 -> #REF! | L34: =J34*D$3 -> #REF! | M34: =AVERAGE(K34:K36) -> #REF! | N34: =AVERAGE(L34:L36) -> #REF! | O34: =Data!#REF! -> #REF!
B35: =Data!#REF! -> #REF! | C35: =Data!#REF!/Data!#REF! -> #REF! | E35: =Data!#REF!/Data!#REF! -> #REF! | G35: =C35-(G$3+G$4*B35) -> #REF! | H35: =E35-(H$3+H$4*B35) -> #REF! | I35: =G35*(B$7/B$9)+B$3 -> #REF! | J35: =H35*(C$7)+C$3 -> #REF! | K35: =I35*D$3 -> #REF! | L35: =J35*D$3 -> #REF!
B36: =Data!#REF! -> #REF! | C36: =Data!#REF!/Data!#REF! -> #REF! | E36: =Data!#REF!/Data!#REF! -> #REF! | G36: =C36-(G$3+G$4*B36) -> #REF! | H36: =E36-(H$3+H$4*B36) -> #REF! | I36: =G36*(B$7/B$9)+B$3 -> #REF! | J36: =H36*(C$7)+C$3 -> #REF! | K36: =I36*D$3 -> #REF! | L36: =J36*D$3 -> #REF!
A37: =Data!#REF! -> #REF! | B37: =Data!#REF! -> #REF! | C37: =Data!#REF!/Data!#REF! -> #REF! | E37: =Data!#REF!/Data!#REF! -> #REF! | G37: =C37-(G$3+G$4*B37) -> #REF! | H37: =E37-(H$3+H$4*B37) -> #REF! | I37: =G37*(B$7/B$9)+B$3 -> #REF! | J37: =H37*(C$7)+C$3 -> #REF! | K37: =I37*D$3 -> #REF! | L37: =J37*D$3 -> #REF! | M37: =AVERAGE(K37:K39) -> #REF! | N37: =AVERAGE(L37:L39) -> #REF! | O37: =Data!#REF! -> #REF!
B38: =Data!#REF! -> #REF! | C38: =Data!#REF!/Data!#REF! -> #REF! | E38: =Data!#REF!/Data!#REF! -> #REF! | G38: =C38-(G$3+G$4*B38) -> #REF! | H38: =E38-(H$3+H$4*B38) -> #REF! | I38: =G38*(B$7/B$9)+B$3 -> #REF! | J38: =H38*(C$7)+C$3 -> #REF! | K38: =I38*D$3 -> #REF! | L38: =J38*D$3 -> #REF!
B39: =Data!#REF! -> #REF! | C39: =Data!#REF!/Data!#REF! -> #REF! | E39: =Data!#REF!/Data!#REF! -> #REF! | G39: =C39-(G$3+G$4*B39) -> #REF! | H39: =E39-(H$3+H$4*B39) -> #REF! | I39: =G39*(B$7/B$9)+B$3 -> #REF! | J39: =H39*(C$7)+C$3 -> #REF! | K39: =I39*D$3 -> #REF! | L39: =J39*D$3 -> #REF!
A40: =Data!#REF! -> #REF! | B40: =Data!#REF! -> #REF! | C40: =Data!#REF!/Data!#REF! -> #REF! | E40: =Data!#REF!/Data!#REF! -> #REF! | G40: =C40-(G$3+G$4*B40) -> #REF! | H40: =E40-(H$3+H$4*B40) -> #REF! | I40: =G40*(B$7/B$9)+B$3 -> #REF! | J40: =H40*(C$7)+C$3 -> #REF! | K40: =I40*D$3 -> #REF! | L40: =J40*D$3 -> #REF! | M40: =AVERAGE(K40:K42) -> #REF! | N40: =AVERAGE(L40:L42) -> #REF! | O40: =Data!#REF! -> #REF!
B41: =Data!#REF! -> #REF! | C41: =Data!#REF!/Data!#REF! -> #REF! | E41: =Data!#REF!/Data!#REF! -> #REF! | G41: =C41-(G$3+G$4*B41) -> #REF! | H41: =E41-(H$3+H$4*B41) -> #REF! | I41: =G41*(B$7/B$9)+B$3 -> #REF! | J41: =H41*(C$7)+C$3 -> #REF! | K41: =I41*D$3 -> #REF! | L41: =J41*D$3 -> #REF!
B42: =Data!#REF! -> #REF! | C42: =Data!#REF!/Data!#REF! -> #REF! | E42: =Data!#REF!/Data!#REF! -> #REF! | G42: =C42-(G$3+G$4*B42) -> #REF! | H42: =E42-(H$3+H$4*B42) -> #REF! | I42: =G42*(B$7/B$9)+B$3 -> #REF! | J42: =H42*(C$7)+C$3 -> #REF! | K42: =I42*D$3 -> #REF! | L42: =J42*D$3 -> #REF!
...

Sheet 30N2
A1: 531.2 | B1: =actual N2 at 20/0
A2: =AVERAGE(Data!#REF!,Data!#REF!,Data!#REF!,Data!C11:C13,Data!C17:C19,Data!#REF!,Data!#REF!,Data!#REF!) -> #REF! | B2: =average measured N2 at 20/0
C4: x | D4: y | F4: N30 based
B5: N2*O2 | C5: SQRT | D5: N30 | E5: Excess | F5: on N2 | H5: SUMMARY OUTPUT
A7: =Data!#REF! -> #REF! | B7: =Data!#REF!*Data!#REF! -> #REF! | C7: =SQRT(B7) -> #REF! | D7: =Data!#REF! -> #REF! | E7: =D7-(C7*I$22+I$21) -> #REF! | F7: =A$1*E7/A$2 -> #REF! | H7: Regression Statistics
B8: =Data!#REF!*Data!#REF! -> #REF! | C8: =SQRT(B8) -> #REF! | D8: =Data!#REF! -> #REF! | E8: =D8-(C8*I$22+I$21) -> #REF! | F8: =A$1*E8/A$2 -> #REF! | H8: Multiple R | I8: 0.92521334
B9: =Data!#REF!*Data!#REF! -> #REF! | C9: =SQRT(B9) -> #REF! | D9: =Data!#REF! -> #REF! | E9: =D9-(C9*I$22+I$21) -> #REF! | F9: =A$1*E9/A$2 -> #REF! | H9: R Square | I9: 0.85601973
A10: =Data!#REF! -> #REF! | B10: =Data!#REF!*Data!#REF! -> #REF! | C10: =SQRT(B10) -> #REF! | D10: =Data!#REF! -> #REF! | E10: =D10-(C10*I$22+I$21) -> #REF! | F10: =A$1*E10/A$2 -> #REF! | H10: Adjusted R Square | I10: 0.85288973
B11: =Data!#REF!*Data!#REF! -> #REF! | C11: =SQRT(B11) -> #REF! | D11: =Data!#REF! -> #REF! | E11: =D11-(C11*I$22+I$21) -> #REF! | F11: =A$1*E11/A$2 -> #REF! | H11: Standard Error | I11: 2.4535244e-13
B12: =Data!#REF!*Data!#REF! -> #REF! | C12: =SQRT(B12) -> #REF! | D12: =Data!#REF! -> #REF! | E12: =D12-(C12*I$22+I$21) -> #REF! | F12: =A$1*E12/A$2 -> #REF! | H12: Observations | I12: 48
A13: =Data!#REF! -> #REF! | B13: =Data!#REF!*Data!#REF! -> #REF! | C13: =SQRT(B13) -> #REF! | D13: =Data!#REF! -> #REF! | E13: =D13-(C13*I$22+I$21) -> #REF! | F13: =A$1*E13/A$2 -> #REF!
B14: =Data!#REF!*Data!#REF! -> #REF! | C14: =SQRT(B14) -> #REF! | D14: =Data!#REF! -> #REF! | E14: =D14-(C14*I$22+I$21) -> #REF! | F14: =A$1*E14/A$2 -> #REF! | H14: ANOVA
B15: =Data!#REF!*Data!#REF! -> #REF! | C15: =SQRT(B15) -> #REF! | D15: =Data!#REF! -> #REF! | E15: =D15-(C15*I$22+I$21) -> #REF! | F15: =A$1*E15/A$2 -> #REF! | I15: df | J15: SS | K15: MS | L15: F | M15: Significance F
A16: =Data!#REF! -> #REF! | B16: =Data!#REF!*Data!#REF! -> #REF! | C16: =SQRT(B16) -> #REF! | D16: =Data!#REF! -> #REF! | E16: =D16-(C16*I$22+I$21) -> #REF! | F16: =A$1*E16/A$2 -> #REF! | H16: Regression | I16: 1 | J16: 1.6463395e-23 | K16: 1.6463395e-23 | L16: 273.48823 | M16: 5.5133839e-21
B17: =Data!#REF!*Data!#REF! -> #REF! | C17: =SQRT(B17) -> #REF! | D17: =Data!#REF! -> #REF! | E17: =D17-(C17*I$22+I$21) -> #REF! | F17: =A$1*E17/A$2 -> #REF! | H17: Residual | I17: 46 | J17: 2.7690996e-24 | K17: 6.0197818e-26
B18: =Data!#REF!*Data!#REF! -> #REF! | C18: =SQRT(B18) -> #REF! | D18: =Data!#REF! -> #REF! | E18: =D18-(C18*I$22+I$21) -> #REF! | F18: =A$1*E18/A$2 -> #REF! | H18: Total | I18: 47 | J18: 1.9232494e-23
A19: =Data!#REF! -> #REF! | B19: =Data!#REF!*Data!#REF! -> #REF! | C19: =SQRT(B19) -> #REF! | D19: =Data!#REF! -> #REF! | E19: =D19-(C19*I$22+I$21) -> #REF! | F19: =A$1*E19/A$2 -> #REF!
B20: =Data!#REF!*Data!#REF! -> #REF! | C20: =SQRT(B20) -> #REF! | D20: =Data!#REF! -> #REF! | E20: =D20-(C20*I$22+I$21) -> #REF! | F20: =A$1*E20/A$2 -> #REF! | I20: Coefficients | J20: Standard Error | K20: t Stat | L20: P-value | M20: Lower 95% | N20: Upper 95% | O20: Lower 95.0% | P20: Upper 95.0%
B21: =Data!#REF!*Data!#REF! -> #REF! | C21: =SQRT(B21) -> #REF! | D21: =Data!#REF! -> #REF! | E21: =D21-(C21*I$22+I$21) -> #REF! | F21: =A$1*E21/A$2 -> #REF! | H21: Intercept | I21: 3.7685473e-12 | J21: 3.9988768e-13 | K21: 9.4240145 | L21: 2.5937484e-12 | M21: 2.9636152e-12 | N21: 4.5734795e-12 | O21: 2.9636152e-12 | P21: 4.5734795e-12
A22: =Data!#REF! -> #REF! | B22: =Data!#REF!*Data!#REF! -> #REF! | C22: =SQRT(B22) -> #REF! | D22: =Data!#REF! -> #REF! | E22: =D22-(C22*I$22+I$21) -> #REF! | F22: =A$1*E22/A$2 -> #REF! | H22: X Variable 1 | I22: 0.00017362145 | J22: 1.0498665e-05 | K22: 16.537479 | L22: 5.5133839e-21 | M22: 0.00015248874 | N22: 0.00019475417 | O22: 0.00015248874 | P22: 0.00019475417
B23: =Data!#REF!*Data!#REF! -> #REF! | C23: =SQRT(B23) -> #REF! | D23: =Data!#REF! -> #REF! | E23: =D23-(C23*I$22+I$21) -> #REF! | F23: =A$1*E23/A$2 -> #REF!
B24: =Data!#REF!*Data!#REF! -> #REF! | C24: =SQRT(B24) -> #REF! | D24: =Data!#REF! -> #REF! | E24: =D24-(C24*I$22+I$21) -> #REF! | F24: =A$1*E24/A$2 -> #REF!
A25: =Data!A11 -> 30 | B25: =Data!C11*Data!G11 -> 1.8696253e-09 | C25: =SQRT(B25) -> 4.3239164e-05 | D25: =Data!E11 -> 5.361757e-12 | E25: =D25-(C25*I$22+I$21) -> -7.5056533e-09 | F25: =A$1*E25/A$2 -> #REF!
B26: =Data!C12*Data!G12 -> 1.8688929e-09 | C26: =SQRT(B26) -> 4.3230694e-05 | D26: =Data!E12 -> 5.362715e-12 | E26: =D26-(C26*I$22+I$21) -> -7.5041818e-09 | F26: =A$1*E26/A$2 -> #REF!
B27: =Data!C13*Data!G13 -> 1.8675736e-09 | C27: =SQRT(B27) -> 4.3215433e-05 | D27: =Data!E13 -> 5.355685e-12 | E27: =D27-(C27*I$22+I$21) -> -7.5015391e-09 | F27: =A$1*E27/A$2 -> #REF!
A28: =Data!A14 -> Hardwoods_IN_T1_1 | B28: =Data!C14*Data!G14 -> 1.6107877e-09 | C28: =SQRT(B28) -> 4.0134619e-05 | D28: =Data!E14 -> 6.348015e-12 | E28: =D28-(C28*I$22+I$21) -> -6.9656515e-09 | F28: =A$1*E28/A$2 -> #REF!
B29: =Data!C15*Data!G15 -> 1.6105371e-09 | C29: =SQRT(B29) -> 4.0131498e-05 | D29: =Data!E15 -> 6.350166e-12 | E29: =D29-(C29*I$22+I$21) -> -6.9651073e-09 | F29: =A$1*E29/A$2 -> #REF!
B30: =Data!C16*Data!G16 -> 1.6101339e-09 | C30: =SQRT(B30) -> 4.0126473e-05 | D30: =Data!E16 -> 6.352163e-12 | E30: =D30-(C30*I$22+I$21) -> -6.964233e-09 | F30: =A$1*E30/A$2 -> #REF!
A31: =Data!A17 -> Hardwoods_13_T1_1 | B31: =Data!C17*Data!G17 -> 1.3249983e-09 | C31: =SQRT(B31) -> 3.6400526e-05 | D31: =Data!E17 -> 6.275724e-12 | E31: =D31-(C31*I$22+I$21) -> -6.317405e-09 | F31: =A$1*E31/A$2 -> #REF!
B32: =Data!C18*Data!G18 -> 1.3246946e-09 | C32: =SQRT(B32) -> 3.6396355e-05 | D32: =Data!E18 -> 6.277455e-12 | E32: =D32-(C32*I$22+I$21) -> -6.316679e-09 | F32: =A$1*E32/A$2 -> #REF!
B33: =Data!C19*Data!G19 -> 1.3243541e-09 | C33: =SQRT(B33) -> 3.6391677e-05 | D33: =Data!E19 -> 6.276681e-12 | E33: =D33-(C33*I$22+I$21) -> -6.3158677e-09 | F33: =A$1*E33/A$2 -> #REF!
A34: =Data!A20 -> Hardwoods_14_T1_1 | B34: =Data!C20*Data!G20 -> 1.5509694e-09 | C34: =SQRT(B34) -> 3.9382348e-05 | D34: =Data!E20 -> 6.259296e-12 | E34: =D34-(C34*I$22+I$21) -> -6.8351298e-09 | F34: =A$1*E34/A$2 -> #REF!
B35: =Data!C21*Data!G21 -> 1.5509677e-09 | C35: =SQRT(B35) -> 3.9382327e-05 | D35: =Data!E21 -> 6.26218e-12 | E35: =D35-(C35*I$22+I$21) -> -6.8351232e-09 | F35: =A$1*E35/A$2 -> #REF!
B36: =Data!C22*Data!G22 -> 1.5509929e-09 | C36: =SQRT(B36) -> 3.9382648e-05 | D36: =Data!E22 -> 6.262415e-12 | E36: =D36-(C36*I$22+I$21) -> -6.8351786e-09 | F36: =A$1*E36/A$2 -> #REF!
A37: =Data!#REF! -> #REF! | B37: =Data!#REF!*Data!#REF! -> #REF! | C37: =SQRT(B37) -> #REF! | D37: =Data!#REF! -> #REF! | E37: =D37-(C37*I$22+I$21) -> #REF! | F37: =A$1*E37/A$2 -> #REF!
B38: =Data!#REF!*Data!#REF! -> #REF! | C38: =SQRT(B38) -> #REF! | D38: =Data!#REF! -> #REF! | E38: =D38-(C38*I$22+I$21) -> #REF! | F38: =A$1*E38/A$2 -> #REF!
B39: =Data!#REF!*Data!#REF! -> #REF! | C39: =SQRT(B39) -> #REF! | D39: =Data!#REF! -> #REF! | E39: =D39-(C39*I$22+I$21) -> #REF! | F39: =A$1*E39/A$2 -> #REF!
A40: =Data!#REF! -> #REF! | B40: =Data!#REF!*Data!#REF! -> #REF! | C40: =SQRT(B40) -> #REF! | D40: =Data!#REF! -> #REF! | E40: =D40-(C40*I$22+I$21) -> #REF! | F40: =A$1*E40/A$2 -> #REF!
B41: =Data!#REF!*Data!#REF! -> #REF! | C41: =SQRT(B41) -> #REF! | D41: =Data!#REF! -> #REF! | E41: =D41-(C41*I$22+I$21) -> #REF! | F41: =A$1*E41/A$2 -> #REF!
B42: =Data!#REF!*Data!#REF! -> #REF! | C42: =SQRT(B42) -> #REF! | D42: =Data!#REF! -> #REF! | E42: =D42-(C42*I$22+I$21) -> #REF! | F42: =A$1*E42/A$2 -> #REF!
...

Sheet 29N2
A1: ='30N2'!A1 -> 531.2 | B1: =actual N2 at 20/0
A2: ='30N2'!A2 -> #REF! | B2: =average measured N2 at 20/0
B4: x | C4: y | E4: N29 based
B5: N28 | C5: N29 | D5: Excess | E5: on N2 | G5: SUMMARY OUTPUT
A7: ='30N2'!A7 -> #REF! | B7: =Data!#REF! -> #REF! | C7: =Data!#REF! -> #REF! | D7: =C7-(B7*H$22+H$21) -> #REF! | E7: =A$1*D7/A$2 -> #REF! | G7: Regression Statistics
B8: =Data!#REF! -> #REF! | C8: =Data!#REF! -> #REF! | D8: =C8-(B8*H$22+H$21) -> #REF! | E8: =A$1*D8/A$2 -> #REF! | G8: Multiple R | H8: 0.9998193
B9: =Data!#REF! -> #REF! | C9: =Data!#REF! -> #REF! | D9: =C9-(B9*H$22+H$21) -> #REF! | E9: =A$1*D9/A$2 -> #REF! | G9: R Square | H9: 0.99963863
A10: ='30N2'!A10 -> #REF! | B10: =Data!#REF! -> #REF! | C10: =Data!#REF! -> #REF! | D10: =C10-(B10*H$22+H$21) -> #REF! | E10: =A$1*D10/A$2 -> #REF! | G10: Adjusted R Square | H10: 0.99963077
B11: =Data!#REF! -> #REF! | C11: =Data!#REF! -> #REF! | D11: =C11-(B11*H$22+H$21) -> #REF! | E11: =A$1*D11/A$2 -> #REF! | G11: Standard Error | H11: 6.367191e-13
B12: =Data!#REF! -> #REF! | C12: =Data!#REF! -> #REF! | D12: =C12-(B12*H$22+H$21) -> #REF! | E12: =A$1*D12/A$2 -> #REF! | G12: Observations | H12: 48
A13: ='30N2'!A13 -> #REF! | B13: =Data!#REF! -> #REF! | C13: =Data!#REF! -> #REF! | D13: =C13-(B13*H$22+H$21) -> #REF! | E13: =A$1*D13/A$2 -> #REF!
B14: =Data!#REF! -> #REF! | C14: =Data!#REF! -> #REF! | D14: =C14-(B14*H$22+H$21) -> #REF! | E14: =A$1*D14/A$2 -> #REF! | G14: ANOVA
B15: =Data!#REF! -> #REF! | C15: =Data!#REF! -> #REF! | D15: =C15-(B15*H$22+H$21) -> #REF! | E15: =A$1*D15/A$2 -> #REF! | H15: df | I15: SS | J15: MS | K15: F | L15: Significance F
A16: ='30N2'!A16 -> #REF! | B16: =Data!#REF! -> #REF! | C16: =Data!#REF! -> #REF! | D16: =C16-(B16*H$22+H$21) -> #REF! | E16: =A$1*D16/A$2 -> #REF! | G16: Regression | H16: 1 | I16: 5.1586937e-20 | J16: 5.1586937e-20 | K16: 127245.96 | L16: 7.9668052e-81
B17: =Data!#REF! -> #REF! | C17: =Data!#REF! -> #REF! | D17: =C17-(B17*H$22+H$21) -> #REF! | E17: =A$1*D17/A$2 -> #REF! | G17: Residual | H17: 46 | I17: 1.8648916e-23 | J17: 4.0541121e-25
B18: =Data!#REF! -> #REF! | C18: =Data!#REF! -> #REF! | D18: =C18-(B18*H$22+H$21) -> #REF! | E18: =A$1*D18/A$2 -> #REF! | G18: Total | H18: 47 | I18: 5.1605586e-20
A19: ='30N2'!A19 -> #REF! | B19: =Data!#REF! -> #REF! | C19: =Data!#REF! -> #REF! | D19: =C19-(B19*H$22+H$21) -> #REF! | E19: =A$1*D19/A$2 -> #REF!
B20: =Data!#REF! -> #REF! | C20: =Data!#REF! -> #REF! | D20: =C20-(B20*H$22+H$21) -> #REF! | E20: =A$1*D20/A$2 -> #REF! | H20: Coefficients | I20: Standard Error | J20: t Stat | K20: P-value | L20: Lower 95% | M20: Upper 95% | N20: Lower 95.0% | O20: Upper 95.0%
B21: =Data!#REF! -> #REF! | C21: =Data!#REF! -> #REF! | D21: =C21-(B21*H$22+H$21) -> #REF! | E21: =A$1*D21/A$2 -> #REF! | G21: Intercept | H21: 2.7348578e-12 | I21: 1.0787438e-12 | J21: 2.5352245 | K21: 0.014701501 | L21: 5.6345907e-13 | M21: 4.9062565e-12 | N21: 5.6345907e-13 | O21: 4.9062565e-12
A22: ='30N2'!A22 -> #REF! | B22: =Data!#REF! -> #REF! | C22: =Data!#REF! -> #REF! | D22: =C22-(B22*H$22+H$21) -> #REF! | E22: =A$1*D22/A$2 -> #REF! | G22: X Variable 1 | H22: 0.0069954418 | I22: 1.9610703e-05 | J22: 356.71551 | K22: 7.9668052e-81 | L22: 0.0069559675 | M22: 0.0070349161 | N22: 0.0069559675 | O22: 0.0070349161
B23: =Data!#REF! -> #REF! | C23: =Data!#REF! -> #REF! | D23: =C23-(B23*H$22+H$21) -> #REF! | E23: =A$1*D23/A$2 -> #REF!
B24: =Data!#REF! -> #REF! | C24: =Data!#REF! -> #REF! | D24: =C24-(B24*H$22+H$21) -> #REF! | E24: =A$1*D24/A$2 -> #REF!
A25: ='30N2'!A25 -> 30 | B25: =Data!C11 -> 1.464004e-10 | C25: =Data!D11 -> 6.847302e-11 | D25: =C25-(B25*H$22+H$21) -> 6.4714027e-11 | E25: =A$1*D25/A$2 -> #REF!
B26: =Data!C12 -> 1.463889e-10 | C26: =Data!D12 -> 6.846379e-11 | D26: =C26-(B26*H$22+H$21) -> 6.4704877e-11 | E26: =A$1*D26/A$2 -> #REF!
B27: =Data!C13 -> 1.462323e-10 | C27: =Data!D13 -> 6.839896e-11 | D27: =C27-(B27*H$22+H$21) -> 6.4641143e-11 | E27: =A$1*D27/A$2 -> #REF!
A28: ='30N2'!A28 -> Hardwoods_IN_T1_1 | B28: =Data!C14 -> 1.703647e-10 | C28: =Data!D14 -> 6.002009e-11 | D28: =C28-(B28*H$22+H$21) -> 5.6093456e-11 | E28: =A$1*D28/A$2 -> #REF!
B29: =Data!C15 -> 1.703934e-10 | C29: =Data!D15 -> 6.002097e-11 | D29: =C29-(B29*H$22+H$21) -> 5.6094135e-11 | E29: =A$1*D29/A$2 -> #REF!
B30: =Data!C16 -> 1.704076e-10 | C30: =Data!D16 -> 6.001982e-11 | D30: =C30-(B30*H$22+H$21) -> 5.6092886e-11 | E30: =A$1*D30/A$2 -> #REF!
A31: ='30N2'!A31 -> Hardwoods_13_T1_1 | B31: =Data!C17 -> 1.682895e-10 | C31: =Data!D17 -> 4.941083e-11 | D31: =C31-(B31*H$22+H$21) -> 4.5498713e-11 | E31: =A$1*D31/A$2 -> #REF!
B32: =Data!C18 -> 1.683322e-10 | C32: =Data!D18 -> 4.940059e-11 | D32: =C32-(B32*H$22+H$21) -> 4.5488174e-11 | E32: =A$1*D32/A$2 -> #REF!
B33: =Data!C19 -> 1.683272e-10 | C33: =Data!D19 -> 4.938328e-11 | D33: =C33-(B33*H$22+H$21) -> 4.5470899e-11 | E33: =A$1*D33/A$2 -> #REF!
A34: ='30N2'!A34 -> Hardwoods_14_T1_1 | B34: =Data!C20 -> 1.678446e-10 | C34: =Data!D20 -> 5.783908e-11 | D34: =C34-(B34*H$22+H$21) -> 5.3930075e-11 | E34: =A$1*D34/A$2 -> #REF!
B35: =Data!C21 -> 1.678652e-10 | C35: =Data!D21 -> 5.785856e-11 | D35: =C35-(B35*H$22+H$21) -> 5.3949411e-11 | E35: =A$1*D35/A$2 -> #REF!
B36: =Data!C22 -> 1.678641e-10 | C36: =Data!D22 -> 5.786206e-11 | D36: =C36-(B36*H$22+H$21) -> 5.3952919e-11 | E36: =A$1*D36/A$2 -> #REF!
A37: ='30N2'!A37 -> #REF! | B37: =Data!#REF! -> #REF! | C37: =Data!#REF! -> #REF! | D37: =C37-(B37*H$22+H$21) -> #REF! | E37: =A$1*D37/A$2 -> #REF!
B38: =Data!#REF! -> #REF! | C38: =Data!#REF! -> #REF! | D38: =C38-(B38*H$22+H$21) -> #REF! | E38: =A$1*D38/A$2 -> #REF!
B39: =Data!#REF! -> #REF! | C39: =Data!#REF! -> #REF! | D39: =C39-(B39*H$22+H$21) -> #REF! | E39: =A$1*D39/A$2 -> #REF!
A40: ='30N2'!A40 -> #REF! | B40: =Data!#REF! -> #REF! | C40: =Data!#REF! -> #REF! | D40: =C40-(B40*H$22+H$21) -> #REF! | E40: =A$1*D40/A$2 -> #REF!
B41: =Data!#REF! -> #REF! | C41: =Data!#REF! -> #REF! | D41: =C41-(B41*H$22+H$21) -> #REF! | E41: =A$1*D41/A$2 -> #REF!
B42: =Data!#REF! -> #REF! | C42: =Data!#REF! -> #REF! | D42: =C42-(B42*H$22+H$21) -> #REF! | E42: =A$1*D42/A$2 -> #REF!
...
