Workbook

Sheet Data
A1: 052121-Lake Superior-Cores+Respirations-May2021
A6: Sample | B6: Time | C6: N2 | D6: O2 | E6: Ar | F6: N2_Ar | G6: O2_Ar | H6: Time
A8: 20 | B8: 0.46233796 | C8: 1.799815e-10 | D8: 8.624249e-11 | E8: 6.763407e-12 | F8: 26.61107 | G8: 12.75134 | H8: =M8-M$8 -> 0 | I8: 0.46233796 | J8: 10 | K8: 16 | L8: 43 | M8: =J8*60+K8+L8/60 -> 616.71667
A9: 20 | B9: 0.46243056 | C9: 1.799493e-10 | D9: 8.622027e-11 | E9: 6.762699e-12 | F9: 26.6091 | G9: 12.74939 | H9: =M9-M$8 -> 0.13333333 | I9: 0.46243056 | J9: 10 | K9: 16 | L9: 51 | M9: =J9*60+K9+L9/60 -> 616.85
A10: 20 | B10: 0.46253472 | C10: 1.799072e-10 | D10: 8.619193e-11 | E10: 6.760184e-12 | F10: 26.61277 | G10: 12.74994 | H10: =M10-M$8 -> 0.3 | I10: 0.46253472 | J10: 10 | K10: 17 | L10: 1 | M10: =J10*60+K10+L10/60 -> 617.01667
A11: 30 | B11: 0.46653935 | C11: 1.55852e-10 | D11: 7.299936e-11 | E11: 5.707334e-12 | F11: 27.30733 | G11: 12.79045 | H11: =M11-M$8 -> 5.0833333 | I11: 0.46653935 | J11: 10 | K11: 21 | L11: 48 | M11: =J11*60+K11+L11/60 -> 621.8
A12: 30 | B12: 0.46664352 | C12: 1.558354e-10 | D12: 7.298733e-11 | E12: 5.705618e-12 | F12: 27.31262 | G12: 12.79219 | H12: =M12-M$8 -> 5.2166667 | I12: 0.46664352 | J12: 10 | K12: 21 | L12: 56 | M12: =J12*60+K12+L12/60 -> 621.93333
A13: 30 | B13: 0.46677083 | C13: 1.557933e-10 | D13: 7.295643e-11 | E13: 5.70235e-12 | F13: 27.32089 | G13: 12.7941 | H13: =M13-M$8 -> 5.35 | I13: 0.46677083 | J13: 10 | K13: 22 | L13: 4 | M13: =J13*60+K13+L13/60 -> 622.06667
A14: Openwater_IN_T1_1 | B14: 0.46967593 | C14: 1.772586e-10 | D14: 7.645243e-11 | E14: 6.610784e-12 | F14: 26.81355 | G14: 11.56481 | H14: =M14-M$8 -> 9.6833333 | I14: 0.46967593 | J14: 10 | K14: 26 | L14: 24 | M14: =J14*60+K14+L14/60 -> 626.4
A15: Openwater_IN_T1_2 | B15: 0.46969907 | C15: 1.77281e-10 | D15: 7.645484e-11 | E15: 6.61151e-12 | F15: 26.814 | G15: 11.5639 | H15: =M15-M$8 -> 9.8166667 | I15: 0.46969907 | J15: 10 | K15: 26 | L15: 32 | M15: =J15*60+K15+L15/60 -> 626.53333
A16: Openwater_IN_T1_3 | B16: 0.46976852 | C16: 1.7734e-10 | D16: 7.645477e-11 | E16: 6.613965e-12 | F16: 26.81296 | G16: 11.5596 | H16: =M16-M$8 -> 10.033333 | I16: 0.46976852 | J16: 10 | K16: 26 | L16: 45 | M16: =J16*60+K16+L16/60 -> 626.75
A17: Openwater_1_T1_1 | B17: 0.47162037 | C17: 1.781335e-10 | D17: 7.037435e-11 | E17: 6.638592e-12 | F17: 26.83303 | G17: 10.6008 | H17: =M17-M$8 -> 16.416667 | I17: 0.47162037 | J17: 10 | K17: 33 | L17: 8 | M17: =J17*60+K17+L17/60 -> 633.13333
A18: Openwater_1_T1_2 | B18: 0.47168981 | C18: 1.781614e-10 | D18: 7.035529e-11 | E18: 6.638157e-12 | F18: 26.83899 | G18: 10.59862 | H18: =M18-M$8 -> 16.55 | I18: 0.47168981 | J18: 10 | K18: 33 | L18: 16 | M18: =J18*60+K18+L18/60 -> 633.26667
A19: Openwater_1_T1_3 | B19: 0.47184028 | C19: 1.781898e-10 | D19: 7.028046e-11 | E19: 6.640424e-12 | F19: 26.8341 | G19: 10.58373 | H19: =M19-M$8 -> 16.683333 | I19: 0.47184028 | J19: 10 | K19: 33 | L19: 24 | M19: =J19*60+K19+L19/60 -> 633.4
A20: Openwater_2_T1_1 | B20: 0.47496528 | C20: 1.789278e-10 | D20: 7.041765e-11 | E20: 6.651651e-12 | F20: 26.89976 | G20: 10.58649 | H20: =M20-M$8 -> 22.2 | I20: 0.47496528 | J20: 10 | K20: 38 | L20: 55 | M20: =J20*60+K20+L20/60 -> 638.91667
A21: Openwater_2_T1_2 | B21: 0.47513889 | C21: 1.78887e-10 | D21: 7.041652e-11 | E21: 6.649463e-12 | F21: 26.90248 | G21: 10.58981 | H21: =M21-M$8 -> 22.333333 | I21: 0.47513889 | J21: 10 | K21: 39 | L21: 3 | M21: =J21*60+K21+L21/60 -> 639.05
A22: Openwater_2_T1_3 | B22: 0.47533565 | C22: 1.7881e-10 | D22: 7.039201e-11 | E22: 6.648812e-12 | F22: 26.89352 | G22: 10.58716 | H22: =M22-M$8 -> 22.466667 | I22: 0.47533565 | J22: 10 | K22: 39 | L22: 11 | M22: =J22*60+K22+L22/60 -> 639.18333
A23: 20 | B23: 0.47762731 | C23: 1.774373e-10 | D23: 8.39613e-11 | E23: 6.64823e-12 | F23: 26.68941 | G23: 12.62912 | H23: =M23-M$8 -> 28.716667 | I23: 0.47762731 | J23: 10 | K23: 45 | L23: 26 | M23: =J23*60+K23+L23/60 -> 645.43333
A24: 20 | B24: 0.47770833 | C24: 1.773901e-10 | D24: 8.398926e-11 | E24: 6.645324e-12 | F24: 26.69397 | G24: 12.63885 | H24: =M24-M$8 -> 28.8 | I24: 0.47770833 | J24: 10 | K24: 45 | L24: 31 | M24: =J24*60+K24+L24/60 -> 645.51667
A25: 20 | B25: 0.47782407 | C25: 1.773144e-10 | D25: 8.400151e-11 | E25: 6.644619e-12 | F25: 26.68541 | G25: 12.64204 | H25: =M25-M$8 -> 29.016667 | I25: 0.47782407 | J25: 10 | K25: 45 | L25: 44 | M25: =J25*60+K25+L25/60 -> 645.73333
A26: 30 | B26: 0.48113426 | C26: 1.545517e-10 | D26: 7.220345e-11 | E26: 5.654792e-12 | F26: 27.33111 | G26: 12.76854 | H26: =M26-M$8 -> 35.483333 | I26: 0.48113426 | J26: 10 | K26: 52 | L26: 12 | M26: =J26*60+K26+L26/60 -> 652.2
A27: 30 | B27: 0.48121528 | C27: 1.545312e-10 | D27: 7.219427e-11 | E27: 5.655104e-12 | F27: 27.32597 | G27: 12.76621 | H27: =M27-M$8 -> 35.616667 | I27: 0.48121528 | J27: 10 | K27: 52 | L27: 20 | M27: =J27*60+K27+L27/60 -> 652.33333
A28: 30 | B28: 0.4812963 | C28: 1.545475e-10 | D28: 7.219674e-11 | E28: 5.655472e-12 | F28: 27.32707 | G28: 12.76582 | H28: =M28-M$8 -> 35.7 | I28: 0.4812963 | J28: 10 | K28: 52 | L28: 25 | M28: =J28*60+K28+L28/60 -> 652.41667
A29: Openwater_3_T1_1 | B29: 0.48649306 | C29: 1.747079e-10 | D29: 6.95979e-11 | E29: 6.530102e-12 | F29: 26.75424 | G29: 10.65801 | H29: =M29-M$8 -> 41.183333 | I29: 0.48649306 | J29: 10 | K29: 57 | L29: 54 | M29: =J29*60+K29+L29/60 -> 657.9
A30: Openwater_3_T1_2 | B30: 0.4865625 | C30: 1.746871e-10 | D30: 6.958327e-11 | E30: 6.530384e-12 | F30: 26.7499 | G30: 10.65531 | H30: =M30-M$8 -> 41.316667 | I30: 0.4865625 | J30: 10 | K30: 58 | L30: 2 | M30: =J30*60+K30+L30/60 -> 658.03333
A31: Openwater_3_T1_3 | B31: 0.48658565 | C31: 1.746812e-10 | D31: 6.957972e-11 | E31: 6.530927e-12 | F31: 26.74677 | G31: 10.65388 | H31: =M31-M$8 -> 41.533333 | I31: 0.48658565 | J31: 10 | K31: 58 | L31: 15 | M31: =J31*60+K31+L31/60 -> 658.25
A32: Openwater_4_T1_1 | B32: 0.48915509 | C32: 1.765403e-10 | D32: 6.103694e-11 | E32: 6.606131e-12 | F32: 26.7237 | G32: 9.239438 | H32: =M32-M$8 -> 43.966667 | I32: 0.48915509 | J32: 11 | K32: 0 | L32: 41 | M32: =J32*60+K32+L32/60 -> 660.68333
A33: Openwater_4_T1_2 | B33: 0.48940972 | C33: 1.765737e-10 | D33: 6.103272e-11 | E33: 6.60907e-12 | F33: 26.71687 | G33: 9.234691 | H33: =M33-M$8 -> 44.05 | I33: 0.48940972 | J33: 11 | K33: 0 | L33: 46 | M33: =J33*60+K33+L33/60 -> 660.76667
A34: Openwater_4_T1_3 | B34: 0.48947917 | C34: 1.76558e-10 | D34: 6.100405e-11 | E34: 6.606303e-12 | F34: 26.72569 | G34: 9.234219 | H34: =M34-M$8 -> 44.183333 | I34: 0.48947917 | J34: 11 | K34: 0 | L34: 54 | M34: =J34*60+K34+L34/60 -> 660.9
A35: SAVa_IN_T1_1 | B35: 0.4921412 | C35: 1.906481e-10 | D35: 6.167105e-11 | E35: 6.853437e-12 | F35: 27.81789 | G35: 8.998558 | H35: =M35-M$8 -> 47.133333 | I35: 0.4921412 | J35: 11 | K35: 3 | L35: 51 | M35: =J35*60+K35+L35/60 -> 663.85
A36: SAVa_IN_T1_2 | B36: 0.49230324 | C36: 1.907207e-10 | D36: 6.171551e-11 | E36: 6.857506e-12 | F36: 27.81196 | G36: 8.999701 | H36: =M36-M$8 -> 47.266667 | I36: 0.49230324 | J36: 11 | K36: 3 | L36: 59 | M36: =J36*60+K36+L36/60 -> 663.98333
A37: SAVa_IN_T1_3 | B37: 0.49247685 | C37: 1.904206e-10 | D37: 6.160282e-11 | E37: 6.848078e-12 | F37: 27.80643 | G37: 8.995637 | H37: =M37-M$8 -> 47.35 | I37: 0.49247685 | J37: 11 | K37: 4 | L37: 4 | M37: =J37*60+K37+L37/60 -> 664.06667
A38: 20 | B38: 0.49517361 | C38: 1.751026e-10 | D38: 8.229256e-11 | E38: 6.558675e-12 | F38: 26.69787 | G38: 12.54713 | H38: =M38-M$8 -> 52.066667 | I38: 0.49517361 | J38: 11 | K38: 8 | L38: 47 | M38: =J38*60+K38+L38/60 -> 668.78333
A39: 20 | B39: 0.49523148 | C39: 1.750518e-10 | D39: 8.231842e-11 | E39: 6.557642e-12 | F39: 26.69432 | G39: 12.55305 | H39: =M39-M$8 -> 52.15 | I39: 0.49523148 | J39: 11 | K39: 8 | L39: 52 | M39: =J39*60+K39+L39/60 -> 668.86667
A40: 20 | B40: 0.49527778 | C40: 1.75007e-10 | D40: 8.233762e-11 | E40: 6.556164e-12 | F40: 26.6935 | G40: 12.55881 | H40: =M40-M$8 -> 52.2 | I40: 0.49527778 | J40: 11 | K40: 8 | L40: 55 | M40: =J40*60+K40+L40/60 -> 668.91667
A41: 30 | B41: 0.49792824 | C41: 1.526047e-10 | D41: 7.096176e-11 | E41: 5.582023e-12 | F41: 27.3386 | G41: 12.71255 | H41: =M41-M$8 -> 56.4 | I41: 0.49792824 | J41: 11 | K41: 13 | L41: 7 | M41: =J41*60+K41+L41/60 -> 673.11667
A42: 30 | B42: 0.49804398 | C42: 1.524989e-10 | D42: 7.092865e-11 | E42: 5.577897e-12 | F42: 27.33986 | G42: 12.71602 | H42: =M42-M$8 -> 56.483333 | I42: 0.49804398 | J42: 11 | K42: 13 | L42: 12 | M42: =J42*60+K42+L42/60 -> 673.2
A43: 30 | B43: 0.49815972 | C43: 1.523994e-10 | D43: 7.088772e-11 | E43: 5.575984e-12 | F43: 27.33139 | G43: 12.71304 | H43: =M43-M$8 -> 56.566667 | I43: 0.49815972 | J43: 11 | K43: 13 | L43: 17 | M43: =J43*60+K43+L43/60 -> 673.28333

Sheet Regs
A1: 20/0 N2 | D1: SUMMARY OUTPUT
A3: N2/Ar | B3: time(min) | D3: Regression Statistics
A4: =Data!F8 -> 26.61107 | B4: =Data!H8 -> 0 | D4: Multiple R | E4: 0.91756831
A5: =Data!F9 -> 26.6091 | B5: =Data!H9 -> 0.13333333 | D5: R Square | E5: 0.84193161
A6: =Data!F10 -> 26.61277 | B6: =Data!H10 -> 0.3 | D6: Adjusted R Square | E6: 0.81935041
A7: =Data!F23 -> 26.68941 | B7: =Data!H23 -> 28.716667 | D7: Standard Error | E7: 0.017372069
A8: =Data!F24 -> 26.69397 | B8: =Data!H24 -> 28.8 | D8: Observations | E8: 9
A9: =Data!F25 -> 26.68541 | B9: =Data!H25 -> 29.016667
A10: =Data!F38 -> 26.69787 | B10: =Data!H38 -> 52.066667 | D10: ANOVA
A11: =Data!F39 -> 26.69432 | B11: =Data!H39 -> 52.15 | E11: df | F11: SS | G11: MS | H11: F | I11: Significance F
A12: =Data!F40 -> 26.6935 | B12: =Data!H40 -> 52.2 | D12: Regression | E12: 1 | F12: 0.011252082 | G12: 0.011252082 | H12: 37.284628 | I12: 0.00048813271
A13: =Data!#REF! -> #REF! | B13: =Data!#REF! -> #REF! | D13: Residual | E13: 7 | F13: 0.0021125214 | G13: 0.00030178877
A14: =Data!#REF! -> #REF! | B14: =Data!#REF! -> #REF! | D14: Total | E14: 8 | F14: 0.013364603
A15: =Data!#REF! -> #REF! | B15: =Data!#REF! -> #REF!
A16: =Data!#REF! -> #REF! | B16: =Data!#REF! -> #REF! | E16: Coefficients | F16: Standard Error | G16: t Stat | H16: P-value | I16: Lower 95% | J16: Upper 95% | K16: Lower 95.0% | L16: Upper 95.0%
A17: =Data!#REF! -> #REF! | B17: =Data!#REF! -> #REF! | D17: Intercept | E17: 26.620304 | F17: 0.0093680234 | G17: 2841.6137 | H17: 1.7653009e-22 | I17: 26.598152 | J17: 26.642456 | K17: 26.598152 | L17: 26.642456
A18: =Data!#REF! -> #REF! | B18: =Data!#REF! -> #REF! | D18: X Variable 1 | E18: 0.001662752 | F18: 0.00027230936 | G18: 6.106114 | H18: 0.00048813271 | I18: 0.0010188427 | J18: 0.0023066613 | K18: 0.0010188427 | L18: 0.0023066613
A19: =Data!#REF! -> #REF! | B19: =Data!#REF! -> #REF!
A20: =Data!#REF! -> #REF! | B20: =Data!#REF! -> #REF!
A21: =Data!#REF! -> #REF! | B21: =Data!#REF! -> #REF!
A22: =Data!#REF! -> #REF! | B22: =Data!#REF! -> #REF!
A23: =Data!#REF! -> #REF! | B23: =Data!#REF! -> #REF!
A24: =Data!#REF! -> #REF! | B24: =Data!#REF! -> #REF!
A28: =Data!C235/Data!F235 -> #DIV/0! | B28: =Data!H235 -> 0
A29: =Data!C236/Data!F236 -> #DIV/0! | B29: =Data!H236 -> 0
A30: =Data!C237/Data!F237 -> #DIV/0! | B30: =Data!H237 -> 0
A31: =Data!C361/Data!F361 -> #DIV/0! | B31: =Data!H361 -> 0
A32: =Data!C362/Data!F362 -> #DIV/0! | B32: =Data!H362 -> 0
A33: =Data!C363/Data!F363 -> #DIV/0! | B33: =Data!H363 -> 0
A34: =Data!C427/Data!F427 -> #DIV/0! | B34: =Data!H427 -> 0
A35: =Data!C428/Data!F428 -> #DIV/0! | B35: =Data!H428 -> 0
A36: =Data!C429/Data!F429 -> #DIV/0! | B36: =Data!H429 -> 0
A37: =Data!C433/Data!F433 -> #DIV/0! | B37: =Data!H433 -> 0
A38: =Data!C434/Data!F434 -> #DIV/0! | B38: =Data!H434 -> 0
A39: =Data!C435/Data!F435 -> #DIV/0! | B39: =Data!H435 -> 0
A41: 30/0 N2 | D41: SUMMARY OUTPUT
A43: N2/Ar | B43: time(min) | D43: Regression Statistics
A44: 27.30733 | B44: =Data!H11 -> 5.0833333 | D44: Multiple R | E44: 0.91835525
A45: 27.31262 | B45: =Data!H12 -> 5.2166667 | D45: R Square | E45: 0.84337637
A46: 27.32089 | B46: =Data!H13 -> 5.35 | D46: Adjusted R Square | E46: 0.82100157
...

Sheet 28N2-O2
C1: Actual | G1: N2(20/0) | H1: O2(20/0)
B2: N2/Ar | C2: O2/Ar | D2: Ar | F2: r2 | G2: =Regs!E5 -> 0.84193161 | H2: =Regs!E85 -> 0.002298157
A3: 20/0 | B3: 38.187 | C3: 20.393 | D3: 13.9 | F3: intercept | G3: =Regs!E17 -> 26.620304 | H3: =Regs!E97 -> 24.408931
A4: 30/0 | B4: 38.861 | C4: 20.38 | D4: 11.6 | F4: slope | G4: =Regs!E18 -> 0.001662752 | H4: =Regs!E98 -> -1.8582266e-05
A6: D= | B6: =(Regs!E57+Regs!E58*(Data!H43/2))-(Regs!E17+Regs!E18*(Data!H43/2)) -> 0.65689064
A7: Avg CF= | B7: =AVERAGE(D13:D15,D28:D30,D43:D45) -> 1.4320906 | C7: =AVERAGE(F13:F15,F19:F21,#REF!,#REF!,#REF!,#REF!,#REF!,#REF!) -> #REF!
A8: Adj. D= | B8: =B6*B7 -> 0.94072688
A9: Factor= | B9: =B8/(B4-B3) -> 1.3957372
E11: Measured | J11: Actual
A12: Sample ID | B12: time (min) | C12: N2/Ar | D12: CF | E12: O2/Ar | F12: CF | G12: N2 D | H12: O2 D | I12: N2/Ar | J12: O2/Ar | K12: N2 | L12: O2 | M12: Avg N2 | N12: Avg O2 | O12: Sample ID
A13: =Data!A8 -> 20 | B13: =Data!H8 -> 0 | C13: 26.61107 | D13: =B$3/C13 -> 1.4350043 | E13: =Data!G8/Data!F8 -> 0.47917427 | F13: =C$3/E13 -> 42.558629 | G13: =C13-(G$3+G$4*B13) -> -0.0092337641 | H13: =E13-(H$3+H$4*B13) -> -23.929757 | I13: =G13*(B$7/B$9)+B$3 -> 38.177526 | J13: =H13*(C$7)+C$3 -> #REF! | K13: =I13*D$3 -> 530.66761 | L13: =J13*D$3 -> #REF! | O13: =Data!A8 -> 20
B14: =Data!H9 -> 0.13333333 | C14: 26.6091 | D14: =B$3/C14 -> 1.4351105 | E14: =Data!G9/Data!F9 -> 0.47913646 | F14: =C$3/E14 -> 42.561987 | G14: =C14-(G$3+G$4*B14) -> -0.011425464 | H14: =E14-(H$3+H$4*B14) -> -23.929792 | I14: =G14*(B$7/B$9)+B$3 -> 38.175277 | J14: =H14*(C$7)+C$3 -> #REF! | K14: =I14*D$3 -> 530.63635 | L14: =J14*D$3 -> #REF!
B15: =Data!H10 -> 0.3 | C15: 26.61277 | D15: =B$3/C15 -> 1.4349126 | E15: =Data!G10/Data!F10 -> 0.47909105 | F15: =C$3/E15 -> 42.566021 | G15: =C15-(G$3+G$4*B15) -> -0.0080325897 | H15: =E15-(H$3+H$4*B15) -> -23.929834 | I15: =G15*(B$7/B$9)+B$3 -> 38.178758 | J15: =H15*(C$7)+C$3 -> #REF! | K15: =I15*D$3 -> 530.68474 | L15: =J15*D$3 -> #REF!
A16: =Data!A11 -> 30 | B16: =Data!H11 -> 5.0833333 | C16: 27.30733 | D16: =B$4/C16 -> 1.4230978 | E16: =Data!G11/Data!F11 -> 0.46838889 | F16: =C$4/E16 -> 43.510853 | G16: =C16-(G$3+G$4*B16) -> 0.67857391 | H16: =E16-(H$3+H$4*B16) -> -23.940448 | I16: =G16*(B$7/B$9)+B$3 -> 38.883248 | J16: =H16*(C$7)+C$3 -> #REF! | K16: =I16*D$3 -> 540.47715 | L16: =J16*D$3 -> #REF! | O16: =Data!A11 -> 30
B17: =Data!H12 -> 5.2166667 | C17: 27.31262 | D17: =B$4/C17 -> 1.4228221 | E17: =Data!G12/Data!F12 -> 0.46836188 | F17: =C$4/E17 -> 43.513362 | G17: =C17-(G$3+G$4*B17) -> 0.68364221 | H17: =E17-(H$3+H$4*B17) -> -23.940472 | I17: =G17*(B$7/B$9)+B$3 -> 38.888448 | J17: =H17*(C$7)+C$3 -> #REF! | K17: =I17*D$3 -> 540.54943 | L17: =J17*D$3 -> #REF!
B18: =Data!H13 -> 5.35 | C18: 27.32089 | D18: =B$4/C18 -> 1.4223914 | E18: =Data!G13/Data!F13 -> 0.46829002 | F18: =C$4/E18 -> 43.52004 | G18: =C18-(G$3+G$4*B18) -> 0.69169051 | H18: =E18-(H$3+H$4*B18) -> -23.940542 | I18: =G18*(B$7/B$9)+B$3 -> 38.896706 | J18: =H18*(C$7)+C$3 -> #REF! | K18: =I18*D$3 -> 540.66422 | L18: =J18*D$3 -> #REF!
A19: =Data!A14 -> Openwater_IN_T1_1 | B19: =Data!H14 -> 9.6833333 | C19: 26.81355 | E19: =Data!G14/Data!F14 -> 0.43130469 | F19: =C$3/E19 -> 47.282119 | G19: =C19-(G$3+G$4*B19) -> 0.17714525 | H19: =E19-(H$3+H$4*B19) -> -23.977446 | I19: =G19*(B$7/B$9)+B$3 -> 38.368759 | J19: =H19*(C$7)+C$3 -> #REF! | K19: =I19*D$3 -> 533.32575 | L19: =J19*D$3 -> #REF! | O19: =Data!A14 -> Openwater_IN_T1_1
B20: =Data!H15 -> 9.8166667 | C20: 26.814 | E20: =Data!G15/Data!F15 -> 0.43126352 | F20: =C$3/E20 -> 47.286634 | G20: =C20-(G$3+G$4*B20) -> 0.17737355 | H20: =E20-(H$3+H$4*B20) -> -23.977485 | I20: =G20*(B$7/B$9)+B$3 -> 38.368993 | J20: =H20*(C$7)+C$3 -> #REF! | K20: =I20*D$3 -> 533.32901 | L20: =J20*D$3 -> #REF!
B21: =Data!H16 -> 10.033333 | C21: 26.81296 | E21: =Data!G16/Data!F16 -> 0.43111988 | F21: =C$3/E21 -> 47.302389 | G21: =C21-(G$3+G$4*B21) -> 0.17597329 | H21: =E21-(H$3+H$4*B21) -> -23.977625 | I21: =G21*(B$7/B$9)+B$3 -> 38.367557 | J21: =H21*(C$7)+C$3 -> #REF! | K21: =I21*D$3 -> 533.30904 | L21: =J21*D$3 -> #REF!
A22: =Data!A17 -> Openwater_1_T1_1 | B22: =Data!H17 -> 16.416667 | C22: 26.83303 | E22: =Data!G17/Data!F17 -> 0.39506534 | F22: =C$4/E22 -> 51.586404 | G22: =C22-(G$3+G$4*B22) -> 0.18542939 | H22: =E22-(H$3+H$4*B22) -> -24.013561 | I22: =G22*(B$7/B$9)+B$3 -> 38.377259 | J22: =H22*(C$7)+C$3 -> #REF! | K22: =I22*D$3 -> 533.4439 | L22: =J22*D$3 -> #REF! | O22: =Data!A17 -> Openwater_1_T1_1
B23: =Data!H18 -> 16.55 | C23: 26.83899 | E23: =Data!G18/Data!F18 -> 0.39489638 | F23: =C$4/E23 -> 51.608475 | G23: =C23-(G$3+G$4*B23) -> 0.19116769 | H23: =E23-(H$3+H$4*B23) -> -24.013727 | I23: =G23*(B$7/B$9)+B$3 -> 38.383147 | J23: =H23*(C$7)+C$3 -> #REF! | K23: =I23*D$3 -> 533.52574 | L23: =J23*D$3 -> #REF!
B24: =Data!H19 -> 16.683333 | C24: 26.8341 | E24: =Data!G19/Data!F19 -> 0.39441345 | F24: =C$4/E24 -> 51.671666 | G24: =C24-(G$3+G$4*B24) -> 0.18605599 | H24: =E24-(H$3+H$4*B24) -> -24.014207 | I24: =G24*(B$7/B$9)+B$3 -> 38.377902 | J24: =H24*(C$7)+C$3 -> #REF! | K24: =I24*D$3 -> 533.45284 | L24: =J24*D$3 -> #REF!
A25: =Data!A20 -> Openwater_2_T1_1 | B25: =Data!H20 -> 22.2 | C25: 26.89976 | E25: =Data!G20/Data!F20 -> 0.39355333 | G25: =C25-(G$3+G$4*B25) -> 0.24254314 | H25: =E25-(H$3+H$4*B25) -> -24.014965 | I25: =G25*(B$7/B$9)+B$3 -> 38.43586 | J25: =H25*(C$7)+C$3 -> #REF! | K25: =I25*D$3 -> 534.25846 | L25: =J25*D$3 -> #REF! | M25: =AVERAGE(K25:K27) -> 534.23856 | N25: =AVERAGE(L25:L27) -> #REF! | O25: =Data!A20 -> Openwater_2_T1_1
B26: =Data!H21 -> 22.333333 | C26: 26.90248 | E26: =Data!G21/Data!F21 -> 0.39363694 | G26: =C26-(G$3+G$4*B26) -> 0.24504144 | H26: =E26-(H$3+H$4*B26) -> -24.014879 | I26: =G26*(B$7/B$9)+B$3 -> 38.438424 | J26: =H26*(C$7)+C$3 -> #REF! | K26: =I26*D$3 -> 534.29409 | L26: =J26*D$3 -> #REF!
B27: =Data!H22 -> 22.466667 | C27: 26.89352 | E27: =Data!G22/Data!F22 -> 0.39366955 | G27: =C27-(G$3+G$4*B27) -> 0.23585974 | H27: =E27-(H$3+H$4*B27) -> -24.014844 | I27: =G27*(B$7/B$9)+B$3 -> 38.429003 | J27: =H27*(C$7)+C$3 -> #REF! | K27: =I27*D$3 -> 534.16314 | L27: =J27*D$3 -> #REF!
A28: =Data!A23 -> 20 | B28: =Data!H23 -> 28.716667 | C28: 26.68941 | D28: =B3/C28 -> 1.4307922 | E28: =Data!G23/Data!F23 -> 0.47318843 | G28: =C28-(G$3+G$4*B28) -> 0.021357541 | H28: =E28-(H$3+H$4*B28) -> -23.935209 | I28: =G28*(B$7/B$9)+B$3 -> 38.208914 | J28: =H28*(C$7)+C$3 -> #REF! | K28: =I28*D$3 -> 531.1039 | L28: =J28*D$3 -> #REF! | M28: =AVERAGE(K28:K29) -> 531.13543 | N28: =AVERAGE(L28:L30) -> #REF! | O28: =Data!A23 -> 20
B29: =Data!H24 -> 28.8 | C29: 26.69397 | D29: =B3/C29 -> 1.4305478 | E29: =Data!G24/Data!F24 -> 0.4734721 | G29: =C29-(G$3+G$4*B29) -> 0.025778978 | H29: =E29-(H$3+H$4*B29) -> -23.934924 | I29: =G29*(B$7/B$9)+B$3 -> 38.21345 | J29: =H29*(C$7)+C$3 -> #REF! | K29: =I29*D$3 -> 531.16696 | L29: =J29*D$3 -> #REF!
B30: =Data!H25 -> 29.016667 | C30: 26.68541 | D30: =B3/C30 -> 1.4310067 | E30: =Data!G25/Data!F25 -> 0.47374352 | G30: =C30-(G$3+G$4*B30) -> 0.016858716 | H30: =E30-(H$3+H$4*B30) -> -23.934648 | I30: =G30*(B$7/B$9)+B$3 -> 38.204298 | J30: =H30*(C$7)+C$3 -> #REF! | K30: =I30*D$3 -> 531.03974 | L30: =J30*D$3 -> #REF!
A31: =Data!A26 -> 30 | B31: =Data!H26 -> 35.483333 | C31: 27.33111 | D31: =B4/C31 -> 1.4218596 | E31: =Data!G26/Data!F26 -> 0.46717971 | G31: =C31-(G$3+G$4*B31) -> 0.65180625 | H31: =E31-(H$3+H$4*B31) -> -23.941092 | I31: =G31*(B$7/B$9)+B$3 -> 38.855783 | J31: =H31*(C$7)+C$3 -> #REF! | K31: =I31*D$3 -> 540.09539 | L31: =J31*D$3 -> #REF! | M31: =AVERAGE(K31:K33) -> 540.04898 | N31: =AVERAGE(L31:L33) -> #REF! | O31: =Data!A26 -> 30
B32: =Data!H27 -> 35.616667 | C32: 27.32597 | D32: =B4/C32 -> 1.422127 | E32: =Data!G27/Data!F27 -> 0.46718232 | G32: =C32-(G$3+G$4*B32) -> 0.64644455 | H32: =E32-(H$3+H$4*B32) -> -23.941087 | I32: =G32*(B$7/B$9)+B$3 -> 38.850282 | J32: =H32*(C$7)+C$3 -> #REF! | K32: =I32*D$3 -> 540.01892 | L32: =J32*D$3 -> #REF!
B33: =Data!H28 -> 35.7 | C33: 27.32707 | D33: =B4/C33 -> 1.4220698 | E33: =Data!G28/Data!F28 -> 0.46714924 | G33: =C33-(G$3+G$4*B33) -> 0.64740599 | H33: =E33-(H$3+H$4*B33) -> -23.941118 | I33: =G33*(B$7/B$9)+B$3 -> 38.851268 | J33: =H33*(C$7)+C$3 -> #REF! | K33: =I33*D$3 -> 540.03263 | L33: =J33*D$3 -> #REF!
A34: =Data!A29 -> Openwater_3_T1_1 | B34: =Data!H29 -> 41.183333 | C34: 26.75424 | E34: =Data!G29/Data!F29 -> 0.39836714 | G34: =C34-(G$3+G$4*B34) -> 0.065458566 | H34: =E34-(H$3+H$4*B34) -> -24.009799 | I34: =G34*(B$7/B$9)+B$3 -> 38.254163 | J34: =H34*(C$7)+C$3 -> #REF! | K34: =I34*D$3 -> 531.73287 | L34: =J34*D$3 -> #REF! | M34: =AVERAGE(K34:K36) -> 531.67291 | N34: =AVERAGE(L34:L36) -> #REF! | O34: =Data!A29 -> Openwater_3_T1_1
B35: =Data!H30 -> 41.316667 | C35: 26.7499 | E35: =Data!G30/Data!F30 -> 0.39833083 | G35: =C35-(G$3+G$4*B35) -> 0.060896866 | H35: =E35-(H$3+H$4*B35) -> -24.009832 | I35: =G35*(B$7/B$9)+B$3 -> 38.249483 | J35: =H35*(C$7)+C$3 -> #REF! | K35: =I35*D$3 -> 531.66781 | L35: =J35*D$3 -> #REF!
B36: =Data!H31 -> 41.533333 | C36: 26.74677 | E36: =Data!G31/Data!F31 -> 0.39832398 | G36: =C36-(G$3+G$4*B36) -> 0.057406603 | H36: =E36-(H$3+H$4*B36) -> -24.009835 | I36: =G36*(B$7/B$9)+B$3 -> 38.245902 | J36: =H36*(C$7)+C$3 -> #REF! | K36: =I36*D$3 -> 531.61804 | L36: =J36*D$3 -> #REF!
A37: =Data!A32 -> Openwater_4_T1_1 | B37: =Data!H32 -> 43.966667 | C37: 26.7237 | E37: =Data!G32/Data!F32 -> 0.34573947 | G37: =C37-(G$3+G$4*B37) -> 0.030290573 | H37: =E37-(H$3+H$4*B37) -> -24.062374 | I37: =G37*(B$7/B$9)+B$3 -> 38.21808 | J37: =H37*(C$7)+C$3 -> #REF! | K37: =I37*D$3 -> 531.23131 | L37: =J37*D$3 -> #REF! | M37: =AVERAGE(K37:K39) -> 531.20592 | N37: =AVERAGE(L37:L39) -> #REF! | O37: =Data!A32 -> Openwater_4_T1_1
B38: =Data!H33 -> 44.05 | C38: 26.71687 | E38: =Data!G33/Data!F33 -> 0.34565018 | G38: =C38-(G$3+G$4*B38) -> 0.02332201 | H38: =E38-(H$3+H$4*B38) -> -24.062462 | I38: =G38*(B$7/B$9)+B$3 -> 38.210929 | J38: =H38*(C$7)+C$3 -> #REF! | K38: =I38*D$3 -> 531.13192 | L38: =J38*D$3 -> #REF!
B39: =Data!H34 -> 44.183333 | C39: 26.72569 | E39: =Data!G34/Data!F34 -> 0.34551845 | G39: =C39-(G$3+G$4*B39) -> 0.03192031 | H39: =E39-(H$3+H$4*B39) -> -24.062591 | I39: =G39*(B$7/B$9)+B$3 -> 38.219752 | J39: =H39*(C$7)+C$3 -> #REF! | K39: =I39*D$3 -> 531.25455 | L39: =J39*D$3 -> #REF!
A40: =Data!A35 -> SAVa_IN_T1_1 | B40: =Data!H35 -> 47.133333 | C40: 27.81789 | E40: =Data!G35/Data!F35 -> 0.32348097 | G40: =C40-(G$3+G$4*B40) -> 1.1192152 | H40: =E40-(H$3+H$4*B40) -> -24.084574 | I40: =G40*(B$7/B$9)+B$3 -> 39.335366 | J40: =H40*(C$7)+C$3 -> #REF! | K40: =I40*D$3 -> 546.76159 | L40: =J40*D$3 -> #REF! | M40: =AVERAGE(K40:K42) -> 546.67615 | N40: =AVERAGE(L40:L42) -> #REF! | O40: =Data!A35 -> SAVa_IN_T1_1
B41: =Data!H36 -> 47.266667 | C41: 27.81196 | E41: =Data!G36/Data!F36 -> 0.32359104 | G41: =C41-(G$3+G$4*B41) -> 1.1130635 | H41: =E41-(H$3+H$4*B41) -> -24.084462 | I41: =G41*(B$7/B$9)+B$3 -> 39.329054 | J41: =H41*(C$7)+C$3 -> #REF! | K41: =I41*D$3 -> 546.67386 | L41: =J41*D$3 -> #REF!
B42: =Data!H37 -> 47.35 | C42: 27.80643 | E42: =Data!G37/Data!F37 -> 0.32350924 | G42: =C42-(G$3+G$4*B42) -> 1.1073949 | H42: =E42-(H$3+H$4*B42) -> -24.084542 | I42: =G42*(B$7/B$9)+B$3 -> 39.323238 | J42: =H42*(C$7)+C$3 -> #REF! | K42: =I42*D$3 -> 546.59301 | L42: =J42*D$3 -> #REF!
...

Sheet mimsy_check
A1: sample_id | B1: N2_ws | C1: N2_mimsy | D1: difference
A2: 20 | B2: 530.66761 | C2: 537.44507 | D2: =B2-C2 -> -6.7774575
A3: 20 | B3: 530.63635 | C3: 537.39569 | D3: =B3-C3 -> -6.7593423
A4: 20 | B4: 530.68474 | C4: 537.45902 | D4: =B4-C4 -> -6.7742858
A5: 30 | B5: 540.47715 | C5: 457.72944 | D5: =B5-C5 -> 82.747706
A6: 30 | B6: 540.54943 | C6: 457.81647 | D6: =B6-C6 -> 82.732967
A7: 30 | B7: 540.66422 | C7: 457.95307 | D7: =B7-C7 -> 82.711144
A8: Openwater_IN_T1_1 | B8: 533.32575 | C8: 540.76884 | D8: =B8-C8 -> -7.4430884
A9: Openwater_IN_T1_2 | B9: 533.32901 | C9: 540.7755 | D9: =B9-C9 -> -7.4464928
A10: Openwater_IN_T1_3 | B10: 533.30904 | C10: 540.74728 | D10: =B10-C10 -> -7.438244
A11: Openwater_1_T1_1 | B11: 533.4439 | C11: 540.9587 | D11: =B11-C11 -> -7.5147959
A12: Openwater_1_T1_2 | B12: 533.52574 | C12: 541.0716 | D12: =B12-C12 -> -7.5458587
A13: Openwater_1_T1_3 | B13: 533.45284 | C13: 540.95731 | D13: =B13-C13 -> -7.5044702
A14: Openwater_2_T1_1 | B14: 534.25846 | C14: 541.95389 | D14: =B14-C14 -> -7.6954296
A15: Openwater_2_T1_2 | B15: 534.29409 | C15: 541.99052 | D15: =B15-C15 -> -7.6964261
A16: Openwater_2_T1_3 | B16: 534.16314 | C16: 541.78942 | D16: =B16-C16 -> -7.6262742
A17: 20 | B17: 531.1039 | C17: 537.43949 | D17: =B17-C17 -> -6.3355865
A18: 20 | B18: 531.16696 | C18: 537.53079 | D18: =B18-C18 -> -6.3638279
A19: 20 | B19: 531.03974 | C19: 537.35767 | D19: =B19-C19 -> -6.3179301
A20: 30 | B20: 540.09539 | C20: 457.92382 | D20: =B20-C20 -> 82.171562
A21: 30 | B21: 540.01892 | C21: 457.83704 | D21: =B21-C21 -> 82.181875
A22: 30 | B22: 540.03263 | C22: 457.85481 | D22: =B22-C22 -> 82.177819
A23: Openwater_3_T1_1 | B23: 531.73287 | C23: 538.68751 | D23: =B23-C23 -> -6.9546412
A24: Openwater_3_T1_2 | B24: 531.66781 | C24: 538.59968 | D24: =B24-C24 -> -6.931866
A25: Openwater_3_T1_3 | B25: 531.61804 | C25: 538.53651 | D25: =B25-C25 -> -6.9184729
A26: Openwater_4_T1_1 | B26: 531.23131 | C26: 538.05537 | D26: =B26-C26 -> -6.8240675
A27: Openwater_4_T1_2 | B27: 531.13192 | C27: 537.91621 | D27: =B27-C27 -> -6.7842905
A28: Openwater_4_T1_3 | B28: 531.25455 | C28: 538.09334 | D28: =B28-C28 -> -6.8387932
A29: SAVa_IN_T1_1 | B29: 546.76159 | C29: 560.06569 | D29: =B29-C29 -> -13.304102
A30: SAVa_IN_T1_2 | B30: 546.67386 | C30: 559.94521 | D30: =B30-C30 -> -13.271356
A31: SAVa_IN_T1_3 | B31: 546.59301 | C31: 559.83271 | D31: =B31-C31 -> -13.239696
A32: 20 | B32: 530.67083 | C32: 537.4964 | D32: =B32-C32 -> -6.8255659
A33: 20 | B33: 530.61823 | C33: 537.43027 | D33: =B33-C33 -> -6.8120471
A34: 20 | B34: 530.60534 | C34: 537.41804 | D34: =B34-C34 -> -6.812695
A35: 30 | B35: 539.70619 | C35: 457.89603 | D35: =B35-C35 -> 81.810157
A36: 30 | B36: 539.72218 | C36: 457.91552 | D36: =B36-C36 -> 81.806662
A37: 30 | B37: 539.5994 | C37: 457.77204 | D37: =B37-C37 -> 81.827365

Sheet 30N2
A1: 531.2 | B1: =actual N2 at 20/0
A2: =AVERAGE(Data!C8:C10,Data!C14:C16,Data!#REF!,Data!#REF!,Data!#REF!,Data!#REF!,Data!#REF!,Data!#REF!) -> #REF! | B2: =average measured N2 at 20/0
C4: x | D4: y | F4: N30 based
B5: N2*O2 | C5: SQRT | D5: N30 | E5: Excess | F5: on N2 | H5: SUMMARY OUTPUT
A7: =Data!A8 -> 20 | B7: =Data!C8*Data!G8 -> 2.2950053e-09 | C7: =SQRT(B7) -> 4.7906214e-05 | D7: =Data!E8 -> 6.763407e-12 | E7: =D7-(C7*I$22+I$21) -> -8.3145515e-09 | F7: =A$1*E7/A$2 -> #REF! | H7: Regression Statistics
B8: =Data!C9*Data!G9 -> 2.2942438e-09 | C8: =SQRT(B8) -> 4.7898265e-05 | D8: =Data!E9 -> 6.762699e-12 | E8: =D8-(C8*I$22+I$21) -> -8.3131722e-09 | F8: =A$1*E8/A$2 -> #REF! | H8: Multiple R | I8: 0.92521334
B9: =Data!C10*Data!G10 -> 2.293806e-09 | C9: =SQRT(B9) -> 4.7893695e-05 | D9: =Data!E10 -> 6.760184e-12 | E9: =D9-(C9*I$22+I$21) -> -8.3123812e-09 | F9: =A$1*E9/A$2 -> #REF! | H9: R Square | I9: 0.85601973
A10: =Data!A11 -> 30 | B10: =Data!C11*Data!G11 -> 1.9934172e-09 | C10: =SQRT(B10) -> 4.4647701e-05 | D10: =Data!E11 -> 5.707334e-12 | E10: =D10-(C10*I$22+I$21) -> -7.7498599e-09 | F10: =A$1*E10/A$2 -> #REF! | H10: Adjusted R Square | I10: 0.85288973
B11: =Data!C12*Data!G12 -> 1.993476e-09 | C11: =SQRT(B11) -> 4.464836e-05 | D11: =Data!E12 -> 5.705618e-12 | E11: =D11-(C11*I$22+I$21) -> -7.749976e-09 | F11: =A$1*E11/A$2 -> #REF! | H11: Standard Error | I11: 2.4535244e-13
B12: =Data!C13*Data!G13 -> 1.9932351e-09 | C12: =SQRT(B12) -> 4.4645661e-05 | D12: =Data!E13 -> 5.70235e-12 | E12: =D12-(C12*I$22+I$21) -> -7.7495107e-09 | F12: =A$1*E12/A$2 -> #REF! | H12: Observations | I12: 48
A13: =Data!A14 -> Openwater_IN_T1_1 | B13: =Data!C14*Data!G14 -> 2.049962e-09 | C13: =SQRT(B13) -> 4.5276506e-05 | D13: =Data!E14 -> 6.610784e-12 | E13: =D13-(C13*I$22+I$21) -> -7.8581306e-09 | F13: =A$1*E13/A$2 -> #REF!
B14: =Data!C15*Data!G15 -> 2.0500598e-09 | C14: =SQRT(B14) -> 4.5277586e-05 | D14: =Data!E15 -> 6.61151e-12 | E14: =D14-(C14*I$22+I$21) -> -7.8583172e-09 | F14: =A$1*E14/A$2 -> #REF! | H14: ANOVA
B15: =Data!C16*Data!G16 -> 2.0499795e-09 | C15: =SQRT(B15) -> 4.5276699e-05 | D15: =Data!E16 -> 6.613965e-12 | E15: =D15-(C15*I$22+I$21) -> -7.8581608e-09 | F15: =A$1*E15/A$2 -> #REF! | I15: df | J15: SS | K15: MS | L15: F | M15: Significance F
A16: =Data!A17 -> Openwater_1_T1_1 | B16: =Data!C17*Data!G17 -> 1.8883576e-09 | C16: =SQRT(B16) -> 4.3455237e-05 | D16: =Data!E17 -> 6.638592e-12 | E16: =D16-(C16*I$22+I$21) -> -7.5418913e-09 | F16: =A$1*E16/A$2 -> #REF! | H16: Regression | I16: 1 | J16: 1.6463395e-23 | K16: 1.6463395e-23 | L16: 273.48823 | M16: 5.5133839e-21
B17: =Data!C18*Data!G18 -> 1.888265e-09 | C17: =SQRT(B17) -> 4.3454171e-05 | D17: =Data!E18 -> 6.638157e-12 | E17: =D17-(C17*I$22+I$21) -> -7.5417067e-09 | F17: =A$1*E17/A$2 -> #REF! | H17: Residual | I17: 46 | J17: 2.7690996e-24 | K17: 6.0197818e-26
B18: =Data!C19*Data!G19 -> 1.8859127e-09 | C18: =SQRT(B18) -> 4.3427097e-05 | D18: =Data!E19 -> 6.640424e-12 | E18: =D18-(C18*I$22+I$21) -> -7.5370037e-09 | F18: =A$1*E18/A$2 -> #REF! | H18: Total | I18: 47 | J18: 1.9232494e-23
A19: =Data!#REF! -> #REF! | B19: =Data!#REF!*Data!#REF! -> #REF! | C19: =SQRT(B19) -> #REF! | D19: =Data!#REF! -> #REF! | E19: =D19-(C19*I$22+I$21) -> #REF! | F19: =A$1*E19/A$2 -> #REF!
B20: =Data!#REF!*Data!#REF! -> #REF! | C20: =SQRT(B20) -> #REF! | D20: =Data!#REF! -> #REF! | E20: =D20-(C20*I$22+I$21) -> #REF! | F20: =A$1*E20/A$2 -> #REF! | I20: Coefficients | J20: Standard Error | K20: t Stat | L20: P-value | M20: Lower 95% | N20: Upper 95% | O20: Lower 95.0% | P20: Upper 95.0%
B21: =Data!#REF!*Data!#REF! -> #REF! | C21: =SQRT(B21) -> #REF! | D21: =Data!#REF! -> #REF! | E21: =D21-(C21*I$22+I$21) -> #REF! | F21: =A$1*E21/A$2 -> #REF! | H21: Intercept | I21: 3.7685473e-12 | J21: 3.9988768e-13 | K21: 9.4240145 | L21: 2.5937484e-12 | M21: 2.9636152e-12 | N21: 4.5734795e-12 | O21: 2.9636152e-12 | P21: 4.5734795e-12
A22: =Data!#REF! -> #REF! | B22: =Data!#REF!*Data!#REF! -> #REF! | C22: =SQRT(B22) -> #REF! | D22: =Data!#REF! -> #REF! | E22: =D22-(C22*I$22+I$21) -> #REF! | F22: =A$1*E22/A$2 -> #REF! | H22: X Variable 1 | I22: 0.00017362145 | J22: 1.0498665e-05 | K22: 16.537479 | L22: 5.5133839e-21 | M22: 0.00015248874 | N22: 0.00019475417 | O22: 0.00015248874 | P22: 0.00019475417
B23: =Data!#REF!*Data!#REF! -> #REF! | C23: =SQRT(B23) -> #REF! | D23: =Data!#REF! -> #REF! | E23: =D23-(C23*I$22+I$21) -> #REF! | F23: =A$1*E23/A$2 -> #REF!
B24: =Data!#REF!*Data!#REF! -> #REF! | C24: =SQRT(B24) -> #REF! | D24: =Data!#REF! -> #REF! | E24: =D24-(C24*I$22+I$21) -> #REF! | F24: =A$1*E24/A$2 -> #REF!
A25: =Data!#REF! -> #REF! | B25: =Data!#REF!*Data!#REF! -> #REF! | C25: =SQRT(B25) -> #REF! | D25: =Data!#REF! -> #REF! | E25: =D25-(C25*I$22+I$21) -> #REF! | F25: =A$1*E25/A$2 -> #REF!
B26: =Data!#REF!*Data!#REF! -> #REF! | C26: =SQRT(B26) -> #REF! | D26: =Data!#REF! -> #REF! | E26: =D26-(C26*I$22+I$21) -> #REF! | F26: =A$1*E26/A$2 -> #REF!
B27: =Data!#REF!*Data!#REF! -> #REF! | C27: =SQRT(B27) -> #REF! | D27: =Data!#REF! -> #REF! | E27: =D27-(C27*I$22+I$21) -> #REF! | F27: =A$1*E27/A$2 -> #REF!
A28: =Data!#REF! -> #REF! | B28: =Data!#REF!*Data!#REF! -> #REF! | C28: =SQRT(B28) -> #REF! | D28: =Data!#REF! -> #REF! | E28: =D28-(C28*I$22+I$21) -> #REF! | F28: =A$1*E28/A$2 -> #REF!
B29: =Data!#REF!*Data!#REF! -> #REF! | C29: =SQRT(B29) -> #REF! | D29: =Data!#REF! -> #REF! | E29: =D29-(C29*I$22+I$21) -> #REF! | F29: =A$1*E29/A$2 -> #REF!
B30: =Data!#REF!*Data!#REF! -> #REF! | C30: =SQRT(B30) -> #REF! | D30: =Data!#REF! -> #REF! | E30: =D30-(C30*I$22+I$21) -> #REF! | F30: =A$1*E30/A$2 -> #REF!
A31: =Data!#REF! -> #REF! | B31: =Data!#REF!*Data!#REF! -> #REF! | C31: =SQRT(B31) -> #REF! | D31: =Data!#REF! -> #REF! | E31: =D31-(C31*I$22+I$21) -> #REF! | F31: =A$1*E31/A$2 -> #REF!
B32: =Data!#REF!*Data!#REF! -> #REF! | C32: =SQRT(B32) -> #REF! | D32: =Data!#REF! -> #REF! | E32: =D32-(C32*I$22+I$21) -> #REF! | F32: =A$1*E32/A$2 -> #REF!
B33: =Data!#REF!*Data!#REF! -> #REF! | C33: =SQRT(B33) -> #REF! | D33: =Data!#REF! -> #REF! | E33: =D33-(C33*I$22+I$21) -> #REF! | F33: =A$1*E33/A$2 -> #REF!
A34: =Data!#REF! -> #REF! | B34: =Data!#REF!*Data!#REF! -> #REF! | C34: =SQRT(B34) -> #REF! | D34: =Data!#REF! -> #REF! | E34: =D34-(C34*I$22+I$21) -> #REF! | F34: =A$1*E34/A$2 -> #REF!
B35: =Data!#REF!*Data!#REF! -> #REF! | C35: =SQRT(B35) -> #REF! | D35: =Data!#REF! -> #REF! | E35: =D35-(C35*I$22+I$21) -> #REF! | F35: =A$1*E35/A$2 -> #REF!
B36: =Data!#REF!*Data!#REF! -> #REF! | C36: =SQRT(B36) -> #REF! | D36: =Data!#REF! -> #REF! | E36: =D36-(C36*I$22+I$21) -> #REF! | F36: =A$1*E36/A$2 -> #REF!
A37: =Data!#REF! -> #REF! | B37: =Data!#REF!*Data!#REF! -> #REF! | C37: =SQRT(B37) -> #REF! | D37: =Data!#REF! -> #REF! | E37: =D37-(C37*I$22+I$21) -> #REF! | F37: =A$1*E37/A$2 -> #REF!
B38: =Data!#REF!*Data!#REF! -> #REF! | C38: =SQRT(B38) -> #REF! | D38: =Data!#REF! -> #REF! | E38: =D38-(C38*I$22+I$21) -> #REF! | F38: =A$1*E38/A$2 -> #REF!
B39: =Data!#REF!*Data!#REF! -> #REF! | C39: =SQRT(B39) -> #REF! | D39: =Data!#REF! -> #REF! | E39: =D39-(C39*I$22+I$21) -> #REF! | F39: =A$1*E39/A$2 -> #REF!
A40: =Data!#REF! -> #REF! | B40: =Data!#REF!*Data!#REF! -> #REF! | C40: =SQRT(B40) -> #REF! | D40: =Data!#REF! -> #REF! | E40: =D40-(C40*I$22+I$21) -> #REF! | F40: =A$1*E40/A$2 -> #REF!
B41: =Data!#REF!*Data!#REF! -> #REF! | C41: =SQRT(B41) -> #REF! | D41: =Data!#REF! -> #REF! | E41: =D41-(C41*I$22+I$21) -> #REF! | F41: =A$1*E41/A$2 -> #REF!
B42: =Data!#REF!*Data!#REF! -> #REF! | C42: =SQRT(B42) -> #REF! | D42: =Data!#REF! -> #REF! | E42: =D42-(C42*I$22+I$21) -> #REF! | F42: =A$1*E42/A$2 -> #REF!
...

Sheet 29N2
A1: ='30N2'!A1 -> 531.2 | B1: =actual N2 at 20/0
A2: ='30N2'!A2 -> #REF! | B2: =average measured N2 at 20/0
B4: x | C4: y | E4: N29 based
B5: N28 | C5: N29 | D5: Excess | E5: on N2 | G5: SUMMARY OUTPUT
A7: ='30N2'!A7 -> 20 | B7: =Data!C8 -> 1.799815e-10 | C7: =Data!D8 -> 8.624249e-11 | D7: =C7-(B7*H$22+H$21) -> 8.2248582e-11 | E7: =A$1*D7/A$2 -> #REF! | G7: Regression Statistics
B8: =Data!C9 -> 1.799493e-10 | C8: =Data!D9 -> 8.622027e-11 | D8: =C8-(B8*H$22+H$21) -> 8.2226587e-11 | E8: =A$1*D8/A$2 -> #REF! | G8: Multiple R | H8: 0.9998193
B9: =Data!C10 -> 1.799072e-10 | C9: =Data!D10 -> 8.619193e-11 | D9: =C9-(B9*H$22+H$21) -> 8.2198542e-11 | E9: =A$1*D9/A$2 -> #REF! | G9: R Square | H9: 0.99963863
A10: ='30N2'!A10 -> 30 | B10: =Data!C11 -> 1.55852e-10 | C10: =Data!D11 -> 7.299936e-11 | D10: =C10-(B10*H$22+H$21) -> 6.9174249e-11 | E10: =A$1*D10/A$2 -> #REF! | G10: Adjusted R Square | H10: 0.99963077
B11: =Data!C12 -> 1.558354e-10 | C11: =Data!D12 -> 7.298733e-11 | D11: =C11-(B11*H$22+H$21) -> 6.9162335e-11 | E11: =A$1*D11/A$2 -> #REF! | G11: Standard Error | H11: 6.367191e-13
B12: =Data!C13 -> 1.557933e-10 | C12: =Data!D13 -> 7.295643e-11 | D12: =C12-(B12*H$22+H$21) -> 6.9131729e-11 | E12: =A$1*D12/A$2 -> #REF! | G12: Observations | H12: 48
A13: ='30N2'!A13 -> Openwater_IN_T1_1 | B13: =Data!C14 -> 1.772586e-10 | C13: =Data!D14 -> 7.645243e-11 | D13: =C13-(B13*H$22+H$21) -> 7.247757e-11 | E13: =A$1*D13/A$2 -> #REF!
B14: =Data!C15 -> 1.77281e-10 | C14: =Data!D15 -> 7.645484e-11 | D14: =C14-(B14*H$22+H$21) -> 7.2479823e-11 | E14: =A$1*D14/A$2 -> #REF! | G14: ANOVA
B15: =Data!C16 -> 1.7734e-10 | C15: =Data!D16 -> 7.645477e-11 | D15: =C15-(B15*H$22+H$21) -> 7.2479341e-11 | E15: =A$1*D15/A$2 -> #REF! | H15: df | I15: SS | J15: MS | K15: F | L15: Significance F
A16: ='30N2'!A16 -> Openwater_1_T1_1 | B16: =Data!C17 -> 1.781335e-10 | C16: =Data!D17 -> 7.037435e-11 | D16: =C16-(B16*H$22+H$21) -> 6.639337e-11 | E16: =A$1*D16/A$2 -> #REF! | G16: Regression | H16: 1 | I16: 5.1586937e-20 | J16: 5.1586937e-20 | K16: 127245.96 | L16: 7.9668052e-81
B17: =Data!C18 -> 1.781614e-10 | C17: =Data!D18 -> 7.035529e-11 | D17: =C17-(B17*H$22+H$21) -> 6.6374115e-11 | E17: =A$1*D17/A$2 -> #REF! | G17: Residual | H17: 46 | I17: 1.8648916e-23 | J17: 4.0541121e-25
B18: =Data!C19 -> 1.781898e-10 | C18: =Data!D19 -> 7.028046e-11 | D18: =C18-(B18*H$22+H$21) -> 6.6299086e-11 | E18: =A$1*D18/A$2 -> #REF! | G18: Total | H18: 47 | I18: 5.1605586e-20
A19: ='30N2'!A19 -> #REF! | B19: =Data!#REF! -> #REF! | C19: =Data!#REF! -> #REF! | D19: =C19-(B19*H$22+H$21) -> #REF! | E19: =A$1*D19/A$2 -> #REF!
B20: =Data!#REF! -> #REF! | C20: =Data!#REF! -> #REF! | D20: =C20-(B20*H$22+H$21) -> #REF! | E20: =A$1*D20/A$2 -> #REF! | H20: Coefficients | I20: Standard Error | J20: t Stat | K20: P-value | L20: Lower 95% | M20: Upper 95% | N20: Lower 95.0% | O20: Upper 95.0%
B21: =Data!#REF! -> #REF! | C21: =Data!#REF! -> #REF! | D21: =C21-(B21*H$22+H$21) -> #REF! | E21: =A$1*D21/A$2 -> #REF! | G21: Intercept | H21: 2.7348578e-12 | I21: 1.0787438e-12 | J21: 2.5352245 | K21: 0.014701501 | L21: 5.6345907e-13 | M21: 4.9062565e-12 | N21: 5.6345907e-13 | O21: 4.9062565e-12
A22: ='30N2'!A22 -> #REF! | B22: =Data!#REF! -> #REF! | C22: =Data!#REF! -> #REF! | D22: =C22-(B22*H$22+H$21) -> #REF! | E22: =A$1*D22/A$2 -> #REF! | G22: X Variable 1 | H22: 0.0069954418 | I22: 1.9610703e-05 | J22: 356.71551 | K22: 7.9668052e-81 | L22: 0.0069559675 | M22: 0.0070349161 | N22: 0.0069559675 | O22: 0.0070349161
B23: =Data!#REF! -> #REF! | C23: =Data!#REF! -> #REF! | D23: =C23-(B23*H$22+H$21) -> #REF! | E23: =A$1*D23/A$2 -> #REF!
B24: =Data!#REF! -> #REF! | C24: =Data!#REF! -> #REF! | D24: =C24-(B24*H$22+H$21) -> #REF! | E24: =A$1*D24/A$2 -> #REF!
A25: ='30N2'!A25 -> #REF! | B25: =Data!#REF! -> #REF! | C25: =Data!#REF! -> #REF! | D25: =C25-(B25*H$22+H$21) -> #REF! | E25: =A$1*D25/A$2 -> #REF!
B26: =Data!#REF! -> #REF! | C26: =Data!#REF! -> #REF! | D26: =C26-(B26*H$22+H$21) -> #REF! | E26: =A$1*D26/A$2 -> #REF!
B27: =Data!#REF! -> #REF! | C27: =Data!#REF! -> #REF! | D27: =C27-(B27*H$22+H$21) -> #REF! | E27: =A$1*D27/A$2 -> #REF!
A28: ='30N2'!A28 -> #REF! | B28: =Data!#REF! -> #REF! | C28: =Data!#REF! -> #REF! | D28: =C28-(B28*H$22+H$21) -> #REF! | E28: =A$1*D28/A$2 -> #REF!
B29: =Data!#REF! -> #REF! | C29: =Data!#REF! -> #REF! | D29: =C29-(B29*H$22+H$21) -> #REF! | E29: =A$1*D29/A$2 -> #REF!
B30: =Data!#REF! -> #REF! | C30: =Data!#REF! -> #REF! | D30: =C30-(B30*H$22+H$21) -> #REF! | E30: =A$1*D30/A$2 -> #REF!
A31: ='30N2'!A31 -> #REF! | B31: =Data!#REF! -> #REF! | C31: =Data!#REF! -> #REF! | D31: =C31-(B31*H$22+H$21) -> #REF! | E31: =A$1*D31/A$2 -> #REF!
B32: =Data!#REF! -> #REF! | C32: =Data!#REF! -> #REF! | D32: =C32-(B32*H$22+H$21) -> #REF! | E32: =A$1*D32/A$2 -> #REF!
B33: =Data!#REF! -> #REF! | C33: =Data!#REF! -> #REF! | D33: =C33-(B33*H$22+H$21) -> #REF! | E33: =A$1*D33/A$2 -> #REF!
A34: ='30N2'!A34 -> #REF! | B34: =Data!#REF! -> #REF! | C34: =Data!#REF! -> #REF! | D34: =C34-(B34*H$22+H$21) -> #REF! | E34: =A$1*D34/A$2 -> #REF!
B35: =Data!#REF! -> #REF! | C35: =Data!#REF! -> #REF! | D35: =C35-(B35*H$22+H$21) -> #REF! | E35: =A$1*D35/A$2 -> #REF!
B36: =Data!#REF! -> #REF! | C36: =Data!#REF! -> #REF! | D36: =C36-(B36*H$22+H$21) -> #REF! | E36: =A$1*D36/A$2 -> #REF!
A37: ='30N2'!A37 -> #REF! | B37: =Data!#REF! -> #REF! | C37: =Data!#REF! -> #REF! | D37: =C37-(B37*H$22+H$21) -> #REF! | E37: =A$1*D37/A$2 -> #REF!
B38: =Data!#REF! -> #REF! | C38: =Data!#REF! -> #REF! | D38: =C38-(B38*H$22+H$21) -> #REF! | E38: =A$1*D38/A$2 -> #REF!
B39: =Data!#REF! -> #REF! | C39: =Data!#REF! -> #REF! | D39: =C39-(B39*H$22+H$21) -> #REF! | E39: =A$1*D39/A$2 -> #REF!
A40: ='30N2'!A40 -> #REF! | B40: =Data!#REF! -> #REF! | C40: =Data!#REF! -> #REF! | D40: =C40-(B40*H$22+H$21) -> #REF! | E40: =A$1*D40/A$2 -> #REF!
B41: =Data!#REF! -> #REF! | C41: =Data!#REF! -> #REF! | D41: =C41-(B41*H$22+H$21) -> #REF! | E41: =A$1*D41/A$2 -> #REF!
B42: =Data!#REF! -> #REF! | C42: =Data!#REF! -> #REF! | D42: =C42-(B42*H$22+H$21) -> #REF! | E42: =A$1*D42/A$2 -> #REF!
...
